Workbook

Sheet Read me
A1: WLab calculator: companion to "Color Without the Fine Print"
A3: Calculator Enter XYZ (white Y = 100) and pick the observing condition. You get Wpt, WLab and CIELAB.
A4: Put another row's name under "Compare with" to get DeltaE(WLab), DeltaE*ab and DeltaE00 between them.
A5: The example rows include the guide's Purplish Blue patches (when the ColorChecker data were present).
A6: MAT Carry XYZ from one observing condition to another: a different light, a different observer, or both.
A7: Matrices The Wpt normalization for each listed condition, and its inverse.
A9: Only the conditions on the Matrices sheet are available here. For any other observer or light, compute the
A10: normalization with the Octave or Python code in this package and add a row to the Matrices sheet.
A12: WLab differences are material color differences. They correspond to perceived color differences under a
A13: reference observing condition, like DeltaE00; WLab is not a color appearance space.

Sheet Calculator
A1: WLab calculator
A2: Yellow cells are inputs. Pick a condition, enter X, Y, Z (white Y = 100). "Compare with" names another row to get the differences.
A3: WLab differences are material color differences; they correspond to perceived differences under a reference observing condition, like DeltaE00. WLab is not a color appearance space.
T4: Working columns (no need to read them)
A5: Name | B5: Condition | C5: X | D5: Y | E5: Z | F5: Compare with | G5: W | H5: p | I5: t | J5: Lw | K5: aw | L5: bw | M5: L* | N5: a* | O5: b* | P5: ΔE(WLab) | Q5: ΔE*ab | R5: ΔE00 | T5: mrow | U5: C | V5: h | W5: Wlin | X5: s | Y5: C1 | Z5: r | AA5: b1 | AB5: b2 | AC5: C2 | AD5: fx | AE5: fy | AF5: fz | AG5: crow | AH5: L2 | AI5: a2 | AJ5: b2_ | AK5: Cm | AL5: G | AM5: ap1 | AN5: ap2 | AO5: Cp1 | AP5: Cp2 | AQ5: hp1 | AR5: hp2 | AS5: dh | AT5: dHp | AU5: Lpm | AV5: Cpm | AW5: hs | AX5: hpm | AY5: T | AZ5: RC | BA5: SL | BB5: SC | BC5: SH | BD5: RT
A6: 5PB 5/6 D65 | B6: CIE 1931 2deg D65 | C6: 18.9333 | D6: 19.8096 | E6: 37.83 | G6: =IF($C6="","",INDEX(Matrices!$G$2:$G$15,T6)*C6+INDEX(Matrices!$H$2:$H$15,T6)*D6+INDEX(Matrices!$I$2:$I$15,T6)*E6) | H6: =IF($C6="","",INDEX(Matrices!$J$2:$J$15,T6)*C6+INDEX(Matrices!$K$2:$K$15,T6)*D6+INDEX(Matrices!$L$2:$L$15,T6)*E6) | I6: =IF($C6="","",INDEX(Matrices!$M$2:$M$15,T6)*C6+INDEX(Matrices!$N$2:$N$15,T6)*D6+INDEX(Matrices!$O$2:$O$15,T6)*E6) | J6: =IF($C6="","",W6) | K6: =IF($C6="","",AC6*COS(RADIANS(V6))) | L6: =IF($C6="","",AC6*SIN(RADIANS(V6))) | M6: =IF($C6="","",116*AE6-16) | N6: =IF($C6="","",500*(AD6-AE6)) | O6: =IF($C6="","",200*(AE6-AF6)) | P6: =IF(OR($C6="",F6=""),"",SQRT((J6-INDEX($J$6:$J$45,AG6))^2+(K6-INDEX($K$6:$K$45,AG6))^2+(L6-INDEX($L$6:$L$45,AG6))^2)) | Q6: =IF(OR($C6="",F6=""),"",SQRT((M6-INDEX($M$6:$M$45,AG6))^2+(N6-INDEX($N$6:$N$45,AG6))^2+(O6-INDEX($O$6:$O$45,AG6))^2)) | R6: =IF(OR($C6="",F6=""),"",SQRT(((AH6-M6)/BA6)^2+((AP6-AO6)/BB6)^2+(AT6/BC6)^2+BD6*((AP6-AO6)/BB6)*(AT6/BC6))) | T6: =IF($C6="","",MATCH(B6,Matrices!$A$2:$A$15,0)) | U6: =IF($C6="","",SQRT(H6^2+I6^2)) | V6: =IF($C6="","",IF(U6=0,0,MOD(DEGREES(ATAN2(H6,I6)),360))) | W6: =IF($C6="","",IF(G6/100>(6/29)^3,(G6/100)^(1/3),(1/3)*(29/6)^2*G6/100+16/116)*116-16) | X6: =IF($C6="","",EXP(0.026742553710937*(W6-51.576165618406904))/0.45888671875) | Y6: =IF($C6="","",U6/X6) | Z6: =IF($C6="","",IF(AND(V6>1,V6<181),SIN(RADIANS(V6-1))^3,0)+IF(AND(V6>104,V6<284),0.39*COS(RADIANS(V6-14))^2,0)) | AA6: =IF($C6="","",62*(Z6+0.31)) | AB6: =IF($C6="","",0.36*(Z6+0.19)) | AC6: =IF($C6="","",AA6*(LN(Y6/80+AB6)-LN(AB6))) | AD6: =IF($C6="","",IF(C6/INDEX(Matrices!$D$2:$D$15,T6)>0.008856,(C6/INDEX(Matrices!$D$2:$D$15,T6))^(1/3),7.787*C6/INDEX(Matrices!$D$2:$D$15,T6)+16/116)) | AE6: =IF($C6="","",IF(D6/INDEX(Matrices!$E$2:$E$15,T6)>0.008856,(D6/INDEX(Matrices!$E$2:$E$15,T6))^(1/3),7.787*D6/INDEX(Matrices!$E$2:$E$15,T6)+16/116)) | AF6: =IF($C6="","",IF(E6/INDEX(Matrices!$F$2:$F$15,T6)>0.008856,(E6/INDEX(Matrices!$F$2:$F$15,T6))^(1/3),7.787*E6/INDEX(Matrices!$F$2:$F$15,T6)+16/116)) | AG6: =IF(OR($C6="",F6=""),"",MATCH(F6,$A$6:$A$45,0)) | AH6: =IF(OR($C6="",F6=""),"",INDEX($M$6:$M$45,AG6)) | AI6: =IF(OR($C6="",F6=""),"",INDEX($N$6:$N$45,AG6)) | AJ6: =IF(OR($C6="",F6=""),"",INDEX($O$6:$O$45,AG6)) | AK6: =IF(OR($C6="",F6=""),"",(SQRT(N6^2+O6^2)+SQRT(AI6^2+AJ6^2))/2) | AL6: =IF(OR($C6="",F6=""),"",0.5*(1-SQRT(AK6^7/(AK6^7+25^7)))) | AM6: =IF(OR($C6="",F6=""),"",(1+AL6)*N6) | AN6: =IF(OR($C6="",F6=""),"",(1+AL6)*AI6) | AO6: =IF(OR($C6="",F6=""),"",SQRT(AM6^2+O6^2)) | AP6: =IF(OR($C6="",F6=""),"",SQRT(AN6^2+AJ6^2)) | AQ6: =IF(OR($C6="",F6=""),"",IF(AO6=0,0,MOD(DEGREES(ATAN2(AM6,O6)),360))) | AR6: =IF(OR($C6="",F6=""),"",IF(AP6=0,0,MOD(DEGREES(ATAN2(AN6,AJ6)),360))) | AS6: =IF(OR($C6="",F6=""),"",IF(AO6*AP6=0,0,IF((AR6-AQ6)>180,(AR6-AQ6)-360,IF((AR6-AQ6)<-180,(AR6-AQ6)+360,(AR6-AQ6))))) | AT6: =IF(OR($C6="",F6=""),"",2*SQRT(AO6*AP6)*SIN(RADIANS(AS6/2))) | AU6: =IF(OR($C6="",F6=""),"",(M6+AH6)/2) | AV6: =IF(OR($C6="",F6=""),"",(AO6+AP6)/2) | AW6: =IF(OR($C6="",F6=""),"",AQ6+AR6) | AX6: =IF(OR($C6="",F6=""),"",IF(AO6*AP6=0,AW6,IF(ABS(AQ6-AR6)>180,IF(AW6<360,(AW6+360)/2,(AW6-360)/2),AW6/2))) | AY6: =IF(OR($C6="",F6=""),"",1-0.17*COS(RADIANS(AX6-30))+0.24*COS(RADIANS(2*AX6))+0.32*COS(RADIANS(3*AX6+6))-0.2*COS(RADIANS(4*AX6-63))) | AZ6: =IF(OR($C6="",F6=""),"",2*SQRT(AV6^7/(AV6^7+25^7))) | BA6: =IF(OR($C6="",F6=""),"",1+0.015*(AU6-50)^2/SQRT(20+(AU6-50)^2)) | BB6: =IF(OR($C6="",F6=""),"",1+0.045*AV6) | BC6: =IF(OR($C6="",F6=""),"",1+0.015*AV6*AY6) | BD6: =IF(OR($C6="",F6=""),"",-SIN(RADIANS(2*30*EXP(-(((AX6-275)/25)^2))))*AZ6)
A7: 5PB 5/6 A | B7: CIE 1931 2deg A | C7: 18.7118 | D7: 18.2392 | E7: 12.1728 | F7: 5PB 5/6 D65 | G7: =IF($C7="","",INDEX(Matrices!$G$2:$G$15,T7)*C7+INDEX(Matrices!$H$2:$H$15,T7)*D7+INDEX(Matrices!$I$2:$I$15,T7)*E7) | H7: =IF($C7="","",INDEX(Matrices!$J$2:$J$15,T7)*C7+INDEX(Matrices!$K$2:$K$15,T7)*D7+INDEX(Matrices!$L$2:$L$15,T7)*E7) | I7: =IF($C7="","",INDEX(Matrices!$M$2:$M$15,T7)*C7+INDEX(Matrices!$N$2:$N$15,T7)*D7+INDEX(Matrices!$O$2:$O$15,T7)*E7) | J7: =IF($C7="","",W7) | K7: =IF($C7="","",AC7*COS(RADIANS(V7))) | L7: =IF($C7="","",AC7*SIN(RADIANS(V7))) | M7: =IF($C7="","",116*AE7-16) | N7: =IF($C7="","",500*(AD7-AE7)) | O7: =IF($C7="","",200*(AE7-AF7)) | P7: =IF(OR($C7="",F7=""),"",SQRT((J7-INDEX($J$6:$J$45,AG7))^2+(K7-INDEX($K$6:$K$45,AG7))^2+(L7-INDEX($L$6:$L$45,AG7))^2)) | Q7: =IF(OR($C7="",F7=""),"",SQRT((M7-INDEX($M$6:$M$45,AG7))^2+(N7-INDEX($N$6:$N$45,AG7))^2+(O7-INDEX($O$6:$O$45,AG7))^2)) | R7: =IF(OR($C7="",F7=""),"",SQRT(((AH7-M7)/BA7)^2+((AP7-AO7)/BB7)^2+(AT7/BC7)^2+BD7*((AP7-AO7)/BB7)*(AT7/BC7))) | T7: =IF($C7="","",MATCH(B7,Matrices!$A$2:$A$15,0)) | U7: =IF($C7="","",SQRT(H7^2+I7^2)) | V7: =IF($C7="","",IF(U7=0,0,MOD(DEGREES(ATAN2(H7,I7)),360))) | W7: =IF($C7="","",IF(G7/100>(6/29)^3,(G7/100)^(1/3),(1/3)*(29/6)^2*G7/100+16/116)*116-16) | X7: =IF($C7="","",EXP(0.026742553710937*(W7-51.576165618406904))/0.45888671875) | Y7: =IF($C7="","",U7/X7) | Z7: =IF($C7="","",IF(AND(V7>1,V7<181),SIN(RADIANS(V7-1))^3,0)+IF(AND(V7>104,V7<284),0.39*COS(RADIANS(V7-14))^2,0)) | AA7: =IF($C7="","",62*(Z7+0.31)) | AB7: =IF($C7="","",0.36*(Z7+0.19)) | AC7: =IF($C7="","",AA7*(LN(Y7/80+AB7)-LN(AB7))) | AD7: =IF($C7="","",IF(C7/INDEX(Matrices!$D$2:$D$15,T7)>0.008856,(C7/INDEX(Matrices!$D$2:$D$15,T7))^(1/3),7.787*C7/INDEX(Matrices!$D$2:$D$15,T7)+16/116)) | AE7: =IF($C7="","",IF(D7/INDEX(Matrices!$E$2:$E$15,T7)>0.008856,(D7/INDEX(Matrices!$E$2:$E$15,T7))^(1/3),7.787*D7/INDEX(Matrices!$E$2:$E$15,T7)+16/116)) | AF7: =IF($C7="","",IF(E7/INDEX(Matrices!$F$2:$F$15,T7)>0.008856,(E7/INDEX(Matrices!$F$2:$F$15,T7))^(1/3),7.787*E7/INDEX(Matrices!$F$2:$F$15,T7)+16/116)) | AG7: =IF(OR($C7="",F7=""),"",MATCH(F7,$A$6:$A$45,0)) | AH7: =IF(OR($C7="",F7=""),"",INDEX($M$6:$M$45,AG7)) | AI7: =IF(OR($C7="",F7=""),"",INDEX($N$6:$N$45,AG7)) | AJ7: =IF(OR($C7="",F7=""),"",INDEX($O$6:$O$45,AG7)) | AK7: =IF(OR($C7="",F7=""),"",(SQRT(N7^2+O7^2)+SQRT(AI7^2+AJ7^2))/2) | AL7: =IF(OR($C7="",F7=""),"",0.5*(1-SQRT(AK7^7/(AK7^7+25^7)))) | AM7: =IF(OR($C7="",F7=""),"",(1+AL7)*N7) | AN7: =IF(OR($C7="",F7=""),"",(1+AL7)*AI7) | AO7: =IF(OR($C7="",F7=""),"",SQRT(AM7^2+O7^2)) | AP7: =IF(OR($C7="",F7=""),"",SQRT(AN7^2+AJ7^2)) | AQ7: =IF(OR($C7="",F7=""),"",IF(AO7=0,0,MOD(DEGREES(ATAN2(AM7,O7)),360))) | AR7: =IF(OR($C7="",F7=""),"",IF(AP7=0,0,MOD(DEGREES(ATAN2(AN7,AJ7)),360))) | AS7: =IF(OR($C7="",F7=""),"",IF(AO7*AP7=0,0,IF((AR7-AQ7)>180,(AR7-AQ7)-360,IF((AR7-AQ7)<-180,(AR7-AQ7)+360,(AR7-AQ7))))) | AT7: =IF(OR($C7="",F7=""),"",2*SQRT(AO7*AP7)*SIN(RADIANS(AS7/2))) | AU7: =IF(OR($C7="",F7=""),"",(M7+AH7)/2) | AV7: =IF(OR($C7="",F7=""),"",(AO7+AP7)/2) | AW7: =IF(OR($C7="",F7=""),"",AQ7+AR7) | AX7: =IF(OR($C7="",F7=""),"",IF(AO7*AP7=0,AW7,IF(ABS(AQ7-AR7)>180,IF(AW7<360,(AW7+360)/2,(AW7-360)/2),AW7/2))) | AY7: =IF(OR($C7="",F7=""),"",1-0.17*COS(RADIANS(AX7-30))+0.24*COS(RADIANS(2*AX7))+0.32*COS(RADIANS(3*AX7+6))-0.2*COS(RADIANS(4*AX7-63))) | AZ7: =IF(OR($C7="",F7=""),"",2*SQRT(AV7^7/(AV7^7+25^7))) | BA7: =IF(OR($C7="",F7=""),"",1+0.015*(AU7-50)^2/SQRT(20+(AU7-50)^2)) | BB7: =IF(OR($C7="",F7=""),"",1+0.045*AV7) | BC7: =IF(OR($C7="",F7=""),"",1+0.015*AV7*AY7) | BD7: =IF(OR($C7="",F7=""),"",-SIN(RADIANS(2*30*EXP(-(((AX7-275)/25)^2))))*AZ7)
A8: 50% gray D65 | B8: CIE 1931 2deg D65 | C8: 47.5215 | D8: 50 | E8: 54.44 | G8: =IF($C8="","",INDEX(Matrices!$G$2:$G$15,T8)*C8+INDEX(Matrices!$H$2:$H$15,T8)*D8+INDEX(Matrices!$I$2:$I$15,T8)*E8) | H8: =IF($C8="","",INDEX(Matrices!$J$2:$J$15,T8)*C8+INDEX(Matrices!$K$2:$K$15,T8)*D8+INDEX(Matrices!$L$2:$L$15,T8)*E8) | I8: =IF($C8="","",INDEX(Matrices!$M$2:$M$15,T8)*C8+INDEX(Matrices!$N$2:$N$15,T8)*D8+INDEX(Matrices!$O$2:$O$15,T8)*E8) | J8: =IF($C8="","",W8) | K8: =IF($C8="","",AC8*COS(RADIANS(V8))) | L8: =IF($C8="","",AC8*SIN(RADIANS(V8))) | M8: =IF($C8="","",116*AE8-16) | N8: =IF($C8="","",500*(AD8-AE8)) | O8: =IF($C8="","",200*(AE8-AF8)) | P8: =IF(OR($C8="",F8=""),"",SQRT((J8-INDEX($J$6:$J$45,AG8))^2+(K8-INDEX($K$6:$K$45,AG8))^2+(L8-INDEX($L$6:$L$45,AG8))^2)) | Q8: =IF(OR($C8="",F8=""),"",SQRT((M8-INDEX($M$6:$M$45,AG8))^2+(N8-INDEX($N$6:$N$45,AG8))^2+(O8-INDEX($O$6:$O$45,AG8))^2)) | R8: =IF(OR($C8="",F8=""),"",SQRT(((AH8-M8)/BA8)^2+((AP8-AO8)/BB8)^2+(AT8/BC8)^2+BD8*((AP8-AO8)/BB8)*(AT8/BC8))) | T8: =IF($C8="","",MATCH(B8,Matrices!$A$2:$A$15,0)) | U8: =IF($C8="","",SQRT(H8^2+I8^2)) | V8: =IF($C8="","",IF(U8=0,0,MOD(DEGREES(ATAN2(H8,I8)),360))) | W8: =IF($C8="","",IF(G8/100>(6/29)^3,(G8/100)^(1/3),(1/3)*(29/6)^2*G8/100+16/116)*116-16) | X8: =IF($C8="","",EXP(0.026742553710937*(W8-51.576165618406904))/0.45888671875) | Y8: =IF($C8="","",U8/X8) | Z8: =IF($C8="","",IF(AND(V8>1,V8<181),SIN(RADIANS(V8-1))^3,0)+IF(AND(V8>104,V8<284),0.39*COS(RADIANS(V8-14))^2,0)) | AA8: =IF($C8="","",62*(Z8+0.31)) | AB8: =IF($C8="","",0.36*(Z8+0.19)) | AC8: =IF($C8="","",AA8*(LN(Y8/80+AB8)-LN(AB8))) | AD8: =IF($C8="","",IF(C8/INDEX(Matrices!$D$2:$D$15,T8)>0.008856,(C8/INDEX(Matrices!$D$2:$D$15,T8))^(1/3),7.787*C8/INDEX(Matrices!$D$2:$D$15,T8)+16/116)) | AE8: =IF($C8="","",IF(D8/INDEX(Matrices!$E$2:$E$15,T8)>0.008856,(D8/INDEX(Matrices!$E$2:$E$15,T8))^(1/3),7.787*D8/INDEX(Matrices!$E$2:$E$15,T8)+16/116)) | AF8: =IF($C8="","",IF(E8/INDEX(Matrices!$F$2:$F$15,T8)>0.008856,(E8/INDEX(Matrices!$F$2:$F$15,T8))^(1/3),7.787*E8/INDEX(Matrices!$F$2:$F$15,T8)+16/116)) | AG8: =IF(OR($C8="",F8=""),"",MATCH(F8,$A$6:$A$45,0)) | AH8: =IF(OR($C8="",F8=""),"",INDEX($M$6:$M$45,AG8)) | AI8: =IF(OR($C8="",F8=""),"",INDEX($N$6:$N$45,AG8)) | AJ8: =IF(OR($C8="",F8=""),"",INDEX($O$6:$O$45,AG8)) | AK8: =IF(OR($C8="",F8=""),"",(SQRT(N8^2+O8^2)+SQRT(AI8^2+AJ8^2))/2) | AL8: =IF(OR($C8="",F8=""),"",0.5*(1-SQRT(AK8^7/(AK8^7+25^7)))) | AM8: =IF(OR($C8="",F8=""),"",(1+AL8)*N8) | AN8: =IF(OR($C8="",F8=""),"",(1+AL8)*AI8) | AO8: =IF(OR($C8="",F8=""),"",SQRT(AM8^2+O8^2)) | AP8: =IF(OR($C8="",F8=""),"",SQRT(AN8^2+AJ8^2)) | AQ8: =IF(OR($C8="",F8=""),"",IF(AO8=0,0,MOD(DEGREES(ATAN2(AM8,O8)),360))) | AR8: =IF(OR($C8="",F8=""),"",IF(AP8=0,0,MOD(DEGREES(ATAN2(AN8,AJ8)),360))) | AS8: =IF(OR($C8="",F8=""),"",IF(AO8*AP8=0,0,IF((AR8-AQ8)>180,(AR8-AQ8)-360,IF((AR8-AQ8)<-180,(AR8-AQ8)+360,(AR8-AQ8))))) | AT8: =IF(OR($C8="",F8=""),"",2*SQRT(AO8*AP8)*SIN(RADIANS(AS8/2))) | AU8: =IF(OR($C8="",F8=""),"",(M8+AH8)/2) | AV8: =IF(OR($C8="",F8=""),"",(AO8+AP8)/2) | AW8: =IF(OR($C8="",F8=""),"",AQ8+AR8) | AX8: =IF(OR($C8="",F8=""),"",IF(AO8*AP8=0,AW8,IF(ABS(AQ8-AR8)>180,IF(AW8<360,(AW8+360)/2,(AW8-360)/2),AW8/2))) | AY8: =IF(OR($C8="",F8=""),"",1-0.17*COS(RADIANS(AX8-30))+0.24*COS(RADIANS(2*AX8))+0.32*COS(RADIANS(3*AX8+6))-0.2*COS(RADIANS(4*AX8-63))) | AZ8: =IF(OR($C8="",F8=""),"",2*SQRT(AV8^7/(AV8^7+25^7))) | BA8: =IF(OR($C8="",F8=""),"",1+0.015*(AU8-50)^2/SQRT(20+(AU8-50)^2)) | BB8: =IF(OR($C8="",F8=""),"",1+0.045*AV8) | BC8: =IF(OR($C8="",F8=""),"",1+0.015*AV8*AY8) | BD8: =IF(OR($C8="",F8=""),"",-SIN(RADIANS(2*30*EXP(-(((AX8-275)/25)^2))))*AZ8)
A9: 50% gray A | B9: CIE 1931 2deg A | C9: 54.9245 | D9: 50 | E9: 17.7912 | G9: =IF($C9="","",INDEX(Matrices!$G$2:$G$15,T9)*C9+INDEX(Matrices!$H$2:$H$15,T9)*D9+INDEX(Matrices!$I$2:$I$15,T9)*E9) | H9: =IF($C9="","",INDEX(Matrices!$J$2:$J$15,T9)*C9+INDEX(Matrices!$K$2:$K$15,T9)*D9+INDEX(Matrices!$L$2:$L$15,T9)*E9) | I9: =IF($C9="","",INDEX(Matrices!$M$2:$M$15,T9)*C9+INDEX(Matrices!$N$2:$N$15,T9)*D9+INDEX(Matrices!$O$2:$O$15,T9)*E9) | J9: =IF($C9="","",W9) | K9: =IF($C9="","",AC9*COS(RADIANS(V9))) | L9: =IF($C9="","",AC9*SIN(RADIANS(V9))) | M9: =IF($C9="","",116*AE9-16) | N9: =IF($C9="","",500*(AD9-AE9)) | O9: =IF($C9="","",200*(AE9-AF9)) | P9: =IF(OR($C9="",F9=""),"",SQRT((J9-INDEX($J$6:$J$45,AG9))^2+(K9-INDEX($K$6:$K$45,AG9))^2+(L9-INDEX($L$6:$L$45,AG9))^2)) | Q9: =IF(OR($C9="",F9=""),"",SQRT((M9-INDEX($M$6:$M$45,AG9))^2+(N9-INDEX($N$6:$N$45,AG9))^2+(O9-INDEX($O$6:$O$45,AG9))^2)) | R9: =IF(OR($C9="",F9=""),"",SQRT(((AH9-M9)/BA9)^2+((AP9-AO9)/BB9)^2+(AT9/BC9)^2+BD9*((AP9-AO9)/BB9)*(AT9/BC9))) | T9: =IF($C9="","",MATCH(B9,Matrices!$A$2:$A$15,0)) | U9: =IF($C9="","",SQRT(H9^2+I9^2)) | V9: =IF($C9="","",IF(U9=0,0,MOD(DEGREES(ATAN2(H9,I9)),360))) | W9: =IF($C9="","",IF(G9/100>(6/29)^3,(G9/100)^(1/3),(1/3)*(29/6)^2*G9/100+16/116)*116-16) | X9: =IF($C9="","",EXP(0.026742553710937*(W9-51.576165618406904))/0.45888671875) | Y9: =IF($C9="","",U9/X9) | Z9: =IF($C9="","",IF(AND(V9>1,V9<181),SIN(RADIANS(V9-1))^3,0)+IF(AND(V9>104,V9<284),0.39*COS(RADIANS(V9-14))^2,0)) | AA9: =IF($C9="","",62*(Z9+0.31)) | AB9: =IF($C9="","",0.36*(Z9+0.19)) | AC9: =IF($C9="","",AA9*(LN(Y9/80+AB9)-LN(AB9))) | AD9: =IF($C9="","",IF(C9/INDEX(Matrices!$D$2:$D$15,T9)>0.008856,(C9/INDEX(Matrices!$D$2:$D$15,T9))^(1/3),7.787*C9/INDEX(Matrices!$D$2:$D$15,T9)+16/116)) | AE9: =IF($C9="","",IF(D9/INDEX(Matrices!$E$2:$E$15,T9)>0.008856,(D9/INDEX(Matrices!$E$2:$E$15,T9))^(1/3),7.787*D9/INDEX(Matrices!$E$2:$E$15,T9)+16/116)) | AF9: =IF($C9="","",IF(E9/INDEX(Matrices!$F$2:$F$15,T9)>0.008856,(E9/INDEX(Matrices!$F$2:$F$15,T9))^(1/3),7.787*E9/INDEX(Matrices!$F$2:$F$15,T9)+16/116)) | AG9: =IF(OR($C9="",F9=""),"",MATCH(F9,$A$6:$A$45,0)) | AH9: =IF(OR($C9="",F9=""),"",INDEX($M$6:$M$45,AG9)) | AI9: =IF(OR($C9="",F9=""),"",INDEX($N$6:$N$45,AG9)) | AJ9: =IF(OR($C9="",F9=""),"",INDEX($O$6:$O$45,AG9)) | AK9: =IF(OR($C9="",F9=""),"",(SQRT(N9^2+O9^2)+SQRT(AI9^2+AJ9^2))/2) | AL9: =IF(OR($C9="",F9=""),"",0.5*(1-SQRT(AK9^7/(AK9^7+25^7)))) | AM9: =IF(OR($C9="",F9=""),"",(1+AL9)*N9) | AN9: =IF(OR($C9="",F9=""),"",(1+AL9)*AI9) | AO9: =IF(OR($C9="",F9=""),"",SQRT(AM9^2+O9^2)) | AP9: =IF(OR($C9="",F9=""),"",SQRT(AN9^2+AJ9^2)) | AQ9: =IF(OR($C9="",F9=""),"",IF(AO9=0,0,MOD(DEGREES(ATAN2(AM9,O9)),360))) | AR9: =IF(OR($C9="",F9=""),"",IF(AP9=0,0,MOD(DEGREES(ATAN2(AN9,AJ9)),360))) | AS9: =IF(OR($C9="",F9=""),"",IF(AO9*AP9=0,0,IF((AR9-AQ9)>180,(AR9-AQ9)-360,IF((AR9-AQ9)<-180,(AR9-AQ9)+360,(AR9-AQ9))))) | AT9: =IF(OR($C9="",F9=""),"",2*SQRT(AO9*AP9)*SIN(RADIANS(AS9/2))) | AU9: =IF(OR($C9="",F9=""),"",(M9+AH9)/2) | AV9: =IF(OR($C9="",F9=""),"",(AO9+AP9)/2) | AW9: =IF(OR($C9="",F9=""),"",AQ9+AR9) | AX9: =IF(OR($C9="",F9=""),"",IF(AO9*AP9=0,AW9,IF(ABS(AQ9-AR9)>180,IF(AW9<360,(AW9+360)/2,(AW9-360)/2),AW9/2))) | AY9: =IF(OR($C9="",F9=""),"",1-0.17*COS(RADIANS(AX9-30))+0.24*COS(RADIANS(2*AX9))+0.32*COS(RADIANS(3*AX9+6))-0.2*COS(RADIANS(4*AX9-63))) | AZ9: =IF(OR($C9="",F9=""),"",2*SQRT(AV9^7/(AV9^7+25^7))) | BA9: =IF(OR($C9="",F9=""),"",1+0.015*(AU9-50)^2/SQRT(20+(AU9-50)^2)) | BB9: =IF(OR($C9="",F9=""),"",1+0.045*AV9) | BC9: =IF(OR($C9="",F9=""),"",1+0.015*AV9*AY9) | BD9: =IF(OR($C9="",F9=""),"",-SIN(RADIANS(2*30*EXP(-(((AX9-275)/25)^2))))*AZ9)
G10: =IF($C10="","",INDEX(Matrices!$G$2:$G$15,T10)*C10+INDEX(Matrices!$H$2:$H$15,T10)*D10+INDEX(Matrices!$I$2:$I$15,T10)*E10) | H10: =IF($C10="","",INDEX(Matrices!$J$2:$J$15,T10)*C10+INDEX(Matrices!$K$2:$K$15,T10)*D10+INDEX(Matrices!$L$2:$L$15,T10)*E10) | I10: =IF($C10="","",INDEX(Matrices!$M$2:$M$15,T10)*C10+INDEX(Matrices!$N$2:$N$15,T10)*D10+INDEX(Matrices!$O$2:$O$15,T10)*E10) | J10: =IF($C10="","",W10) | K10: =IF($C10="","",AC10*COS(RADIANS(V10))) | L10: =IF($C10="","",AC10*SIN(RADIANS(V10))) | M10: =IF($C10="","",116*AE10-16) | N10: =IF($C10="","",500*(AD10-AE10)) | O10: =IF($C10="","",200*(AE10-AF10)) | P10: =IF(OR($C10="",F10=""),"",SQRT((J10-INDEX($J$6:$J$45,AG10))^2+(K10-INDEX($K$6:$K$45,AG10))^2+(L10-INDEX($L$6:$L$45,AG10))^2)) | Q10: =IF(OR($C10="",F10=""),"",SQRT((M10-INDEX($M$6:$M$45,AG10))^2+(N10-INDEX($N$6:$N$45,AG10))^2+(O10-INDEX($O$6:$O$45,AG10))^2)) | R10: =IF(OR($C10="",F10=""),"",SQRT(((AH10-M10)/BA10)^2+((AP10-AO10)/BB10)^2+(AT10/BC10)^2+BD10*((AP10-AO10)/BB10)*(AT10/BC10))) | T10: =IF($C10="","",MATCH(B10,Matrices!$A$2:$A$15,0)) | U10: =IF($C10="","",SQRT(H10^2+I10^2)) | V10: =IF($C10="","",IF(U10=0,0,MOD(DEGREES(ATAN2(H10,I10)),360))) | W10: =IF($C10="","",IF(G10/100>(6/29)^3,(G10/100)^(1/3),(1/3)*(29/6)^2*G10/100+16/116)*116-16) | X10: =IF($C10="","",EXP(0.026742553710937*(W10-51.576165618406904))/0.45888671875) | Y10: =IF($C10="","",U10/X10) | Z10: =IF($C10="","",IF(AND(V10>1,V10<181),SIN(RADIANS(V10-1))^3,0)+IF(AND(V10>104,V10<284),0.39*COS(RADIANS(V10-14))^2,0)) | AA10: =IF($C10="","",62*(Z10+0.31)) | AB10: =IF($C10="","",0.36*(Z10+0.19)) | AC10: =IF($C10="","",AA10*(LN(Y10/80+AB10)-LN(AB10))) | AD10: =IF($C10="","",IF(C10/INDEX(Matrices!$D$2:$D$15,T10)>0.008856,(C10/INDEX(Matrices!$D$2:$D$15,T10))^(1/3),7.787*C10/INDEX(Matrices!$D$2:$D$15,T10)+16/116)) | AE10: =IF($C10="","",IF(D10/INDEX(Matrices!$E$2:$E$15,T10)>0.008856,(D10/INDEX(Matrices!$E$2:$E$15,T10))^(1/3),7.787*D10/INDEX(Matrices!$E$2:$E$15,T10)+16/116)) | AF10: =IF($C10="","",IF(E10/INDEX(Matrices!$F$2:$F$15,T10)>0.008856,(E10/INDEX(Matrices!$F$2:$F$15,T10))^(1/3),7.787*E10/INDEX(Matrices!$F$2:$F$15,T10)+16/116)) | AG10: =IF(OR($C10="",F10=""),"",MATCH(F10,$A$6:$A$45,0)) | AH10: =IF(OR($C10="",F10=""),"",INDEX($M$6:$M$45,AG10)) | AI10: =IF(OR($C10="",F10=""),"",INDEX($N$6:$N$45,AG10)) | AJ10: =IF(OR($C10="",F10=""),"",INDEX($O$6:$O$45,AG10)) | AK10: =IF(OR($C10="",F10=""),"",(SQRT(N10^2+O10^2)+SQRT(AI10^2+AJ10^2))/2) | AL10: =IF(OR($C10="",F10=""),"",0.5*(1-SQRT(AK10^7/(AK10^7+25^7)))) | AM10: =IF(OR($C10="",F10=""),"",(1+AL10)*N10) | AN10: =IF(OR($C10="",F10=""),"",(1+AL10)*AI10) | AO10: =IF(OR($C10="",F10=""),"",SQRT(AM10^2+O10^2)) | AP10: =IF(OR($C10="",F10=""),"",SQRT(AN10^2+AJ10^2)) | AQ10: =IF(OR($C10="",F10=""),"",IF(AO10=0,0,MOD(DEGREES(ATAN2(AM10,O10)),360))) | AR10: =IF(OR($C10="",F10=""),"",IF(AP10=0,0,MOD(DEGREES(ATAN2(AN10,AJ10)),360))) | AS10: =IF(OR($C10="",F10=""),"",IF(AO10*AP10=0,0,IF((AR10-AQ10)>180,(AR10-AQ10)-360,IF((AR10-AQ10)<-180,(AR10-AQ10)+360,(AR10-AQ10))))) | AT10: =IF(OR($C10="",F10=""),"",2*SQRT(AO10*AP10)*SIN(RADIANS(AS10/2))) | AU10: =IF(OR($C10="",F10=""),"",(M10+AH10)/2) | AV10: =IF(OR($C10="",F10=""),"",(AO10+AP10)/2) | AW10: =IF(OR($C10="",F10=""),"",AQ10+AR10) | AX10: =IF(OR($C10="",F10=""),"",IF(AO10*AP10=0,AW10,IF(ABS(AQ10-AR10)>180,IF(AW10<360,(AW10+360)/2,(AW10-360)/2),AW10/2))) | AY10: =IF(OR($C10="",F10=""),"",1-0.17*COS(RADIANS(AX10-30))+0.24*COS(RADIANS(2*AX10))+0.32*COS(RADIANS(3*AX10+6))-0.2*COS(RADIANS(4*AX10-63))) | AZ10: =IF(OR($C10="",F10=""),"",2*SQRT(AV10^7/(AV10^7+25^7))) | BA10: =IF(OR($C10="",F10=""),"",1+0.015*(AU10-50)^2/SQRT(20+(AU10-50)^2)) | BB10: =IF(OR($C10="",F10=""),"",1+0.045*AV10) | BC10: =IF(OR($C10="",F10=""),"",1+0.015*AV10*AY10) | BD10: =IF(OR($C10="",F10=""),"",-SIN(RADIANS(2*30*EXP(-(((AX10-275)/25)^2))))*AZ10)
G11: =IF($C11="","",INDEX(Matrices!$G$2:$G$15,T11)*C11+INDEX(Matrices!$H$2:$H$15,T11)*D11+INDEX(Matrices!$I$2:$I$15,T11)*E11) | H11: =IF($C11="","",INDEX(Matrices!$J$2:$J$15,T11)*C11+INDEX(Matrices!$K$2:$K$15,T11)*D11+INDEX(Matrices!$L$2:$L$15,T11)*E11) | I11: =IF($C11="","",INDEX(Matrices!$M$2:$M$15,T11)*C11+INDEX(Matrices!$N$2:$N$15,T11)*D11+INDEX(Matrices!$O$2:$O$15,T11)*E11) | J11: =IF($C11="","",W11) | K11: =IF($C11="","",AC11*COS(RADIANS(V11))) | L11: =IF($C11="","",AC11*SIN(RADIANS(V11))) | M11: =IF($C11="","",116*AE11-16) | N11: =IF($C11="","",500*(AD11-AE11)) | O11: =IF($C11="","",200*(AE11-AF11)) | P11: =IF(OR($C11="",F11=""),"",SQRT((J11-INDEX($J$6:$J$45,AG11))^2+(K11-INDEX($K$6:$K$45,AG11))^2+(L11-INDEX($L$6:$L$45,AG11))^2)) | Q11: =IF(OR($C11="",F11=""),"",SQRT((M11-INDEX($M$6:$M$45,AG11))^2+(N11-INDEX($N$6:$N$45,AG11))^2+(O11-INDEX($O$6:$O$45,AG11))^2)) | R11: =IF(OR($C11="",F11=""),"",SQRT(((AH11-M11)/BA11)^2+((AP11-AO11)/BB11)^2+(AT11/BC11)^2+BD11*((AP11-AO11)/BB11)*(AT11/BC11))) | T11: =IF($C11="","",MATCH(B11,Matrices!$A$2:$A$15,0)) | U11: =IF($C11="","",SQRT(H11^2+I11^2)) | V11: =IF($C11="","",IF(U11=0,0,MOD(DEGREES(ATAN2(H11,I11)),360))) | W11: =IF($C11="","",IF(G11/100>(6/29)^3,(G11/100)^(1/3),(1/3)*(29/6)^2*G11/100+16/116)*116-16) | X11: =IF($C11="","",EXP(0.026742553710937*(W11-51.576165618406904))/0.45888671875) | Y11: =IF($C11="","",U11/X11) | Z11: =IF($C11="","",IF(AND(V11>1,V11<181),SIN(RADIANS(V11-1))^3,0)+IF(AND(V11>104,V11<284),0.39*COS(RADIANS(V11-14))^2,0)) | AA11: =IF($C11="","",62*(Z11+0.31)) | AB11: =IF($C11="","",0.36*(Z11+0.19)) | AC11: =IF($C11="","",AA11*(LN(Y11/80+AB11)-LN(AB11))) | AD11: =IF($C11="","",IF(C11/INDEX(Matrices!$D$2:$D$15,T11)>0.008856,(C11/INDEX(Matrices!$D$2:$D$15,T11))^(1/3),7.787*C11/INDEX(Matrices!$D$2:$D$15,T11)+16/116)) | AE11: =IF($C11="","",IF(D11/INDEX(Matrices!$E$2:$E$15,T11)>0.008856,(D11/INDEX(Matrices!$E$2:$E$15,T11))^(1/3),7.787*D11/INDEX(Matrices!$E$2:$E$15,T11)+16/116)) | AF11: =IF($C11="","",IF(E11/INDEX(Matrices!$F$2:$F$15,T11)>0.008856,(E11/INDEX(Matrices!$F$2:$F$15,T11))^(1/3),7.787*E11/INDEX(Matrices!$F$2:$F$15,T11)+16/116)) | AG11: =IF(OR($C11="",F11=""),"",MATCH(F11,$A$6:$A$45,0)) | AH11: =IF(OR($C11="",F11=""),"",INDEX($M$6:$M$45,AG11)) | AI11: =IF(OR($C11="",F11=""),"",INDEX($N$6:$N$45,AG11)) | AJ11: =IF(OR($C11="",F11=""),"",INDEX($O$6:$O$45,AG11)) | AK11: =IF(OR($C11="",F11=""),"",(SQRT(N11^2+O11^2)+SQRT(AI11^2+AJ11^2))/2) | AL11: =IF(OR($C11="",F11=""),"",0.5*(1-SQRT(AK11^7/(AK11^7+25^7)))) | AM11: =IF(OR($C11="",F11=""),"",(1+AL11)*N11) | AN11: =IF(OR($C11="",F11=""),"",(1+AL11)*AI11) | AO11: =IF(OR($C11="",F11=""),"",SQRT(AM11^2+O11^2)) | AP11: =IF(OR($C11="",F11=""),"",SQRT(AN11^2+AJ11^2)) | AQ11: =IF(OR($C11="",F11=""),"",IF(AO11=0,0,MOD(DEGREES(ATAN2(AM11,O11)),360))) | AR11: =IF(OR($C11="",F11=""),"",IF(AP11=0,0,MOD(DEGREES(ATAN2(AN11,AJ11)),360))) | AS11: =IF(OR($C11="",F11=""),"",IF(AO11*AP11=0,0,IF((AR11-AQ11)>180,(AR11-AQ11)-360,IF((AR11-AQ11)<-180,(AR11-AQ11)+360,(AR11-AQ11))))) | AT11: =IF(OR($C11="",F11=""),"",2*SQRT(AO11*AP11)*SIN(RADIANS(AS11/2))) | AU11: =IF(OR($C11="",F11=""),"",(M11+AH11)/2) | AV11: =IF(OR($C11="",F11=""),"",(AO11+AP11)/2) | AW11: =IF(OR($C11="",F11=""),"",AQ11+AR11) | AX11: =IF(OR($C11="",F11=""),"",IF(AO11*AP11=0,AW11,IF(ABS(AQ11-AR11)>180,IF(AW11<360,(AW11+360)/2,(AW11-360)/2),AW11/2))) | AY11: =IF(OR($C11="",F11=""),"",1-0.17*COS(RADIANS(AX11-30))+0.24*COS(RADIANS(2*AX11))+0.32*COS(RADIANS(3*AX11+6))-0.2*COS(RADIANS(4*AX11-63))) | AZ11: =IF(OR($C11="",F11=""),"",2*SQRT(AV11^7/(AV11^7+25^7))) | BA11: =IF(OR($C11="",F11=""),"",1+0.015*(AU11-50)^2/SQRT(20+(AU11-50)^2)) | BB11: =IF(OR($C11="",F11=""),"",1+0.045*AV11) | BC11: =IF(OR($C11="",F11=""),"",1+0.015*AV11*AY11) | BD11: =IF(OR($C11="",F11=""),"",-SIN(RADIANS(2*30*EXP(-(((AX11-275)/25)^2))))*AZ11)
G12: =IF($C12="","",INDEX(Matrices!$G$2:$G$15,T12)*C12+INDEX(Matrices!$H$2:$H$15,T12)*D12+INDEX(Matrices!$I$2:$I$15,T12)*E12) | H12: =IF($C12="","",INDEX(Matrices!$J$2:$J$15,T12)*C12+INDEX(Matrices!$K$2:$K$15,T12)*D12+INDEX(Matrices!$L$2:$L$15,T12)*E12) | I12: =IF($C12="","",INDEX(Matrices!$M$2:$M$15,T12)*C12+INDEX(Matrices!$N$2:$N$15,T12)*D12+INDEX(Matrices!$O$2:$O$15,T12)*E12) | J12: =IF($C12="","",W12) | K12: =IF($C12="","",AC12*COS(RADIANS(V12))) | L12: =IF($C12="","",AC12*SIN(RADIANS(V12))) | M12: =IF($C12="","",116*AE12-16) | N12: =IF($C12="","",500*(AD12-AE12)) | O12: =IF($C12="","",200*(AE12-AF12)) | P12: =IF(OR($C12="",F12=""),"",SQRT((J12-INDEX($J$6:$J$45,AG12))^2+(K12-INDEX($K$6:$K$45,AG12))^2+(L12-INDEX($L$6:$L$45,AG12))^2)) | Q12: =IF(OR($C12="",F12=""),"",SQRT((M12-INDEX($M$6:$M$45,AG12))^2+(N12-INDEX($N$6:$N$45,AG12))^2+(O12-INDEX($O$6:$O$45,AG12))^2)) | R12: =IF(OR($C12="",F12=""),"",SQRT(((AH12-M12)/BA12)^2+((AP12-AO12)/BB12)^2+(AT12/BC12)^2+BD12*((AP12-AO12)/BB12)*(AT12/BC12))) | T12: =IF($C12="","",MATCH(B12,Matrices!$A$2:$A$15,0)) | U12: =IF($C12="","",SQRT(H12^2+I12^2)) | V12: =IF($C12="","",IF(U12=0,0,MOD(DEGREES(ATAN2(H12,I12)),360))) | W12: =IF($C12="","",IF(G12/100>(6/29)^3,(G12/100)^(1/3),(1/3)*(29/6)^2*G12/100+16/116)*116-16) | X12: =IF($C12="","",EXP(0.026742553710937*(W12-51.576165618406904))/0.45888671875) | Y12: =IF($C12="","",U12/X12) | Z12: =IF($C12="","",IF(AND(V12>1,V12<181),SIN(RADIANS(V12-1))^3,0)+IF(AND(V12>104,V12<284),0.39*COS(RADIANS(V12-14))^2,0)) | AA12: =IF($C12="","",62*(Z12+0.31)) | AB12: =IF($C12="","",0.36*(Z12+0.19)) | AC12: =IF($C12="","",AA12*(LN(Y12/80+AB12)-LN(AB12))) | AD12: =IF($C12="","",IF(C12/INDEX(Matrices!$D$2:$D$15,T12)>0.008856,(C12/INDEX(Matrices!$D$2:$D$15,T12))^(1/3),7.787*C12/INDEX(Matrices!$D$2:$D$15,T12)+16/116)) | AE12: =IF($C12="","",IF(D12/INDEX(Matrices!$E$2:$E$15,T12)>0.008856,(D12/INDEX(Matrices!$E$2:$E$15,T12))^(1/3),7.787*D12/INDEX(Matrices!$E$2:$E$15,T12)+16/116)) | AF12: =IF($C12="","",IF(E12/INDEX(Matrices!$F$2:$F$15,T12)>0.008856,(E12/INDEX(Matrices!$F$2:$F$15,T12))^(1/3),7.787*E12/INDEX(Matrices!$F$2:$F$15,T12)+16/116)) | AG12: =IF(OR($C12="",F12=""),"",MATCH(F12,$A$6:$A$45,0)) | AH12: =IF(OR($C12="",F12=""),"",INDEX($M$6:$M$45,AG12)) | AI12: =IF(OR($C12="",F12=""),"",INDEX($N$6:$N$45,AG12)) | AJ12: =IF(OR($C12="",F12=""),"",INDEX($O$6:$O$45,AG12)) | AK12: =IF(OR($C12="",F12=""),"",(SQRT(N12^2+O12^2)+SQRT(AI12^2+AJ12^2))/2) | AL12: =IF(OR($C12="",F12=""),"",0.5*(1-SQRT(AK12^7/(AK12^7+25^7)))) | AM12: =IF(OR($C12="",F12=""),"",(1+AL12)*N12) | AN12: =IF(OR($C12="",F12=""),"",(1+AL12)*AI12) | AO12: =IF(OR($C12="",F12=""),"",SQRT(AM12^2+O12^2)) | AP12: =IF(OR($C12="",F12=""),"",SQRT(AN12^2+AJ12^2)) | AQ12: =IF(OR($C12="",F12=""),"",IF(AO12=0,0,MOD(DEGREES(ATAN2(AM12,O12)),360))) | AR12: =IF(OR($C12="",F12=""),"",IF(AP12=0,0,MOD(DEGREES(ATAN2(AN12,AJ12)),360))) | AS12: =IF(OR($C12="",F12=""),"",IF(AO12*AP12=0,0,IF((AR12-AQ12)>180,(AR12-AQ12)-360,IF((AR12-AQ12)<-180,(AR12-AQ12)+360,(AR12-AQ12))))) | AT12: =IF(OR($C12="",F12=""),"",2*SQRT(AO12*AP12)*SIN(RADIANS(AS12/2))) | AU12: =IF(OR($C12="",F12=""),"",(M12+AH12)/2) | AV12: =IF(OR($C12="",F12=""),"",(AO12+AP12)/2) | AW12: =IF(OR($C12="",F12=""),"",AQ12+AR12) | AX12: =IF(OR($C12="",F12=""),"",IF(AO12*AP12=0,AW12,IF(ABS(AQ12-AR12)>180,IF(AW12<360,(AW12+360)/2,(AW12-360)/2),AW12/2))) | AY12: =IF(OR($C12="",F12=""),"",1-0.17*COS(RADIANS(AX12-30))+0.24*COS(RADIANS(2*AX12))+0.32*COS(RADIANS(3*AX12+6))-0.2*COS(RADIANS(4*AX12-63))) | AZ12: =IF(OR($C12="",F12=""),"",2*SQRT(AV12^7/(AV12^7+25^7))) | BA12: =IF(OR($C12="",F12=""),"",1+0.015*(AU12-50)^2/SQRT(20+(AU12-50)^2)) | BB12: =IF(OR($C12="",F12=""),"",1+0.045*AV12) | BC12: =IF(OR($C12="",F12=""),"",1+0.015*AV12*AY12) | BD12: =IF(OR($C12="",F12=""),"",-SIN(RADIANS(2*30*EXP(-(((AX12-275)/25)^2))))*AZ12)
G13: =IF($C13="","",INDEX(Matrices!$G$2:$G$15,T13)*C13+INDEX(Matrices!$H$2:$H$15,T13)*D13+INDEX(Matrices!$I$2:$I$15,T13)*E13) | H13: =IF($C13="","",INDEX(Matrices!$J$2:$J$15,T13)*C13+INDEX(Matrices!$K$2:$K$15,T13)*D13+INDEX(Matrices!$L$2:$L$15,T13)*E13) | I13: =IF($C13="","",INDEX(Matrices!$M$2:$M$15,T13)*C13+INDEX(Matrices!$N$2:$N$15,T13)*D13+INDEX(Matrices!$O$2:$O$15,T13)*E13) | J13: =IF($C13="","",W13) | K13: =IF($C13="","",AC13*COS(RADIANS(V13))) | L13: =IF($C13="","",AC13*SIN(RADIANS(V13))) | M13: =IF($C13="","",116*AE13-16) | N13: =IF($C13="","",500*(AD13-AE13)) | O13: =IF($C13="","",200*(AE13-AF13)) | P13: =IF(OR($C13="",F13=""),"",SQRT((J13-INDEX($J$6:$J$45,AG13))^2+(K13-INDEX($K$6:$K$45,AG13))^2+(L13-INDEX($L$6:$L$45,AG13))^2)) | Q13: =IF(OR($C13="",F13=""),"",SQRT((M13-INDEX($M$6:$M$45,AG13))^2+(N13-INDEX($N$6:$N$45,AG13))^2+(O13-INDEX($O$6:$O$45,AG13))^2)) | R13: =IF(OR($C13="",F13=""),"",SQRT(((AH13-M13)/BA13)^2+((AP13-AO13)/BB13)^2+(AT13/BC13)^2+BD13*((AP13-AO13)/BB13)*(AT13/BC13))) | T13: =IF($C13="","",MATCH(B13,Matrices!$A$2:$A$15,0)) | U13: =IF($C13="","",SQRT(H13^2+I13^2)) | V13: =IF($C13="","",IF(U13=0,0,MOD(DEGREES(ATAN2(H13,I13)),360))) | W13: =IF($C13="","",IF(G13/100>(6/29)^3,(G13/100)^(1/3),(1/3)*(29/6)^2*G13/100+16/116)*116-16) | X13: =IF($C13="","",EXP(0.026742553710937*(W13-51.576165618406904))/0.45888671875) | Y13: =IF($C13="","",U13/X13) | Z13: =IF($C13="","",IF(AND(V13>1,V13<181),SIN(RADIANS(V13-1))^3,0)+IF(AND(V13>104,V13<284),0.39*COS(RADIANS(V13-14))^2,0)) | AA13: =IF($C13="","",62*(Z13+0.31)) | AB13: =IF($C13="","",0.36*(Z13+0.19)) | AC13: =IF($C13="","",AA13*(LN(Y13/80+AB13)-LN(AB13))) | AD13: =IF($C13="","",IF(C13/INDEX(Matrices!$D$2:$D$15,T13)>0.008856,(C13/INDEX(Matrices!$D$2:$D$15,T13))^(1/3),7.787*C13/INDEX(Matrices!$D$2:$D$15,T13)+16/116)) | AE13: =IF($C13="","",IF(D13/INDEX(Matrices!$E$2:$E$15,T13)>0.008856,(D13/INDEX(Matrices!$E$2:$E$15,T13))^(1/3),7.787*D13/INDEX(Matrices!$E$2:$E$15,T13)+16/116)) | AF13: =IF($C13="","",IF(E13/INDEX(Matrices!$F$2:$F$15,T13)>0.008856,(E13/INDEX(Matrices!$F$2:$F$15,T13))^(1/3),7.787*E13/INDEX(Matrices!$F$2:$F$15,T13)+16/116)) | AG13: =IF(OR($C13="",F13=""),"",MATCH(F13,$A$6:$A$45,0)) | AH13: =IF(OR($C13="",F13=""),"",INDEX($M$6:$M$45,AG13)) | AI13: =IF(OR($C13="",F13=""),"",INDEX($N$6:$N$45,AG13)) | AJ13: =IF(OR($C13="",F13=""),"",INDEX($O$6:$O$45,AG13)) | AK13: =IF(OR($C13="",F13=""),"",(SQRT(N13^2+O13^2)+SQRT(AI13^2+AJ13^2))/2) | AL13: =IF(OR($C13="",F13=""),"",0.5*(1-SQRT(AK13^7/(AK13^7+25^7)))) | AM13: =IF(OR($C13="",F13=""),"",(1+AL13)*N13) | AN13: =IF(OR($C13="",F13=""),"",(1+AL13)*AI13) | AO13: =IF(OR($C13="",F13=""),"",SQRT(AM13^2+O13^2)) | AP13: =IF(OR($C13="",F13=""),"",SQRT(AN13^2+AJ13^2)) | AQ13: =IF(OR($C13="",F13=""),"",IF(AO13=0,0,MOD(DEGREES(ATAN2(AM13,O13)),360))) | AR13: =IF(OR($C13="",F13=""),"",IF(AP13=0,0,MOD(DEGREES(ATAN2(AN13,AJ13)),360))) | AS13: =IF(OR($C13="",F13=""),"",IF(AO13*AP13=0,0,IF((AR13-AQ13)>180,(AR13-AQ13)-360,IF((AR13-AQ13)<-180,(AR13-AQ13)+360,(AR13-AQ13))))) | AT13: =IF(OR($C13="",F13=""),"",2*SQRT(AO13*AP13)*SIN(RADIANS(AS13/2))) | AU13: =IF(OR($C13="",F13=""),"",(M13+AH13)/2) | AV13: =IF(OR($C13="",F13=""),"",(AO13+AP13)/2) | AW13: =IF(OR($C13="",F13=""),"",AQ13+AR13) | AX13: =IF(OR($C13="",F13=""),"",IF(AO13*AP13=0,AW13,IF(ABS(AQ13-AR13)>180,IF(AW13<360,(AW13+360)/2,(AW13-360)/2),AW13/2))) | AY13: =IF(OR($C13="",F13=""),"",1-0.17*COS(RADIANS(AX13-30))+0.24*COS(RADIANS(2*AX13))+0.32*COS(RADIANS(3*AX13+6))-0.2*COS(RADIANS(4*AX13-63))) | AZ13: =IF(OR($C13="",F13=""),"",2*SQRT(AV13^7/(AV13^7+25^7))) | BA13: =IF(OR($C13="",F13=""),"",1+0.015*(AU13-50)^2/SQRT(20+(AU13-50)^2)) | BB13: =IF(OR($C13="",F13=""),"",1+0.045*AV13) | BC13: =IF(OR($C13="",F13=""),"",1+0.015*AV13*AY13) | BD13: =IF(OR($C13="",F13=""),"",-SIN(RADIANS(2*30*EXP(-(((AX13-275)/25)^2))))*AZ13)
G14: =IF($C14="","",INDEX(Matrices!$G$2:$G$15,T14)*C14+INDEX(Matrices!$H$2:$H$15,T14)*D14+INDEX(Matrices!$I$2:$I$15,T14)*E14) | H14: =IF($C14="","",INDEX(Matrices!$J$2:$J$15,T14)*C14+INDEX(Matrices!$K$2:$K$15,T14)*D14+INDEX(Matrices!$L$2:$L$15,T14)*E14) | I14: =IF($C14="","",INDEX(Matrices!$M$2:$M$15,T14)*C14+INDEX(Matrices!$N$2:$N$15,T14)*D14+INDEX(Matrices!$O$2:$O$15,T14)*E14) | J14: =IF($C14="","",W14) | K14: =IF($C14="","",AC14*COS(RADIANS(V14))) | L14: =IF($C14="","",AC14*SIN(RADIANS(V14))) | M14: =IF($C14="","",116*AE14-16) | N14: =IF($C14="","",500*(AD14-AE14)) | O14: =IF($C14="","",200*(AE14-AF14)) | P14: =IF(OR($C14="",F14=""),"",SQRT((J14-INDEX($J$6:$J$45,AG14))^2+(K14-INDEX($K$6:$K$45,AG14))^2+(L14-INDEX($L$6:$L$45,AG14))^2)) | Q14: =IF(OR($C14="",F14=""),"",SQRT((M14-INDEX($M$6:$M$45,AG14))^2+(N14-INDEX($N$6:$N$45,AG14))^2+(O14-INDEX($O$6:$O$45,AG14))^2)) | R14: =IF(OR($C14="",F14=""),"",SQRT(((AH14-M14)/BA14)^2+((AP14-AO14)/BB14)^2+(AT14/BC14)^2+BD14*((AP14-AO14)/BB14)*(AT14/BC14))) | T14: =IF($C14="","",MATCH(B14,Matrices!$A$2:$A$15,0)) | U14: =IF($C14="","",SQRT(H14^2+I14^2)) | V14: =IF($C14="","",IF(U14=0,0,MOD(DEGREES(ATAN2(H14,I14)),360))) | W14: =IF($C14="","",IF(G14/100>(6/29)^3,(G14/100)^(1/3),(1/3)*(29/6)^2*G14/100+16/116)*116-16) | X14: =IF($C14="","",EXP(0.026742553710937*(W14-51.576165618406904))/0.45888671875) | Y14: =IF($C14="","",U14/X14) | Z14: =IF($C14="","",IF(AND(V14>1,V14<181),SIN(RADIANS(V14-1))^3,0)+IF(AND(V14>104,V14<284),0.39*COS(RADIANS(V14-14))^2,0)) | AA14: =IF($C14="","",62*(Z14+0.31)) | AB14: =IF($C14="","",0.36*(Z14+0.19)) | AC14: =IF($C14="","",AA14*(LN(Y14/80+AB14)-LN(AB14))) | AD14: =IF($C14="","",IF(C14/INDEX(Matrices!$D$2:$D$15,T14)>0.008856,(C14/INDEX(Matrices!$D$2:$D$15,T14))^(1/3),7.787*C14/INDEX(Matrices!$D$2:$D$15,T14)+16/116)) | AE14: =IF($C14="","",IF(D14/INDEX(Matrices!$E$2:$E$15,T14)>0.008856,(D14/INDEX(Matrices!$E$2:$E$15,T14))^(1/3),7.787*D14/INDEX(Matrices!$E$2:$E$15,T14)+16/116)) | AF14: =IF($C14="","",IF(E14/INDEX(Matrices!$F$2:$F$15,T14)>0.008856,(E14/INDEX(Matrices!$F$2:$F$15,T14))^(1/3),7.787*E14/INDEX(Matrices!$F$2:$F$15,T14)+16/116)) | AG14: =IF(OR($C14="",F14=""),"",MATCH(F14,$A$6:$A$45,0)) | AH14: =IF(OR($C14="",F14=""),"",INDEX($M$6:$M$45,AG14)) | AI14: =IF(OR($C14="",F14=""),"",INDEX($N$6:$N$45,AG14)) | AJ14: =IF(OR($C14="",F14=""),"",INDEX($O$6:$O$45,AG14)) | AK14: =IF(OR($C14="",F14=""),"",(SQRT(N14^2+O14^2)+SQRT(AI14^2+AJ14^2))/2) | AL14: =IF(OR($C14="",F14=""),"",0.5*(1-SQRT(AK14^7/(AK14^7+25^7)))) | AM14: =IF(OR($C14="",F14=""),"",(1+AL14)*N14) | AN14: =IF(OR($C14="",F14=""),"",(1+AL14)*AI14) | AO14: =IF(OR($C14="",F14=""),"",SQRT(AM14^2+O14^2)) | AP14: =IF(OR($C14="",F14=""),"",SQRT(AN14^2+AJ14^2)) | AQ14: =IF(OR($C14="",F14=""),"",IF(AO14=0,0,MOD(DEGREES(ATAN2(AM14,O14)),360))) | AR14: =IF(OR($C14="",F14=""),"",IF(AP14=0,0,MOD(DEGREES(ATAN2(AN14,AJ14)),360))) | AS14: =IF(OR($C14="",F14=""),"",IF(AO14*AP14=0,0,IF((AR14-AQ14)>180,(AR14-AQ14)-360,IF((AR14-AQ14)<-180,(AR14-AQ14)+360,(AR14-AQ14))))) | AT14: =IF(OR($C14="",F14=""),"",2*SQRT(AO14*AP14)*SIN(RADIANS(AS14/2))) | AU14: =IF(OR($C14="",F14=""),"",(M14+AH14)/2) | AV14: =IF(OR($C14="",F14=""),"",(AO14+AP14)/2) | AW14: =IF(OR($C14="",F14=""),"",AQ14+AR14) | AX14: =IF(OR($C14="",F14=""),"",IF(AO14*AP14=0,AW14,IF(ABS(AQ14-AR14)>180,IF(AW14<360,(AW14+360)/2,(AW14-360)/2),AW14/2))) | AY14: =IF(OR($C14="",F14=""),"",1-0.17*COS(RADIANS(AX14-30))+0.24*COS(RADIANS(2*AX14))+0.32*COS(RADIANS(3*AX14+6))-0.2*COS(RADIANS(4*AX14-63))) | AZ14: =IF(OR($C14="",F14=""),"",2*SQRT(AV14^7/(AV14^7+25^7))) | BA14: =IF(OR($C14="",F14=""),"",1+0.015*(AU14-50)^2/SQRT(20+(AU14-50)^2)) | BB14: =IF(OR($C14="",F14=""),"",1+0.045*AV14) | BC14: =IF(OR($C14="",F14=""),"",1+0.015*AV14*AY14) | BD14: =IF(OR($C14="",F14=""),"",-SIN(RADIANS(2*30*EXP(-(((AX14-275)/25)^2))))*AZ14)
G15: =IF($C15="","",INDEX(Matrices!$G$2:$G$15,T15)*C15+INDEX(Matrices!$H$2:$H$15,T15)*D15+INDEX(Matrices!$I$2:$I$15,T15)*E15) | H15: =IF($C15="","",INDEX(Matrices!$J$2:$J$15,T15)*C15+INDEX(Matrices!$K$2:$K$15,T15)*D15+INDEX(Matrices!$L$2:$L$15,T15)*E15) | I15: =IF($C15="","",INDEX(Matrices!$M$2:$M$15,T15)*C15+INDEX(Matrices!$N$2:$N$15,T15)*D15+INDEX(Matrices!$O$2:$O$15,T15)*E15) | J15: =IF($C15="","",W15) | K15: =IF($C15="","",AC15*COS(RADIANS(V15))) | L15: =IF($C15="","",AC15*SIN(RADIANS(V15))) | M15: =IF($C15="","",116*AE15-16) | N15: =IF($C15="","",500*(AD15-AE15)) | O15: =IF($C15="","",200*(AE15-AF15)) | P15: =IF(OR($C15="",F15=""),"",SQRT((J15-INDEX($J$6:$J$45,AG15))^2+(K15-INDEX($K$6:$K$45,AG15))^2+(L15-INDEX($L$6:$L$45,AG15))^2)) | Q15: =IF(OR($C15="",F15=""),"",SQRT((M15-INDEX($M$6:$M$45,AG15))^2+(N15-INDEX($N$6:$N$45,AG15))^2+(O15-INDEX($O$6:$O$45,AG15))^2)) | R15: =IF(OR($C15="",F15=""),"",SQRT(((AH15-M15)/BA15)^2+((AP15-AO15)/BB15)^2+(AT15/BC15)^2+BD15*((AP15-AO15)/BB15)*(AT15/BC15))) | T15: =IF($C15="","",MATCH(B15,Matrices!$A$2:$A$15,0)) | U15: =IF($C15="","",SQRT(H15^2+I15^2)) | V15: =IF($C15="","",IF(U15=0,0,MOD(DEGREES(ATAN2(H15,I15)),360))) | W15: =IF($C15="","",IF(G15/100>(6/29)^3,(G15/100)^(1/3),(1/3)*(29/6)^2*G15/100+16/116)*116-16) | X15: =IF($C15="","",EXP(0.026742553710937*(W15-51.576165618406904))/0.45888671875) | Y15: =IF($C15="","",U15/X15) | Z15: =IF($C15="","",IF(AND(V15>1,V15<181),SIN(RADIANS(V15-1))^3,0)+IF(AND(V15>104,V15<284),0.39*COS(RADIANS(V15-14))^2,0)) | AA15: =IF($C15="","",62*(Z15+0.31)) | AB15: =IF($C15="","",0.36*(Z15+0.19)) | AC15: =IF($C15="","",AA15*(LN(Y15/80+AB15)-LN(AB15))) | AD15: =IF($C15="","",IF(C15/INDEX(Matrices!$D$2:$D$15,T15)>0.008856,(C15/INDEX(Matrices!$D$2:$D$15,T15))^(1/3),7.787*C15/INDEX(Matrices!$D$2:$D$15,T15)+16/116)) | AE15: =IF($C15="","",IF(D15/INDEX(Matrices!$E$2:$E$15,T15)>0.008856,(D15/INDEX(Matrices!$E$2:$E$15,T15))^(1/3),7.787*D15/INDEX(Matrices!$E$2:$E$15,T15)+16/116)) | AF15: =IF($C15="","",IF(E15/INDEX(Matrices!$F$2:$F$15,T15)>0.008856,(E15/INDEX(Matrices!$F$2:$F$15,T15))^(1/3),7.787*E15/INDEX(Matrices!$F$2:$F$15,T15)+16/116)) | AG15: =IF(OR($C15="",F15=""),"",MATCH(F15,$A$6:$A$45,0)) | AH15: =IF(OR($C15="",F15=""),"",INDEX($M$6:$M$45,AG15)) | AI15: =IF(OR($C15="",F15=""),"",INDEX($N$6:$N$45,AG15)) | AJ15: =IF(OR($C15="",F15=""),"",INDEX($O$6:$O$45,AG15)) | AK15: =IF(OR($C15="",F15=""),"",(SQRT(N15^2+O15^2)+SQRT(AI15^2+AJ15^2))/2) | AL15: =IF(OR($C15="",F15=""),"",0.5*(1-SQRT(AK15^7/(AK15^7+25^7)))) | AM15: =IF(OR($C15="",F15=""),"",(1+AL15)*N15) | AN15: =IF(OR($C15="",F15=""),"",(1+AL15)*AI15) | AO15: =IF(OR($C15="",F15=""),"",SQRT(AM15^2+O15^2)) | AP15: =IF(OR($C15="",F15=""),"",SQRT(AN15^2+AJ15^2)) | AQ15: =IF(OR($C15="",F15=""),"",IF(AO15=0,0,MOD(DEGREES(ATAN2(AM15,O15)),360))) | AR15: =IF(OR($C15="",F15=""),"",IF(AP15=0,0,MOD(DEGREES(ATAN2(AN15,AJ15)),360))) | AS15: =IF(OR($C15="",F15=""),"",IF(AO15*AP15=0,0,IF((AR15-AQ15)>180,(AR15-AQ15)-360,IF((AR15-AQ15)<-180,(AR15-AQ15)+360,(AR15-AQ15))))) | AT15: =IF(OR($C15="",F15=""),"",2*SQRT(AO15*AP15)*SIN(RADIANS(AS15/2))) | AU15: =IF(OR($C15="",F15=""),"",(M15+AH15)/2) | AV15: =IF(OR($C15="",F15=""),"",(AO15+AP15)/2) | AW15: =IF(OR($C15="",F15=""),"",AQ15+AR15) | AX15: =IF(OR($C15="",F15=""),"",IF(AO15*AP15=0,AW15,IF(ABS(AQ15-AR15)>180,IF(AW15<360,(AW15+360)/2,(AW15-360)/2),AW15/2))) | AY15: =IF(OR($C15="",F15=""),"",1-0.17*COS(RADIANS(AX15-30))+0.24*COS(RADIANS(2*AX15))+0.32*COS(RADIANS(3*AX15+6))-0.2*COS(RADIANS(4*AX15-63))) | AZ15: =IF(OR($C15="",F15=""),"",2*SQRT(AV15^7/(AV15^7+25^7))) | BA15: =IF(OR($C15="",F15=""),"",1+0.015*(AU15-50)^2/SQRT(20+(AU15-50)^2)) | BB15: =IF(OR($C15="",F15=""),"",1+0.045*AV15) | BC15: =IF(OR($C15="",F15=""),"",1+0.015*AV15*AY15) | BD15: =IF(OR($C15="",F15=""),"",-SIN(RADIANS(2*30*EXP(-(((AX15-275)/25)^2))))*AZ15)
G16: =IF($C16="","",INDEX(Matrices!$G$2:$G$15,T16)*C16+INDEX(Matrices!$H$2:$H$15,T16)*D16+INDEX(Matrices!$I$2:$I$15,T16)*E16) | H16: =IF($C16="","",INDEX(Matrices!$J$2:$J$15,T16)*C16+INDEX(Matrices!$K$2:$K$15,T16)*D16+INDEX(Matrices!$L$2:$L$15,T16)*E16) | I16: =IF($C16="","",INDEX(Matrices!$M$2:$M$15,T16)*C16+INDEX(Matrices!$N$2:$N$15,T16)*D16+INDEX(Matrices!$O$2:$O$15,T16)*E16) | J16: =IF($C16="","",W16) | K16: =IF($C16="","",AC16*COS(RADIANS(V16))) | L16: =IF($C16="","",AC16*SIN(RADIANS(V16))) | M16: =IF($C16="","",116*AE16-16) | N16: =IF($C16="","",500*(AD16-AE16)) | O16: =IF($C16="","",200*(AE16-AF16)) | P16: =IF(OR($C16="",F16=""),"",SQRT((J16-INDEX($J$6:$J$45,AG16))^2+(K16-INDEX($K$6:$K$45,AG16))^2+(L16-INDEX($L$6:$L$45,AG16))^2)) | Q16: =IF(OR($C16="",F16=""),"",SQRT((M16-INDEX($M$6:$M$45,AG16))^2+(N16-INDEX($N$6:$N$45,AG16))^2+(O16-INDEX($O$6:$O$45,AG16))^2)) | R16: =IF(OR($C16="",F16=""),"",SQRT(((AH16-M16)/BA16)^2+((AP16-AO16)/BB16)^2+(AT16/BC16)^2+BD16*((AP16-AO16)/BB16)*(AT16/BC16))) | T16: =IF($C16="","",MATCH(B16,Matrices!$A$2:$A$15,0)) | U16: =IF($C16="","",SQRT(H16^2+I16^2)) | V16: =IF($C16="","",IF(U16=0,0,MOD(DEGREES(ATAN2(H16,I16)),360))) | W16: =IF($C16="","",IF(G16/100>(6/29)^3,(G16/100)^(1/3),(1/3)*(29/6)^2*G16/100+16/116)*116-16) | X16: =IF($C16="","",EXP(0.026742553710937*(W16-51.576165618406904))/0.45888671875) | Y16: =IF($C16="","",U16/X16) | Z16: =IF($C16="","",IF(AND(V16>1,V16<181),SIN(RADIANS(V16-1))^3,0)+IF(AND(V16>104,V16<284),0.39*COS(RADIANS(V16-14))^2,0)) | AA16: =IF($C16="","",62*(Z16+0.31)) | AB16: =IF($C16="","",0.36*(Z16+0.19)) | AC16: =IF($C16="","",AA16*(LN(Y16/80+AB16)-LN(AB16))) | AD16: =IF($C16="","",IF(C16/INDEX(Matrices!$D$2:$D$15,T16)>0.008856,(C16/INDEX(Matrices!$D$2:$D$15,T16))^(1/3),7.787*C16/INDEX(Matrices!$D$2:$D$15,T16)+16/116)) | AE16: =IF($C16="","",IF(D16/INDEX(Matrices!$E$2:$E$15,T16)>0.008856,(D16/INDEX(Matrices!$E$2:$E$15,T16))^(1/3),7.787*D16/INDEX(Matrices!$E$2:$E$15,T16)+16/116)) | AF16: =IF($C16="","",IF(E16/INDEX(Matrices!$F$2:$F$15,T16)>0.008856,(E16/INDEX(Matrices!$F$2:$F$15,T16))^(1/3),7.787*E16/INDEX(Matrices!$F$2:$F$15,T16)+16/116)) | AG16: =IF(OR($C16="",F16=""),"",MATCH(F16,$A$6:$A$45,0)) | AH16: =IF(OR($C16="",F16=""),"",INDEX($M$6:$M$45,AG16)) | AI16: =IF(OR($C16="",F16=""),"",INDEX($N$6:$N$45,AG16)) | AJ16: =IF(OR($C16="",F16=""),"",INDEX($O$6:$O$45,AG16)) | AK16: =IF(OR($C16="",F16=""),"",(SQRT(N16^2+O16^2)+SQRT(AI16^2+AJ16^2))/2) | AL16: =IF(OR($C16="",F16=""),"",0.5*(1-SQRT(AK16^7/(AK16^7+25^7)))) | AM16: =IF(OR($C16="",F16=""),"",(1+AL16)*N16) | AN16: =IF(OR($C16="",F16=""),"",(1+AL16)*AI16) | AO16: =IF(OR($C16="",F16=""),"",SQRT(AM16^2+O16^2)) | AP16: =IF(OR($C16="",F16=""),"",SQRT(AN16^2+AJ16^2)) | AQ16: =IF(OR($C16="",F16=""),"",IF(AO16=0,0,MOD(DEGREES(ATAN2(AM16,O16)),360))) | AR16: =IF(OR($C16="",F16=""),"",IF(AP16=0,0,MOD(DEGREES(ATAN2(AN16,AJ16)),360))) | AS16: =IF(OR($C16="",F16=""),"",IF(AO16*AP16=0,0,IF((AR16-AQ16)>180,(AR16-AQ16)-360,IF((AR16-AQ16)<-180,(AR16-AQ16)+360,(AR16-AQ16))))) | AT16: =IF(OR($C16="",F16=""),"",2*SQRT(AO16*AP16)*SIN(RADIANS(AS16/2))) | AU16: =IF(OR($C16="",F16=""),"",(M16+AH16)/2) | AV16: =IF(OR($C16="",F16=""),"",(AO16+AP16)/2) | AW16: =IF(OR($C16="",F16=""),"",AQ16+AR16) | AX16: =IF(OR($C16="",F16=""),"",IF(AO16*AP16=0,AW16,IF(ABS(AQ16-AR16)>180,IF(AW16<360,(AW16+360)/2,(AW16-360)/2),AW16/2))) | AY16: =IF(OR($C16="",F16=""),"",1-0.17*COS(RADIANS(AX16-30))+0.24*COS(RADIANS(2*AX16))+0.32*COS(RADIANS(3*AX16+6))-0.2*COS(RADIANS(4*AX16-63))) | AZ16: =IF(OR($C16="",F16=""),"",2*SQRT(AV16^7/(AV16^7+25^7))) | BA16: =IF(OR($C16="",F16=""),"",1+0.015*(AU16-50)^2/SQRT(20+(AU16-50)^2)) | BB16: =IF(OR($C16="",F16=""),"",1+0.045*AV16) | BC16: =IF(OR($C16="",F16=""),"",1+0.015*AV16*AY16) | BD16: =IF(OR($C16="",F16=""),"",-SIN(RADIANS(2*30*EXP(-(((AX16-275)/25)^2))))*AZ16)
G17: =IF($C17="","",INDEX(Matrices!$G$2:$G$15,T17)*C17+INDEX(Matrices!$H$2:$H$15,T17)*D17+INDEX(Matrices!$I$2:$I$15,T17)*E17) | H17: =IF($C17="","",INDEX(Matrices!$J$2:$J$15,T17)*C17+INDEX(Matrices!$K$2:$K$15,T17)*D17+INDEX(Matrices!$L$2:$L$15,T17)*E17) | I17: =IF($C17="","",INDEX(Matrices!$M$2:$M$15,T17)*C17+INDEX(Matrices!$N$2:$N$15,T17)*D17+INDEX(Matrices!$O$2:$O$15,T17)*E17) | J17: =IF($C17="","",W17) | K17: =IF($C17="","",AC17*COS(RADIANS(V17))) | L17: =IF($C17="","",AC17*SIN(RADIANS(V17))) | M17: =IF($C17="","",116*AE17-16) | N17: =IF($C17="","",500*(AD17-AE17)) | O17: =IF($C17="","",200*(AE17-AF17)) | P17: =IF(OR($C17="",F17=""),"",SQRT((J17-INDEX($J$6:$J$45,AG17))^2+(K17-INDEX($K$6:$K$45,AG17))^2+(L17-INDEX($L$6:$L$45,AG17))^2)) | Q17: =IF(OR($C17="",F17=""),"",SQRT((M17-INDEX($M$6:$M$45,AG17))^2+(N17-INDEX($N$6:$N$45,AG17))^2+(O17-INDEX($O$6:$O$45,AG17))^2)) | R17: =IF(OR($C17="",F17=""),"",SQRT(((AH17-M17)/BA17)^2+((AP17-AO17)/BB17)^2+(AT17/BC17)^2+BD17*((AP17-AO17)/BB17)*(AT17/BC17))) | T17: =IF($C17="","",MATCH(B17,Matrices!$A$2:$A$15,0)) | U17: =IF($C17="","",SQRT(H17^2+I17^2)) | V17: =IF($C17="","",IF(U17=0,0,MOD(DEGREES(ATAN2(H17,I17)),360))) | W17: =IF($C17="","",IF(G17/100>(6/29)^3,(G17/100)^(1/3),(1/3)*(29/6)^2*G17/100+16/116)*116-16) | X17: =IF($C17="","",EXP(0.026742553710937*(W17-51.576165618406904))/0.45888671875) | Y17: =IF($C17="","",U17/X17) | Z17: =IF($C17="","",IF(AND(V17>1,V17<181),SIN(RADIANS(V17-1))^3,0)+IF(AND(V17>104,V17<284),0.39*COS(RADIANS(V17-14))^2,0)) | AA17: =IF($C17="","",62*(Z17+0.31)) | AB17: =IF($C17="","",0.36*(Z17+0.19)) | AC17: =IF($C17="","",AA17*(LN(Y17/80+AB17)-LN(AB17))) | AD17: =IF($C17="","",IF(C17/INDEX(Matrices!$D$2:$D$15,T17)>0.008856,(C17/INDEX(Matrices!$D$2:$D$15,T17))^(1/3),7.787*C17/INDEX(Matrices!$D$2:$D$15,T17)+16/116)) | AE17: =IF($C17="","",IF(D17/INDEX(Matrices!$E$2:$E$15,T17)>0.008856,(D17/INDEX(Matrices!$E$2:$E$15,T17))^(1/3),7.787*D17/INDEX(Matrices!$E$2:$E$15,T17)+16/116)) | AF17: =IF($C17="","",IF(E17/INDEX(Matrices!$F$2:$F$15,T17)>0.008856,(E17/INDEX(Matrices!$F$2:$F$15,T17))^(1/3),7.787*E17/INDEX(Matrices!$F$2:$F$15,T17)+16/116)) | AG17: =IF(OR($C17="",F17=""),"",MATCH(F17,$A$6:$A$45,0)) | AH17: =IF(OR($C17="",F17=""),"",INDEX($M$6:$M$45,AG17)) | AI17: =IF(OR($C17="",F17=""),"",INDEX($N$6:$N$45,AG17)) | AJ17: =IF(OR($C17="",F17=""),"",INDEX($O$6:$O$45,AG17)) | AK17: =IF(OR($C17="",F17=""),"",(SQRT(N17^2+O17^2)+SQRT(AI17^2+AJ17^2))/2) | AL17: =IF(OR($C17="",F17=""),"",0.5*(1-SQRT(AK17^7/(AK17^7+25^7)))) | AM17: =IF(OR($C17="",F17=""),"",(1+AL17)*N17) | AN17: =IF(OR($C17="",F17=""),"",(1+AL17)*AI17) | AO17: =IF(OR($C17="",F17=""),"",SQRT(AM17^2+O17^2)) | AP17: =IF(OR($C17="",F17=""),"",SQRT(AN17^2+AJ17^2)) | AQ17: =IF(OR($C17="",F17=""),"",IF(AO17=0,0,MOD(DEGREES(ATAN2(AM17,O17)),360))) | AR17: =IF(OR($C17="",F17=""),"",IF(AP17=0,0,MOD(DEGREES(ATAN2(AN17,AJ17)),360))) | AS17: =IF(OR($C17="",F17=""),"",IF(AO17*AP17=0,0,IF((AR17-AQ17)>180,(AR17-AQ17)-360,IF((AR17-AQ17)<-180,(AR17-AQ17)+360,(AR17-AQ17))))) | AT17: =IF(OR($C17="",F17=""),"",2*SQRT(AO17*AP17)*SIN(RADIANS(AS17/2))) | AU17: =IF(OR($C17="",F17=""),"",(M17+AH17)/2) | AV17: =IF(OR($C17="",F17=""),"",(AO17+AP17)/2) | AW17: =IF(OR($C17="",F17=""),"",AQ17+AR17) | AX17: =IF(OR($C17="",F17=""),"",IF(AO17*AP17=0,AW17,IF(ABS(AQ17-AR17)>180,IF(AW17<360,(AW17+360)/2,(AW17-360)/2),AW17/2))) | AY17: =IF(OR($C17="",F17=""),"",1-0.17*COS(RADIANS(AX17-30))+0.24*COS(RADIANS(2*AX17))+0.32*COS(RADIANS(3*AX17+6))-0.2*COS(RADIANS(4*AX17-63))) | AZ17: =IF(OR($C17="",F17=""),"",2*SQRT(AV17^7/(AV17^7+25^7))) | BA17: =IF(OR($C17="",F17=""),"",1+0.015*(AU17-50)^2/SQRT(20+(AU17-50)^2)) | BB17: =IF(OR($C17="",F17=""),"",1+0.045*AV17) | BC17: =IF(OR($C17="",F17=""),"",1+0.015*AV17*AY17) | BD17: =IF(OR($C17="",F17=""),"",-SIN(RADIANS(2*30*EXP(-(((AX17-275)/25)^2))))*AZ17)
G18: =IF($C18="","",INDEX(Matrices!$G$2:$G$15,T18)*C18+INDEX(Matrices!$H$2:$H$15,T18)*D18+INDEX(Matrices!$I$2:$I$15,T18)*E18) | H18: =IF($C18="","",INDEX(Matrices!$J$2:$J$15,T18)*C18+INDEX(Matrices!$K$2:$K$15,T18)*D18+INDEX(Matrices!$L$2:$L$15,T18)*E18) | I18: =IF($C18="","",INDEX(Matrices!$M$2:$M$15,T18)*C18+INDEX(Matrices!$N$2:$N$15,T18)*D18+INDEX(Matrices!$O$2:$O$15,T18)*E18) | J18: =IF($C18="","",W18) | K18: =IF($C18="","",AC18*COS(RADIANS(V18))) | L18: =IF($C18="","",AC18*SIN(RADIANS(V18))) | M18: =IF($C18="","",116*AE18-16) | N18: =IF($C18="","",500*(AD18-AE18)) | O18: =IF($C18="","",200*(AE18-AF18)) | P18: =IF(OR($C18="",F18=""),"",SQRT((J18-INDEX($J$6:$J$45,AG18))^2+(K18-INDEX($K$6:$K$45,AG18))^2+(L18-INDEX($L$6:$L$45,AG18))^2)) | Q18: =IF(OR($C18="",F18=""),"",SQRT((M18-INDEX($M$6:$M$45,AG18))^2+(N18-INDEX($N$6:$N$45,AG18))^2+(O18-INDEX($O$6:$O$45,AG18))^2)) | R18: =IF(OR($C18="",F18=""),"",SQRT(((AH18-M18)/BA18)^2+((AP18-AO18)/BB18)^2+(AT18/BC18)^2+BD18*((AP18-AO18)/BB18)*(AT18/BC18))) | T18: =IF($C18="","",MATCH(B18,Matrices!$A$2:$A$15,0)) | U18: =IF($C18="","",SQRT(H18^2+I18^2)) | V18: =IF($C18="","",IF(U18=0,0,MOD(DEGREES(ATAN2(H18,I18)),360))) | W18: =IF($C18="","",IF(G18/100>(6/29)^3,(G18/100)^(1/3),(1/3)*(29/6)^2*G18/100+16/116)*116-16) | X18: =IF($C18="","",EXP(0.026742553710937*(W18-51.576165618406904))/0.45888671875) | Y18: =IF($C18="","",U18/X18) | Z18: =IF($C18="","",IF(AND(V18>1,V18<181),SIN(RADIANS(V18-1))^3,0)+IF(AND(V18>104,V18<284),0.39*COS(RADIANS(V18-14))^2,0)) | AA18: =IF($C18="","",62*(Z18+0.31)) | AB18: =IF($C18="","",0.36*(Z18+0.19)) | AC18: =IF($C18="","",AA18*(LN(Y18/80+AB18)-LN(AB18))) | AD18: =IF($C18="","",IF(C18/INDEX(Matrices!$D$2:$D$15,T18)>0.008856,(C18/INDEX(Matrices!$D$2:$D$15,T18))^(1/3),7.787*C18/INDEX(Matrices!$D$2:$D$15,T18)+16/116)) | AE18: =IF($C18="","",IF(D18/INDEX(Matrices!$E$2:$E$15,T18)>0.008856,(D18/INDEX(Matrices!$E$2:$E$15,T18))^(1/3),7.787*D18/INDEX(Matrices!$E$2:$E$15,T18)+16/116)) | AF18: =IF($C18="","",IF(E18/INDEX(Matrices!$F$2:$F$15,T18)>0.008856,(E18/INDEX(Matrices!$F$2:$F$15,T18))^(1/3),7.787*E18/INDEX(Matrices!$F$2:$F$15,T18)+16/116)) | AG18: =IF(OR($C18="",F18=""),"",MATCH(F18,$A$6:$A$45,0)) | AH18: =IF(OR($C18="",F18=""),"",INDEX($M$6:$M$45,AG18)) | AI18: =IF(OR($C18="",F18=""),"",INDEX($N$6:$N$45,AG18)) | AJ18: =IF(OR($C18="",F18=""),"",INDEX($O$6:$O$45,AG18)) | AK18: =IF(OR($C18="",F18=""),"",(SQRT(N18^2+O18^2)+SQRT(AI18^2+AJ18^2))/2) | AL18: =IF(OR($C18="",F18=""),"",0.5*(1-SQRT(AK18^7/(AK18^7+25^7)))) | AM18: =IF(OR($C18="",F18=""),"",(1+AL18)*N18) | AN18: =IF(OR($C18="",F18=""),"",(1+AL18)*AI18) | AO18: =IF(OR($C18="",F18=""),"",SQRT(AM18^2+O18^2)) | AP18: =IF(OR($C18="",F18=""),"",SQRT(AN18^2+AJ18^2)) | AQ18: =IF(OR($C18="",F18=""),"",IF(AO18=0,0,MOD(DEGREES(ATAN2(AM18,O18)),360))) | AR18: =IF(OR($C18="",F18=""),"",IF(AP18=0,0,MOD(DEGREES(ATAN2(AN18,AJ18)),360))) | AS18: =IF(OR($C18="",F18=""),"",IF(AO18*AP18=0,0,IF((AR18-AQ18)>180,(AR18-AQ18)-360,IF((AR18-AQ18)<-180,(AR18-AQ18)+360,(AR18-AQ18))))) | AT18: =IF(OR($C18="",F18=""),"",2*SQRT(AO18*AP18)*SIN(RADIANS(AS18/2))) | AU18: =IF(OR($C18="",F18=""),"",(M18+AH18)/2) | AV18: =IF(OR($C18="",F18=""),"",(AO18+AP18)/2) | AW18: =IF(OR($C18="",F18=""),"",AQ18+AR18) | AX18: =IF(OR($C18="",F18=""),"",IF(AO18*AP18=0,AW18,IF(ABS(AQ18-AR18)>180,IF(AW18<360,(AW18+360)/2,(AW18-360)/2),AW18/2))) | AY18: =IF(OR($C18="",F18=""),"",1-0.17*COS(RADIANS(AX18-30))+0.24*COS(RADIANS(2*AX18))+0.32*COS(RADIANS(3*AX18+6))-0.2*COS(RADIANS(4*AX18-63))) | AZ18: =IF(OR($C18="",F18=""),"",2*SQRT(AV18^7/(AV18^7+25^7))) | BA18: =IF(OR($C18="",F18=""),"",1+0.015*(AU18-50)^2/SQRT(20+(AU18-50)^2)) | BB18: =IF(OR($C18="",F18=""),"",1+0.045*AV18) | BC18: =IF(OR($C18="",F18=""),"",1+0.015*AV18*AY18) | BD18: =IF(OR($C18="",F18=""),"",-SIN(RADIANS(2*30*EXP(-(((AX18-275)/25)^2))))*AZ18)
G19: =IF($C19="","",INDEX(Matrices!$G$2:$G$15,T19)*C19+INDEX(Matrices!$H$2:$H$15,T19)*D19+INDEX(Matrices!$I$2:$I$15,T19)*E19) | H19: =IF($C19="","",INDEX(Matrices!$J$2:$J$15,T19)*C19+INDEX(Matrices!$K$2:$K$15,T19)*D19+INDEX(Matrices!$L$2:$L$15,T19)*E19) | I19: =IF($C19="","",INDEX(Matrices!$M$2:$M$15,T19)*C19+INDEX(Matrices!$N$2:$N$15,T19)*D19+INDEX(Matrices!$O$2:$O$15,T19)*E19) | J19: =IF($C19="","",W19) | K19: =IF($C19="","",AC19*COS(RADIANS(V19))) | L19: =IF($C19="","",AC19*SIN(RADIANS(V19))) | M19: =IF($C19="","",116*AE19-16) | N19: =IF($C19="","",500*(AD19-AE19)) | O19: =IF($C19="","",200*(AE19-AF19)) | P19: =IF(OR($C19="",F19=""),"",SQRT((J19-INDEX($J$6:$J$45,AG19))^2+(K19-INDEX($K$6:$K$45,AG19))^2+(L19-INDEX($L$6:$L$45,AG19))^2)) | Q19: =IF(OR($C19="",F19=""),"",SQRT((M19-INDEX($M$6:$M$45,AG19))^2+(N19-INDEX($N$6:$N$45,AG19))^2+(O19-INDEX($O$6:$O$45,AG19))^2)) | R19: =IF(OR($C19="",F19=""),"",SQRT(((AH19-M19)/BA19)^2+((AP19-AO19)/BB19)^2+(AT19/BC19)^2+BD19*((AP19-AO19)/BB19)*(AT19/BC19))) | T19: =IF($C19="","",MATCH(B19,Matrices!$A$2:$A$15,0)) | U19: =IF($C19="","",SQRT(H19^2+I19^2)) | V19: =IF($C19="","",IF(U19=0,0,MOD(DEGREES(ATAN2(H19,I19)),360))) | W19: =IF($C19="","",IF(G19/100>(6/29)^3,(G19/100)^(1/3),(1/3)*(29/6)^2*G19/100+16/116)*116-16) | X19: =IF($C19="","",EXP(0.026742553710937*(W19-51.576165618406904))/0.45888671875) | Y19: =IF($C19="","",U19/X19) | Z19: =IF($C19="","",IF(AND(V19>1,V19<181),SIN(RADIANS(V19-1))^3,0)+IF(AND(V19>104,V19<284),0.39*COS(RADIANS(V19-14))^2,0)) | AA19: =IF($C19="","",62*(Z19+0.31)) | AB19: =IF($C19="","",0.36*(Z19+0.19)) | AC19: =IF($C19="","",AA19*(LN(Y19/80+AB19)-LN(AB19))) | AD19: =IF($C19="","",IF(C19/INDEX(Matrices!$D$2:$D$15,T19)>0.008856,(C19/INDEX(Matrices!$D$2:$D$15,T19))^(1/3),7.787*C19/INDEX(Matrices!$D$2:$D$15,T19)+16/116)) | AE19: =IF($C19="","",IF(D19/INDEX(Matrices!$E$2:$E$15,T19)>0.008856,(D19/INDEX(Matrices!$E$2:$E$15,T19))^(1/3),7.787*D19/INDEX(Matrices!$E$2:$E$15,T19)+16/116)) | AF19: =IF($C19="","",IF(E19/INDEX(Matrices!$F$2:$F$15,T19)>0.008856,(E19/INDEX(Matrices!$F$2:$F$15,T19))^(1/3),7.787*E19/INDEX(Matrices!$F$2:$F$15,T19)+16/116)) | AG19: =IF(OR($C19="",F19=""),"",MATCH(F19,$A$6:$A$45,0)) | AH19: =IF(OR($C19="",F19=""),"",INDEX($M$6:$M$45,AG19)) | AI19: =IF(OR($C19="",F19=""),"",INDEX($N$6:$N$45,AG19)) | AJ19: =IF(OR($C19="",F19=""),"",INDEX($O$6:$O$45,AG19)) | AK19: =IF(OR($C19="",F19=""),"",(SQRT(N19^2+O19^2)+SQRT(AI19^2+AJ19^2))/2) | AL19: =IF(OR($C19="",F19=""),"",0.5*(1-SQRT(AK19^7/(AK19^7+25^7)))) | AM19: =IF(OR($C19="",F19=""),"",(1+AL19)*N19) | AN19: =IF(OR($C19="",F19=""),"",(1+AL19)*AI19) | AO19: =IF(OR($C19="",F19=""),"",SQRT(AM19^2+O19^2)) | AP19: =IF(OR($C19="",F19=""),"",SQRT(AN19^2+AJ19^2)) | AQ19: =IF(OR($C19="",F19=""),"",IF(AO19=0,0,MOD(DEGREES(ATAN2(AM19,O19)),360))) | AR19: =IF(OR($C19="",F19=""),"",IF(AP19=0,0,MOD(DEGREES(ATAN2(AN19,AJ19)),360))) | AS19: =IF(OR($C19="",F19=""),"",IF(AO19*AP19=0,0,IF((AR19-AQ19)>180,(AR19-AQ19)-360,IF((AR19-AQ19)<-180,(AR19-AQ19)+360,(AR19-AQ19))))) | AT19: =IF(OR($C19="",F19=""),"",2*SQRT(AO19*AP19)*SIN(RADIANS(AS19/2))) | AU19: =IF(OR($C19="",F19=""),"",(M19+AH19)/2) | AV19: =IF(OR($C19="",F19=""),"",(AO19+AP19)/2) | AW19: =IF(OR($C19="",F19=""),"",AQ19+AR19) | AX19: =IF(OR($C19="",F19=""),"",IF(AO19*AP19=0,AW19,IF(ABS(AQ19-AR19)>180,IF(AW19<360,(AW19+360)/2,(AW19-360)/2),AW19/2))) | AY19: =IF(OR($C19="",F19=""),"",1-0.17*COS(RADIANS(AX19-30))+0.24*COS(RADIANS(2*AX19))+0.32*COS(RADIANS(3*AX19+6))-0.2*COS(RADIANS(4*AX19-63))) | AZ19: =IF(OR($C19="",F19=""),"",2*SQRT(AV19^7/(AV19^7+25^7))) | BA19: =IF(OR($C19="",F19=""),"",1+0.015*(AU19-50)^2/SQRT(20+(AU19-50)^2)) | BB19: =IF(OR($C19="",F19=""),"",1+0.045*AV19) | BC19: =IF(OR($C19="",F19=""),"",1+0.015*AV19*AY19) | BD19: =IF(OR($C19="",F19=""),"",-SIN(RADIANS(2*30*EXP(-(((AX19-275)/25)^2))))*AZ19)
G20: =IF($C20="","",INDEX(Matrices!$G$2:$G$15,T20)*C20+INDEX(Matrices!$H$2:$H$15,T20)*D20+INDEX(Matrices!$I$2:$I$15,T20)*E20) | H20: =IF($C20="","",INDEX(Matrices!$J$2:$J$15,T20)*C20+INDEX(Matrices!$K$2:$K$15,T20)*D20+INDEX(Matrices!$L$2:$L$15,T20)*E20) | I20: =IF($C20="","",INDEX(Matrices!$M$2:$M$15,T20)*C20+INDEX(Matrices!$N$2:$N$15,T20)*D20+INDEX(Matrices!$O$2:$O$15,T20)*E20) | J20: =IF($C20="","",W20) | K20: =IF($C20="","",AC20*COS(RADIANS(V20))) | L20: =IF($C20="","",AC20*SIN(RADIANS(V20))) | M20: =IF($C20="","",116*AE20-16) | N20: =IF($C20="","",500*(AD20-AE20)) | O20: =IF($C20="","",200*(AE20-AF20)) | P20: =IF(OR($C20="",F20=""),"",SQRT((J20-INDEX($J$6:$J$45,AG20))^2+(K20-INDEX($K$6:$K$45,AG20))^2+(L20-INDEX($L$6:$L$45,AG20))^2)) | Q20: =IF(OR($C20="",F20=""),"",SQRT((M20-INDEX($M$6:$M$45,AG20))^2+(N20-INDEX($N$6:$N$45,AG20))^2+(O20-INDEX($O$6:$O$45,AG20))^2)) | R20: =IF(OR($C20="",F20=""),"",SQRT(((AH20-M20)/BA20)^2+((AP20-AO20)/BB20)^2+(AT20/BC20)^2+BD20*((AP20-AO20)/BB20)*(AT20/BC20))) | T20: =IF($C20="","",MATCH(B20,Matrices!$A$2:$A$15,0)) | U20: =IF($C20="","",SQRT(H20^2+I20^2)) | V20: =IF($C20="","",IF(U20=0,0,MOD(DEGREES(ATAN2(H20,I20)),360))) | W20: =IF($C20="","",IF(G20/100>(6/29)^3,(G20/100)^(1/3),(1/3)*(29/6)^2*G20/100+16/116)*116-16) | X20: =IF($C20="","",EXP(0.026742553710937*(W20-51.576165618406904))/0.45888671875) | Y20: =IF($C20="","",U20/X20) | Z20: =IF($C20="","",IF(AND(V20>1,V20<181),SIN(RADIANS(V20-1))^3,0)+IF(AND(V20>104,V20<284),0.39*COS(RADIANS(V20-14))^2,0)) | AA20: =IF($C20="","",62*(Z20+0.31)) | AB20: =IF($C20="","",0.36*(Z20+0.19)) | AC20: =IF($C20="","",AA20*(LN(Y20/80+AB20)-LN(AB20))) | AD20: =IF($C20="","",IF(C20/INDEX(Matrices!$D$2:$D$15,T20)>0.008856,(C20/INDEX(Matrices!$D$2:$D$15,T20))^(1/3),7.787*C20/INDEX(Matrices!$D$2:$D$15,T20)+16/116)) | AE20: =IF($C20="","",IF(D20/INDEX(Matrices!$E$2:$E$15,T20)>0.008856,(D20/INDEX(Matrices!$E$2:$E$15,T20))^(1/3),7.787*D20/INDEX(Matrices!$E$2:$E$15,T20)+16/116)) | AF20: =IF($C20="","",IF(E20/INDEX(Matrices!$F$2:$F$15,T20)>0.008856,(E20/INDEX(Matrices!$F$2:$F$15,T20))^(1/3),7.787*E20/INDEX(Matrices!$F$2:$F$15,T20)+16/116)) | AG20: =IF(OR($C20="",F20=""),"",MATCH(F20,$A$6:$A$45,0)) | AH20: =IF(OR($C20="",F20=""),"",INDEX($M$6:$M$45,AG20)) | AI20: =IF(OR($C20="",F20=""),"",INDEX($N$6:$N$45,AG20)) | AJ20: =IF(OR($C20="",F20=""),"",INDEX($O$6:$O$45,AG20)) | AK20: =IF(OR($C20="",F20=""),"",(SQRT(N20^2+O20^2)+SQRT(AI20^2+AJ20^2))/2) | AL20: =IF(OR($C20="",F20=""),"",0.5*(1-SQRT(AK20^7/(AK20^7+25^7)))) | AM20: =IF(OR($C20="",F20=""),"",(1+AL20)*N20) | AN20: =IF(OR($C20="",F20=""),"",(1+AL20)*AI20) | AO20: =IF(OR($C20="",F20=""),"",SQRT(AM20^2+O20^2)) | AP20: =IF(OR($C20="",F20=""),"",SQRT(AN20^2+AJ20^2)) | AQ20: =IF(OR($C20="",F20=""),"",IF(AO20=0,0,MOD(DEGREES(ATAN2(AM20,O20)),360))) | AR20: =IF(OR($C20="",F20=""),"",IF(AP20=0,0,MOD(DEGREES(ATAN2(AN20,AJ20)),360))) | AS20: =IF(OR($C20="",F20=""),"",IF(AO20*AP20=0,0,IF((AR20-AQ20)>180,(AR20-AQ20)-360,IF((AR20-AQ20)<-180,(AR20-AQ20)+360,(AR20-AQ20))))) | AT20: =IF(OR($C20="",F20=""),"",2*SQRT(AO20*AP20)*SIN(RADIANS(AS20/2))) | AU20: =IF(OR($C20="",F20=""),"",(M20+AH20)/2) | AV20: =IF(OR($C20="",F20=""),"",(AO20+AP20)/2) | AW20: =IF(OR($C20="",F20=""),"",AQ20+AR20) | AX20: =IF(OR($C20="",F20=""),"",IF(AO20*AP20=0,AW20,IF(ABS(AQ20-AR20)>180,IF(AW20<360,(AW20+360)/2,(AW20-360)/2),AW20/2))) | AY20: =IF(OR($C20="",F20=""),"",1-0.17*COS(RADIANS(AX20-30))+0.24*COS(RADIANS(2*AX20))+0.32*COS(RADIANS(3*AX20+6))-0.2*COS(RADIANS(4*AX20-63))) | AZ20: =IF(OR($C20="",F20=""),"",2*SQRT(AV20^7/(AV20^7+25^7))) | BA20: =IF(OR($C20="",F20=""),"",1+0.015*(AU20-50)^2/SQRT(20+(AU20-50)^2)) | BB20: =IF(OR($C20="",F20=""),"",1+0.045*AV20) | BC20: =IF(OR($C20="",F20=""),"",1+0.015*AV20*AY20) | BD20: =IF(OR($C20="",F20=""),"",-SIN(RADIANS(2*30*EXP(-(((AX20-275)/25)^2))))*AZ20)
