Workbook

Sheet Report
A1: WLab robustness report
A2: Pick up to six observing conditions (yellow). The first is the viewing booth: DeltaE00 is shown for it.
A3: Values are DeltaE(WLab) between each sample and the standard. They are similar in size to DeltaE00 values; no tolerances are built in, so let experience with your own products set the limits.
A5: Conditions
C6: CIE 1931 2deg D50 | D6: CIE 1931 2deg D65 | E6: CIE 1931 2deg A | F6: CIE 1931 2deg F2 | G6: CIE 1931 2deg F11 | H6: CIE 1964 10deg D50
L7: DeltaE00 working columns (no need to read them)
A8: Sample | B8: ΔE00 booth | C8: =IF(C$6="","","ΔE(WLab) "&C$6) | D8: =IF(D$6="","","ΔE(WLab) "&D$6) | E8: =IF(E$6="","","ΔE(WLab) "&E$6) | F8: =IF(F$6="","","ΔE(WLab) "&F$6) | G8: =IF(G$6="","","ΔE(WLab) "&G$6) | H8: =IF(H$6="","","ΔE(WLab) "&H$6) | L8: L1 | M8: a1 | N8: b1 | O8: L2 | P8: a2 | Q8: b2 | R8: Cm | S8: G | T8: ap1 | U8: ap2 | V8: Cp1 | W8: Cp2 | X8: hp1 | Y8: hp2 | Z8: dh | AA8: dHp | AB8: Lpm | AC8: Cpm | AD8: hs | AE8: hpm | AF8: T | AG8: RC | AH8: SL | AI8: SC | AJ8: SH | AK8: RT
A9: =IF(Spectra!C4="","",Spectra!C4) | B9: =IF(AND(Calc!$E$8<>"",Calc!$E$2<>""),SQRT(((O9-L9)/AH9)^2+((W9-V9)/AI9)^2+(AA9/AJ9)^2+AK9*((W9-V9)/AI9)*(AA9/AJ9)),"") | C9: =IF(OR(Calc!$E$8="",Calc!$E$2=""),"",SQRT((Calc!$T$8-Calc!$T$2)^2+(Calc!$U$8-Calc!$U$2)^2+(Calc!$V$8-Calc!$V$2)^2)) | D9: =IF(OR(Calc!$E$9="",Calc!$E$3=""),"",SQRT((Calc!$T$9-Calc!$T$3)^2+(Calc!$U$9-Calc!$U$3)^2+(Calc!$V$9-Calc!$V$3)^2)) | E9: =IF(OR(Calc!$E$10="",Calc!$E$4=""),"",SQRT((Calc!$T$10-Calc!$T$4)^2+(Calc!$U$10-Calc!$U$4)^2+(Calc!$V$10-Calc!$V$4)^2)) | F9: =IF(OR(Calc!$E$11="",Calc!$E$5=""),"",SQRT((Calc!$T$11-Calc!$T$5)^2+(Calc!$U$11-Calc!$U$5)^2+(Calc!$V$11-Calc!$V$5)^2)) | G9: =IF(OR(Calc!$E$12="",Calc!$E$6=""),"",SQRT((Calc!$T$12-Calc!$T$6)^2+(Calc!$U$12-Calc!$U$6)^2+(Calc!$V$12-Calc!$V$6)^2)) | H9: =IF(OR(Calc!$E$13="",Calc!$E$7=""),"",SQRT((Calc!$T$13-Calc!$T$7)^2+(Calc!$U$13-Calc!$U$7)^2+(Calc!$V$13-Calc!$V$7)^2)) | L9: =IF(AND(Calc!$E$8<>"",Calc!$E$2<>""),Calc!$Z$2,"") | M9: =IF(AND(Calc!$E$8<>"",Calc!$E$2<>""),Calc!$AA$2,"") | N9: =IF(AND(Calc!$E$8<>"",Calc!$E$2<>""),Calc!$AB$2,"") | O9: =IF(AND(Calc!$E$8<>"",Calc!$E$2<>""),Calc!$Z$8,"") | P9: =IF(AND(Calc!$E$8<>"",Calc!$E$2<>""),Calc!$AA$8,"") | Q9: =IF(AND(Calc!$E$8<>"",Calc!$E$2<>""),Calc!$AB$8,"") | R9: =IF(AND(Calc!$E$8<>"",Calc!$E$2<>""),(SQRT(M9^2+N9^2)+SQRT(P9^2+Q9^2))/2,"") | S9: =IF(AND(Calc!$E$8<>"",Calc!$E$2<>""),0.5*(1-SQRT(R9^7/(R9^7+25^7))),"") | T9: =IF(AND(Calc!$E$8<>"",Calc!$E$2<>""),(1+S9)*M9,"") | U9: =IF(AND(Calc!$E$8<>"",Calc!$E$2<>""),(1+S9)*P9,"") | V9: =IF(AND(Calc!$E$8<>"",Calc!$E$2<>""),SQRT(T9^2+N9^2),"") | W9: =IF(AND(Calc!$E$8<>"",Calc!$E$2<>""),SQRT(U9^2+Q9^2),"") | X9: =IF(AND(Calc!$E$8<>"",Calc!$E$2<>""),IF(V9=0,0,MOD(DEGREES(ATAN2(T9,N9)),360)),"") | Y9: =IF(AND(Calc!$E$8<>"",Calc!$E$2<>""),IF(W9=0,0,MOD(DEGREES(ATAN2(U9,Q9)),360)),"") | Z9: =IF(AND(Calc!$E$8<>"",Calc!$E$2<>""),IF(V9*W9=0,0,IF((Y9-X9)>180,(Y9-X9)-360,IF((Y9-X9)<-180,(Y9-X9)+360,(Y9-X9)))),"") | AA9: =IF(AND(Calc!$E$8<>"",Calc!$E$2<>""),2*SQRT(V9*W9)*SIN(RADIANS(Z9/2)),"") | AB9: =IF(AND(Calc!$E$8<>"",Calc!$E$2<>""),(L9+O9)/2,"") | AC9: =IF(AND(Calc!$E$8<>"",Calc!$E$2<>""),(V9+W9)/2,"") | AD9: =IF(AND(Calc!$E$8<>"",Calc!$E$2<>""),X9+Y9,"") | AE9: =IF(AND(Calc!$E$8<>"",Calc!$E$2<>""),IF(V9*W9=0,AD9,IF(ABS(X9-Y9)>180,IF(AD9<360,(AD9+360)/2,(AD9-360)/2),AD9/2)),"") | AF9: =IF(AND(Calc!$E$8<>"",Calc!$E$2<>""),1-0.17*COS(RADIANS(AE9-30))+0.24*COS(RADIANS(2*AE9))+0.32*COS(RADIANS(3*AE9+6))-0.2*COS(RADIANS(4*AE9-63)),"") | AG9: =IF(AND(Calc!$E$8<>"",Calc!$E$2<>""),2*SQRT(AC9^7/(AC9^7+25^7)),"") | AH9: =IF(AND(Calc!$E$8<>"",Calc!$E$2<>""),1+0.015*(AB9-50)^2/SQRT(20+(AB9-50)^2),"") | AI9: =IF(AND(Calc!$E$8<>"",Calc!$E$2<>""),1+0.045*AC9,"") | AJ9: =IF(AND(Calc!$E$8<>"",Calc!$E$2<>""),1+0.015*AC9*AF9,"") | AK9: =IF(AND(Calc!$E$8<>"",Calc!$E$2<>""),-SIN(RADIANS(2*30*EXP(-(((AE9-275)/25)^2))))*AG9,"")
A10: =IF(Spectra!D4="","",Spectra!D4) | B10: =IF(AND(Calc!$E$14<>"",Calc!$E$2<>""),SQRT(((O10-L10)/AH10)^2+((W10-V10)/AI10)^2+(AA10/AJ10)^2+AK10*((W10-V10)/AI10)*(AA10/AJ10)),"") | C10: =IF(OR(Calc!$E$14="",Calc!$E$2=""),"",SQRT((Calc!$T$14-Calc!$T$2)^2+(Calc!$U$14-Calc!$U$2)^2+(Calc!$V$14-Calc!$V$2)^2)) | D10: =IF(OR(Calc!$E$15="",Calc!$E$3=""),"",SQRT((Calc!$T$15-Calc!$T$3)^2+(Calc!$U$15-Calc!$U$3)^2+(Calc!$V$15-Calc!$V$3)^2)) | E10: =IF(OR(Calc!$E$16="",Calc!$E$4=""),"",SQRT((Calc!$T$16-Calc!$T$4)^2+(Calc!$U$16-Calc!$U$4)^2+(Calc!$V$16-Calc!$V$4)^2)) | F10: =IF(OR(Calc!$E$17="",Calc!$E$5=""),"",SQRT((Calc!$T$17-Calc!$T$5)^2+(Calc!$U$17-Calc!$U$5)^2+(Calc!$V$17-Calc!$V$5)^2)) | G10: =IF(OR(Calc!$E$18="",Calc!$E$6=""),"",SQRT((Calc!$T$18-Calc!$T$6)^2+(Calc!$U$18-Calc!$U$6)^2+(Calc!$V$18-Calc!$V$6)^2)) | H10: =IF(OR(Calc!$E$19="",Calc!$E$7=""),"",SQRT((Calc!$T$19-Calc!$T$7)^2+(Calc!$U$19-Calc!$U$7)^2+(Calc!$V$19-Calc!$V$7)^2)) | L10: =IF(AND(Calc!$E$14<>"",Calc!$E$2<>""),Calc!$Z$2,"") | M10: =IF(AND(Calc!$E$14<>"",Calc!$E$2<>""),Calc!$AA$2,"") | N10: =IF(AND(Calc!$E$14<>"",Calc!$E$2<>""),Calc!$AB$2,"") | O10: =IF(AND(Calc!$E$14<>"",Calc!$E$2<>""),Calc!$Z$14,"") | P10: =IF(AND(Calc!$E$14<>"",Calc!$E$2<>""),Calc!$AA$14,"") | Q10: =IF(AND(Calc!$E$14<>"",Calc!$E$2<>""),Calc!$AB$14,"") | R10: =IF(AND(Calc!$E$14<>"",Calc!$E$2<>""),(SQRT(M10^2+N10^2)+SQRT(P10^2+Q10^2))/2,"") | S10: =IF(AND(Calc!$E$14<>"",Calc!$E$2<>""),0.5*(1-SQRT(R10^7/(R10^7+25^7))),"") | T10: =IF(AND(Calc!$E$14<>"",Calc!$E$2<>""),(1+S10)*M10,"") | U10: =IF(AND(Calc!$E$14<>"",Calc!$E$2<>""),(1+S10)*P10,"") | V10: =IF(AND(Calc!$E$14<>"",Calc!$E$2<>""),SQRT(T10^2+N10^2),"") | W10: =IF(AND(Calc!$E$14<>"",Calc!$E$2<>""),SQRT(U10^2+Q10^2),"") | X10: =IF(AND(Calc!$E$14<>"",Calc!$E$2<>""),IF(V10=0,0,MOD(DEGREES(ATAN2(T10,N10)),360)),"") | Y10: =IF(AND(Calc!$E$14<>"",Calc!$E$2<>""),IF(W10=0,0,MOD(DEGREES(ATAN2(U10,Q10)),360)),"") | Z10: =IF(AND(Calc!$E$14<>"",Calc!$E$2<>""),IF(V10*W10=0,0,IF((Y10-X10)>180,(Y10-X10)-360,IF((Y10-X10)<-180,(Y10-X10)+360,(Y10-X10)))),"") | AA10: =IF(AND(Calc!$E$14<>"",Calc!$E$2<>""),2*SQRT(V10*W10)*SIN(RADIANS(Z10/2)),"") | AB10: =IF(AND(Calc!$E$14<>"",Calc!$E$2<>""),(L10+O10)/2,"") | AC10: =IF(AND(Calc!$E$14<>"",Calc!$E$2<>""),(V10+W10)/2,"") | AD10: =IF(AND(Calc!$E$14<>"",Calc!$E$2<>""),X10+Y10,"") | AE10: =IF(AND(Calc!$E$14<>"",Calc!$E$2<>""),IF(V10*W10=0,AD10,IF(ABS(X10-Y10)>180,IF(AD10<360,(AD10+360)/2,(AD10-360)/2),AD10/2)),"") | AF10: =IF(AND(Calc!$E$14<>"",Calc!$E$2<>""),1-0.17*COS(RADIANS(AE10-30))+0.24*COS(RADIANS(2*AE10))+0.32*COS(RADIANS(3*AE10+6))-0.2*COS(RADIANS(4*AE10-63)),"") | AG10: =IF(AND(Calc!$E$14<>"",Calc!$E$2<>""),2*SQRT(AC10^7/(AC10^7+25^7)),"") | AH10: =IF(AND(Calc!$E$14<>"",Calc!$E$2<>""),1+0.015*(AB10-50)^2/SQRT(20+(AB10-50)^2),"") | AI10: =IF(AND(Calc!$E$14<>"",Calc!$E$2<>""),1+0.045*AC10,"") | AJ10: =IF(AND(Calc!$E$14<>"",Calc!$E$2<>""),1+0.015*AC10*AF10,"") | AK10: =IF(AND(Calc!$E$14<>"",Calc!$E$2<>""),-SIN(RADIANS(2*30*EXP(-(((AE10-275)/25)^2))))*AG10,"")
A11: =IF(Spectra!E4="","",Spectra!E4) | B11: =IF(AND(Calc!$E$20<>"",Calc!$E$2<>""),SQRT(((O11-L11)/AH11)^2+((W11-V11)/AI11)^2+(AA11/AJ11)^2+AK11*((W11-V11)/AI11)*(AA11/AJ11)),"") | C11: =IF(OR(Calc!$E$20="",Calc!$E$2=""),"",SQRT((Calc!$T$20-Calc!$T$2)^2+(Calc!$U$20-Calc!$U$2)^2+(Calc!$V$20-Calc!$V$2)^2)) | D11: =IF(OR(Calc!$E$21="",Calc!$E$3=""),"",SQRT((Calc!$T$21-Calc!$T$3)^2+(Calc!$U$21-Calc!$U$3)^2+(Calc!$V$21-Calc!$V$3)^2)) | E11: =IF(OR(Calc!$E$22="",Calc!$E$4=""),"",SQRT((Calc!$T$22-Calc!$T$4)^2+(Calc!$U$22-Calc!$U$4)^2+(Calc!$V$22-Calc!$V$4)^2)) | F11: =IF(OR(Calc!$E$23="",Calc!$E$5=""),"",SQRT((Calc!$T$23-Calc!$T$5)^2+(Calc!$U$23-Calc!$U$5)^2+(Calc!$V$23-Calc!$V$5)^2)) | G11: =IF(OR(Calc!$E$24="",Calc!$E$6=""),"",SQRT((Calc!$T$24-Calc!$T$6)^2+(Calc!$U$24-Calc!$U$6)^2+(Calc!$V$24-Calc!$V$6)^2)) | H11: =IF(OR(Calc!$E$25="",Calc!$E$7=""),"",SQRT((Calc!$T$25-Calc!$T$7)^2+(Calc!$U$25-Calc!$U$7)^2+(Calc!$V$25-Calc!$V$7)^2)) | L11: =IF(AND(Calc!$E$20<>"",Calc!$E$2<>""),Calc!$Z$2,"") | M11: =IF(AND(Calc!$E$20<>"",Calc!$E$2<>""),Calc!$AA$2,"") | N11: =IF(AND(Calc!$E$20<>"",Calc!$E$2<>""),Calc!$AB$2,"") | O11: =IF(AND(Calc!$E$20<>"",Calc!$E$2<>""),Calc!$Z$20,"") | P11: =IF(AND(Calc!$E$20<>"",Calc!$E$2<>""),Calc!$AA$20,"") | Q11: =IF(AND(Calc!$E$20<>"",Calc!$E$2<>""),Calc!$AB$20,"") | R11: =IF(AND(Calc!$E$20<>"",Calc!$E$2<>""),(SQRT(M11^2+N11^2)+SQRT(P11^2+Q11^2))/2,"") | S11: =IF(AND(Calc!$E$20<>"",Calc!$E$2<>""),0.5*(1-SQRT(R11^7/(R11^7+25^7))),"") | T11: =IF(AND(Calc!$E$20<>"",Calc!$E$2<>""),(1+S11)*M11,"") | U11: =IF(AND(Calc!$E$20<>"",Calc!$E$2<>""),(1+S11)*P11,"") | V11: =IF(AND(Calc!$E$20<>"",Calc!$E$2<>""),SQRT(T11^2+N11^2),"") | W11: =IF(AND(Calc!$E$20<>"",Calc!$E$2<>""),SQRT(U11^2+Q11^2),"") | X11: =IF(AND(Calc!$E$20<>"",Calc!$E$2<>""),IF(V11=0,0,MOD(DEGREES(ATAN2(T11,N11)),360)),"") | Y11: =IF(AND(Calc!$E$20<>"",Calc!$E$2<>""),IF(W11=0,0,MOD(DEGREES(ATAN2(U11,Q11)),360)),"") | Z11: =IF(AND(Calc!$E$20<>"",Calc!$E$2<>""),IF(V11*W11=0,0,IF((Y11-X11)>180,(Y11-X11)-360,IF((Y11-X11)<-180,(Y11-X11)+360,(Y11-X11)))),"") | AA11: =IF(AND(Calc!$E$20<>"",Calc!$E$2<>""),2*SQRT(V11*W11)*SIN(RADIANS(Z11/2)),"") | AB11: =IF(AND(Calc!$E$20<>"",Calc!$E$2<>""),(L11+O11)/2,"") | AC11: =IF(AND(Calc!$E$20<>"",Calc!$E$2<>""),(V11+W11)/2,"") | AD11: =IF(AND(Calc!$E$20<>"",Calc!$E$2<>""),X11+Y11,"") | AE11: =IF(AND(Calc!$E$20<>"",Calc!$E$2<>""),IF(V11*W11=0,AD11,IF(ABS(X11-Y11)>180,IF(AD11<360,(AD11+360)/2,(AD11-360)/2),AD11/2)),"") | AF11: =IF(AND(Calc!$E$20<>"",Calc!$E$2<>""),1-0.17*COS(RADIANS(AE11-30))+0.24*COS(RADIANS(2*AE11))+0.32*COS(RADIANS(3*AE11+6))-0.2*COS(RADIANS(4*AE11-63)),"") | AG11: =IF(AND(Calc!$E$20<>"",Calc!$E$2<>""),2*SQRT(AC11^7/(AC11^7+25^7)),"") | AH11: =IF(AND(Calc!$E$20<>"",Calc!$E$2<>""),1+0.015*(AB11-50)^2/SQRT(20+(AB11-50)^2),"") | AI11: =IF(AND(Calc!$E$20<>"",Calc!$E$2<>""),1+0.045*AC11,"") | AJ11: =IF(AND(Calc!$E$20<>"",Calc!$E$2<>""),1+0.015*AC11*AF11,"") | AK11: =IF(AND(Calc!$E$20<>"",Calc!$E$2<>""),-SIN(RADIANS(2*30*EXP(-(((AE11-275)/25)^2))))*AG11,"")
A12: =IF(Spectra!F4="","",Spectra!F4) | B12: =IF(AND(Calc!$E$26<>"",Calc!$E$2<>""),SQRT(((O12-L12)/AH12)^2+((W12-V12)/AI12)^2+(AA12/AJ12)^2+AK12*((W12-V12)/AI12)*(AA12/AJ12)),"") | C12: =IF(OR(Calc!$E$26="",Calc!$E$2=""),"",SQRT((Calc!$T$26-Calc!$T$2)^2+(Calc!$U$26-Calc!$U$2)^2+(Calc!$V$26-Calc!$V$2)^2)) | D12: =IF(OR(Calc!$E$27="",Calc!$E$3=""),"",SQRT((Calc!$T$27-Calc!$T$3)^2+(Calc!$U$27-Calc!$U$3)^2+(Calc!$V$27-Calc!$V$3)^2)) | E12: =IF(OR(Calc!$E$28="",Calc!$E$4=""),"",SQRT((Calc!$T$28-Calc!$T$4)^2+(Calc!$U$28-Calc!$U$4)^2+(Calc!$V$28-Calc!$V$4)^2)) | F12: =IF(OR(Calc!$E$29="",Calc!$E$5=""),"",SQRT((Calc!$T$29-Calc!$T$5)^2+(Calc!$U$29-Calc!$U$5)^2+(Calc!$V$29-Calc!$V$5)^2)) | G12: =IF(OR(Calc!$E$30="",Calc!$E$6=""),"",SQRT((Calc!$T$30-Calc!$T$6)^2+(Calc!$U$30-Calc!$U$6)^2+(Calc!$V$30-Calc!$V$6)^2)) | H12: =IF(OR(Calc!$E$31="",Calc!$E$7=""),"",SQRT((Calc!$T$31-Calc!$T$7)^2+(Calc!$U$31-Calc!$U$7)^2+(Calc!$V$31-Calc!$V$7)^2)) | L12: =IF(AND(Calc!$E$26<>"",Calc!$E$2<>""),Calc!$Z$2,"") | M12: =IF(AND(Calc!$E$26<>"",Calc!$E$2<>""),Calc!$AA$2,"") | N12: =IF(AND(Calc!$E$26<>"",Calc!$E$2<>""),Calc!$AB$2,"") | O12: =IF(AND(Calc!$E$26<>"",Calc!$E$2<>""),Calc!$Z$26,"") | P12: =IF(AND(Calc!$E$26<>"",Calc!$E$2<>""),Calc!$AA$26,"") | Q12: =IF(AND(Calc!$E$26<>"",Calc!$E$2<>""),Calc!$AB$26,"") | R12: =IF(AND(Calc!$E$26<>"",Calc!$E$2<>""),(SQRT(M12^2+N12^2)+SQRT(P12^2+Q12^2))/2,"") | S12: =IF(AND(Calc!$E$26<>"",Calc!$E$2<>""),0.5*(1-SQRT(R12^7/(R12^7+25^7))),"") | T12: =IF(AND(Calc!$E$26<>"",Calc!$E$2<>""),(1+S12)*M12,"") | U12: =IF(AND(Calc!$E$26<>"",Calc!$E$2<>""),(1+S12)*P12,"") | V12: =IF(AND(Calc!$E$26<>"",Calc!$E$2<>""),SQRT(T12^2+N12^2),"") | W12: =IF(AND(Calc!$E$26<>"",Calc!$E$2<>""),SQRT(U12^2+Q12^2),"") | X12: =IF(AND(Calc!$E$26<>"",Calc!$E$2<>""),IF(V12=0,0,MOD(DEGREES(ATAN2(T12,N12)),360)),"") | Y12: =IF(AND(Calc!$E$26<>"",Calc!$E$2<>""),IF(W12=0,0,MOD(DEGREES(ATAN2(U12,Q12)),360)),"") | Z12: =IF(AND(Calc!$E$26<>"",Calc!$E$2<>""),IF(V12*W12=0,0,IF((Y12-X12)>180,(Y12-X12)-360,IF((Y12-X12)<-180,(Y12-X12)+360,(Y12-X12)))),"") | AA12: =IF(AND(Calc!$E$26<>"",Calc!$E$2<>""),2*SQRT(V12*W12)*SIN(RADIANS(Z12/2)),"") | AB12: =IF(AND(Calc!$E$26<>"",Calc!$E$2<>""),(L12+O12)/2,"") | AC12: =IF(AND(Calc!$E$26<>"",Calc!$E$2<>""),(V12+W12)/2,"") | AD12: =IF(AND(Calc!$E$26<>"",Calc!$E$2<>""),X12+Y12,"") | AE12: =IF(AND(Calc!$E$26<>"",Calc!$E$2<>""),IF(V12*W12=0,AD12,IF(ABS(X12-Y12)>180,IF(AD12<360,(AD12+360)/2,(AD12-360)/2),AD12/2)),"") | AF12: =IF(AND(Calc!$E$26<>"",Calc!$E$2<>""),1-0.17*COS(RADIANS(AE12-30))+0.24*COS(RADIANS(2*AE12))+0.32*COS(RADIANS(3*AE12+6))-0.2*COS(RADIANS(4*AE12-63)),"") | AG12: =IF(AND(Calc!$E$26<>"",Calc!$E$2<>""),2*SQRT(AC12^7/(AC12^7+25^7)),"") | AH12: =IF(AND(Calc!$E$26<>"",Calc!$E$2<>""),1+0.015*(AB12-50)^2/SQRT(20+(AB12-50)^2),"") | AI12: =IF(AND(Calc!$E$26<>"",Calc!$E$2<>""),1+0.045*AC12,"") | AJ12: =IF(AND(Calc!$E$26<>"",Calc!$E$2<>""),1+0.015*AC12*AF12,"") | AK12: =IF(AND(Calc!$E$26<>"",Calc!$E$2<>""),-SIN(RADIANS(2*30*EXP(-(((AE12-275)/25)^2))))*AG12,"")
A13: =IF(Spectra!G4="","",Spectra!G4) | B13: =IF(AND(Calc!$E$32<>"",Calc!$E$2<>""),SQRT(((O13-L13)/AH13)^2+((W13-V13)/AI13)^2+(AA13/AJ13)^2+AK13*((W13-V13)/AI13)*(AA13/AJ13)),"") | C13: =IF(OR(Calc!$E$32="",Calc!$E$2=""),"",SQRT((Calc!$T$32-Calc!$T$2)^2+(Calc!$U$32-Calc!$U$2)^2+(Calc!$V$32-Calc!$V$2)^2)) | D13: =IF(OR(Calc!$E$33="",Calc!$E$3=""),"",SQRT((Calc!$T$33-Calc!$T$3)^2+(Calc!$U$33-Calc!$U$3)^2+(Calc!$V$33-Calc!$V$3)^2)) | E13: =IF(OR(Calc!$E$34="",Calc!$E$4=""),"",SQRT((Calc!$T$34-Calc!$T$4)^2+(Calc!$U$34-Calc!$U$4)^2+(Calc!$V$34-Calc!$V$4)^2)) | F13: =IF(OR(Calc!$E$35="",Calc!$E$5=""),"",SQRT((Calc!$T$35-Calc!$T$5)^2+(Calc!$U$35-Calc!$U$5)^2+(Calc!$V$35-Calc!$V$5)^2)) | G13: =IF(OR(Calc!$E$36="",Calc!$E$6=""),"",SQRT((Calc!$T$36-Calc!$T$6)^2+(Calc!$U$36-Calc!$U$6)^2+(Calc!$V$36-Calc!$V$6)^2)) | H13: =IF(OR(Calc!$E$37="",Calc!$E$7=""),"",SQRT((Calc!$T$37-Calc!$T$7)^2+(Calc!$U$37-Calc!$U$7)^2+(Calc!$V$37-Calc!$V$7)^2)) | L13: =IF(AND(Calc!$E$32<>"",Calc!$E$2<>""),Calc!$Z$2,"") | M13: =IF(AND(Calc!$E$32<>"",Calc!$E$2<>""),Calc!$AA$2,"") | N13: =IF(AND(Calc!$E$32<>"",Calc!$E$2<>""),Calc!$AB$2,"") | O13: =IF(AND(Calc!$E$32<>"",Calc!$E$2<>""),Calc!$Z$32,"") | P13: =IF(AND(Calc!$E$32<>"",Calc!$E$2<>""),Calc!$AA$32,"") | Q13: =IF(AND(Calc!$E$32<>"",Calc!$E$2<>""),Calc!$AB$32,"") | R13: =IF(AND(Calc!$E$32<>"",Calc!$E$2<>""),(SQRT(M13^2+N13^2)+SQRT(P13^2+Q13^2))/2,"") | S13: =IF(AND(Calc!$E$32<>"",Calc!$E$2<>""),0.5*(1-SQRT(R13^7/(R13^7+25^7))),"") | T13: =IF(AND(Calc!$E$32<>"",Calc!$E$2<>""),(1+S13)*M13,"") | U13: =IF(AND(Calc!$E$32<>"",Calc!$E$2<>""),(1+S13)*P13,"") | V13: =IF(AND(Calc!$E$32<>"",Calc!$E$2<>""),SQRT(T13^2+N13^2),"") | W13: =IF(AND(Calc!$E$32<>"",Calc!$E$2<>""),SQRT(U13^2+Q13^2),"") | X13: =IF(AND(Calc!$E$32<>"",Calc!$E$2<>""),IF(V13=0,0,MOD(DEGREES(ATAN2(T13,N13)),360)),"") | Y13: =IF(AND(Calc!$E$32<>"",Calc!$E$2<>""),IF(W13=0,0,MOD(DEGREES(ATAN2(U13,Q13)),360)),"") | Z13: =IF(AND(Calc!$E$32<>"",Calc!$E$2<>""),IF(V13*W13=0,0,IF((Y13-X13)>180,(Y13-X13)-360,IF((Y13-X13)<-180,(Y13-X13)+360,(Y13-X13)))),"") | AA13: =IF(AND(Calc!$E$32<>"",Calc!$E$2<>""),2*SQRT(V13*W13)*SIN(RADIANS(Z13/2)),"") | AB13: =IF(AND(Calc!$E$32<>"",Calc!$E$2<>""),(L13+O13)/2,"") | AC13: =IF(AND(Calc!$E$32<>"",Calc!$E$2<>""),(V13+W13)/2,"") | AD13: =IF(AND(Calc!$E$32<>"",Calc!$E$2<>""),X13+Y13,"") | AE13: =IF(AND(Calc!$E$32<>"",Calc!$E$2<>""),IF(V13*W13=0,AD13,IF(ABS(X13-Y13)>180,IF(AD13<360,(AD13+360)/2,(AD13-360)/2),AD13/2)),"") | AF13: =IF(AND(Calc!$E$32<>"",Calc!$E$2<>""),1-0.17*COS(RADIANS(AE13-30))+0.24*COS(RADIANS(2*AE13))+0.32*COS(RADIANS(3*AE13+6))-0.2*COS(RADIANS(4*AE13-63)),"") | AG13: =IF(AND(Calc!$E$32<>"",Calc!$E$2<>""),2*SQRT(AC13^7/(AC13^7+25^7)),"") | AH13: =IF(AND(Calc!$E$32<>"",Calc!$E$2<>""),1+0.015*(AB13-50)^2/SQRT(20+(AB13-50)^2),"") | AI13: =IF(AND(Calc!$E$32<>"",Calc!$E$2<>""),1+0.045*AC13,"") | AJ13: =IF(AND(Calc!$E$32<>"",Calc!$E$2<>""),1+0.015*AC13*AF13,"") | AK13: =IF(AND(Calc!$E$32<>"",Calc!$E$2<>""),-SIN(RADIANS(2*30*EXP(-(((AE13-275)/25)^2))))*AG13,"")
A14: =IF(Spectra!H4="","",Spectra!H4) | B14: =IF(AND(Calc!$E$38<>"",Calc!$E$2<>""),SQRT(((O14-L14)/AH14)^2+((W14-V14)/AI14)^2+(AA14/AJ14)^2+AK14*((W14-V14)/AI14)*(AA14/AJ14)),"") | C14: =IF(OR(Calc!$E$38="",Calc!$E$2=""),"",SQRT((Calc!$T$38-Calc!$T$2)^2+(Calc!$U$38-Calc!$U$2)^2+(Calc!$V$38-Calc!$V$2)^2)) | D14: =IF(OR(Calc!$E$39="",Calc!$E$3=""),"",SQRT((Calc!$T$39-Calc!$T$3)^2+(Calc!$U$39-Calc!$U$3)^2+(Calc!$V$39-Calc!$V$3)^2)) | E14: =IF(OR(Calc!$E$40="",Calc!$E$4=""),"",SQRT((Calc!$T$40-Calc!$T$4)^2+(Calc!$U$40-Calc!$U$4)^2+(Calc!$V$40-Calc!$V$4)^2)) | F14: =IF(OR(Calc!$E$41="",Calc!$E$5=""),"",SQRT((Calc!$T$41-Calc!$T$5)^2+(Calc!$U$41-Calc!$U$5)^2+(Calc!$V$41-Calc!$V$5)^2)) | G14: =IF(OR(Calc!$E$42="",Calc!$E$6=""),"",SQRT((Calc!$T$42-Calc!$T$6)^2+(Calc!$U$42-Calc!$U$6)^2+(Calc!$V$42-Calc!$V$6)^2)) | H14: =IF(OR(Calc!$E$43="",Calc!$E$7=""),"",SQRT((Calc!$T$43-Calc!$T$7)^2+(Calc!$U$43-Calc!$U$7)^2+(Calc!$V$43-Calc!$V$7)^2)) | L14: =IF(AND(Calc!$E$38<>"",Calc!$E$2<>""),Calc!$Z$2,"") | M14: =IF(AND(Calc!$E$38<>"",Calc!$E$2<>""),Calc!$AA$2,"") | N14: =IF(AND(Calc!$E$38<>"",Calc!$E$2<>""),Calc!$AB$2,"") | O14: =IF(AND(Calc!$E$38<>"",Calc!$E$2<>""),Calc!$Z$38,"") | P14: =IF(AND(Calc!$E$38<>"",Calc!$E$2<>""),Calc!$AA$38,"") | Q14: =IF(AND(Calc!$E$38<>"",Calc!$E$2<>""),Calc!$AB$38,"") | R14: =IF(AND(Calc!$E$38<>"",Calc!$E$2<>""),(SQRT(M14^2+N14^2)+SQRT(P14^2+Q14^2))/2,"") | S14: =IF(AND(Calc!$E$38<>"",Calc!$E$2<>""),0.5*(1-SQRT(R14^7/(R14^7+25^7))),"") | T14: =IF(AND(Calc!$E$38<>"",Calc!$E$2<>""),(1+S14)*M14,"") | U14: =IF(AND(Calc!$E$38<>"",Calc!$E$2<>""),(1+S14)*P14,"") | V14: =IF(AND(Calc!$E$38<>"",Calc!$E$2<>""),SQRT(T14^2+N14^2),"") | W14: =IF(AND(Calc!$E$38<>"",Calc!$E$2<>""),SQRT(U14^2+Q14^2),"") | X14: =IF(AND(Calc!$E$38<>"",Calc!$E$2<>""),IF(V14=0,0,MOD(DEGREES(ATAN2(T14,N14)),360)),"") | Y14: =IF(AND(Calc!$E$38<>"",Calc!$E$2<>""),IF(W14=0,0,MOD(DEGREES(ATAN2(U14,Q14)),360)),"") | Z14: =IF(AND(Calc!$E$38<>"",Calc!$E$2<>""),IF(V14*W14=0,0,IF((Y14-X14)>180,(Y14-X14)-360,IF((Y14-X14)<-180,(Y14-X14)+360,(Y14-X14)))),"") | AA14: =IF(AND(Calc!$E$38<>"",Calc!$E$2<>""),2*SQRT(V14*W14)*SIN(RADIANS(Z14/2)),"") | AB14: =IF(AND(Calc!$E$38<>"",Calc!$E$2<>""),(L14+O14)/2,"") | AC14: =IF(AND(Calc!$E$38<>"",Calc!$E$2<>""),(V14+W14)/2,"") | AD14: =IF(AND(Calc!$E$38<>"",Calc!$E$2<>""),X14+Y14,"") | AE14: =IF(AND(Calc!$E$38<>"",Calc!$E$2<>""),IF(V14*W14=0,AD14,IF(ABS(X14-Y14)>180,IF(AD14<360,(AD14+360)/2,(AD14-360)/2),AD14/2)),"") | AF14: =IF(AND(Calc!$E$38<>"",Calc!$E$2<>""),1-0.17*COS(RADIANS(AE14-30))+0.24*COS(RADIANS(2*AE14))+0.32*COS(RADIANS(3*AE14+6))-0.2*COS(RADIANS(4*AE14-63)),"") | AG14: =IF(AND(Calc!$E$38<>"",Calc!$E$2<>""),2*SQRT(AC14^7/(AC14^7+25^7)),"") | AH14: =IF(AND(Calc!$E$38<>"",Calc!$E$2<>""),1+0.015*(AB14-50)^2/SQRT(20+(AB14-50)^2),"") | AI14: =IF(AND(Calc!$E$38<>"",Calc!$E$2<>""),1+0.045*AC14,"") | AJ14: =IF(AND(Calc!$E$38<>"",Calc!$E$2<>""),1+0.015*AC14*AF14,"") | AK14: =IF(AND(Calc!$E$38<>"",Calc!$E$2<>""),-SIN(RADIANS(2*30*EXP(-(((AE14-275)/25)^2))))*AG14,"")
A15: =IF(Spectra!I4="","",Spectra!I4) | B15: =IF(AND(Calc!$E$44<>"",Calc!$E$2<>""),SQRT(((O15-L15)/AH15)^2+((W15-V15)/AI15)^2+(AA15/AJ15)^2+AK15*((W15-V15)/AI15)*(AA15/AJ15)),"") | C15: =IF(OR(Calc!$E$44="",Calc!$E$2=""),"",SQRT((Calc!$T$44-Calc!$T$2)^2+(Calc!$U$44-Calc!$U$2)^2+(Calc!$V$44-Calc!$V$2)^2)) | D15: =IF(OR(Calc!$E$45="",Calc!$E$3=""),"",SQRT((Calc!$T$45-Calc!$T$3)^2+(Calc!$U$45-Calc!$U$3)^2+(Calc!$V$45-Calc!$V$3)^2)) | E15: =IF(OR(Calc!$E$46="",Calc!$E$4=""),"",SQRT((Calc!$T$46-Calc!$T$4)^2+(Calc!$U$46-Calc!$U$4)^2+(Calc!$V$46-Calc!$V$4)^2)) | F15: =IF(OR(Calc!$E$47="",Calc!$E$5=""),"",SQRT((Calc!$T$47-Calc!$T$5)^2+(Calc!$U$47-Calc!$U$5)^2+(Calc!$V$47-Calc!$V$5)^2)) | G15: =IF(OR(Calc!$E$48="",Calc!$E$6=""),"",SQRT((Calc!$T$48-Calc!$T$6)^2+(Calc!$U$48-Calc!$U$6)^2+(Calc!$V$48-Calc!$V$6)^2)) | H15: =IF(OR(Calc!$E$49="",Calc!$E$7=""),"",SQRT((Calc!$T$49-Calc!$T$7)^2+(Calc!$U$49-Calc!$U$7)^2+(Calc!$V$49-Calc!$V$7)^2)) | L15: =IF(AND(Calc!$E$44<>"",Calc!$E$2<>""),Calc!$Z$2,"") | M15: =IF(AND(Calc!$E$44<>"",Calc!$E$2<>""),Calc!$AA$2,"") | N15: =IF(AND(Calc!$E$44<>"",Calc!$E$2<>""),Calc!$AB$2,"") | O15: =IF(AND(Calc!$E$44<>"",Calc!$E$2<>""),Calc!$Z$44,"") | P15: =IF(AND(Calc!$E$44<>"",Calc!$E$2<>""),Calc!$AA$44,"") | Q15: =IF(AND(Calc!$E$44<>"",Calc!$E$2<>""),Calc!$AB$44,"") | R15: =IF(AND(Calc!$E$44<>"",Calc!$E$2<>""),(SQRT(M15^2+N15^2)+SQRT(P15^2+Q15^2))/2,"") | S15: =IF(AND(Calc!$E$44<>"",Calc!$E$2<>""),0.5*(1-SQRT(R15^7/(R15^7+25^7))),"") | T15: =IF(AND(Calc!$E$44<>"",Calc!$E$2<>""),(1+S15)*M15,"") | U15: =IF(AND(Calc!$E$44<>"",Calc!$E$2<>""),(1+S15)*P15,"") | V15: =IF(AND(Calc!$E$44<>"",Calc!$E$2<>""),SQRT(T15^2+N15^2),"") | W15: =IF(AND(Calc!$E$44<>"",Calc!$E$2<>""),SQRT(U15^2+Q15^2),"") | X15: =IF(AND(Calc!$E$44<>"",Calc!$E$2<>""),IF(V15=0,0,MOD(DEGREES(ATAN2(T15,N15)),360)),"") | Y15: =IF(AND(Calc!$E$44<>"",Calc!$E$2<>""),IF(W15=0,0,MOD(DEGREES(ATAN2(U15,Q15)),360)),"") | Z15: =IF(AND(Calc!$E$44<>"",Calc!$E$2<>""),IF(V15*W15=0,0,IF((Y15-X15)>180,(Y15-X15)-360,IF((Y15-X15)<-180,(Y15-X15)+360,(Y15-X15)))),"") | AA15: =IF(AND(Calc!$E$44<>"",Calc!$E$2<>""),2*SQRT(V15*W15)*SIN(RADIANS(Z15/2)),"") | AB15: =IF(AND(Calc!$E$44<>"",Calc!$E$2<>""),(L15+O15)/2,"") | AC15: =IF(AND(Calc!$E$44<>"",Calc!$E$2<>""),(V15+W15)/2,"") | AD15: =IF(AND(Calc!$E$44<>"",Calc!$E$2<>""),X15+Y15,"") | AE15: =IF(AND(Calc!$E$44<>"",Calc!$E$2<>""),IF(V15*W15=0,AD15,IF(ABS(X15-Y15)>180,IF(AD15<360,(AD15+360)/2,(AD15-360)/2),AD15/2)),"") | AF15: =IF(AND(Calc!$E$44<>"",Calc!$E$2<>""),1-0.17*COS(RADIANS(AE15-30))+0.24*COS(RADIANS(2*AE15))+0.32*COS(RADIANS(3*AE15+6))-0.2*COS(RADIANS(4*AE15-63)),"") | AG15: =IF(AND(Calc!$E$44<>"",Calc!$E$2<>""),2*SQRT(AC15^7/(AC15^7+25^7)),"") | AH15: =IF(AND(Calc!$E$44<>"",Calc!$E$2<>""),1+0.015*(AB15-50)^2/SQRT(20+(AB15-50)^2),"") | AI15: =IF(AND(Calc!$E$44<>"",Calc!$E$2<>""),1+0.045*AC15,"") | AJ15: =IF(AND(Calc!$E$44<>"",Calc!$E$2<>""),1+0.015*AC15*AF15,"") | AK15: =IF(AND(Calc!$E$44<>"",Calc!$E$2<>""),-SIN(RADIANS(2*30*EXP(-(((AE15-275)/25)^2))))*AG15,"")
A16: =IF(Spectra!J4="","",Spectra!J4) | B16: =IF(AND(Calc!$E$50<>"",Calc!$E$2<>""),SQRT(((O16-L16)/AH16)^2+((W16-V16)/AI16)^2+(AA16/AJ16)^2+AK16*((W16-V16)/AI16)*(AA16/AJ16)),"") | C16: =IF(OR(Calc!$E$50="",Calc!$E$2=""),"",SQRT((Calc!$T$50-Calc!$T$2)^2+(Calc!$U$50-Calc!$U$2)^2+(Calc!$V$50-Calc!$V$2)^2)) | D16: =IF(OR(Calc!$E$51="",Calc!$E$3=""),"",SQRT((Calc!$T$51-Calc!$T$3)^2+(Calc!$U$51-Calc!$U$3)^2+(Calc!$V$51-Calc!$V$3)^2)) | E16: =IF(OR(Calc!$E$52="",Calc!$E$4=""),"",SQRT((Calc!$T$52-Calc!$T$4)^2+(Calc!$U$52-Calc!$U$4)^2+(Calc!$V$52-Calc!$V$4)^2)) | F16: =IF(OR(Calc!$E$53="",Calc!$E$5=""),"",SQRT((Calc!$T$53-Calc!$T$5)^2+(Calc!$U$53-Calc!$U$5)^2+(Calc!$V$53-Calc!$V$5)^2)) | G16: =IF(OR(Calc!$E$54="",Calc!$E$6=""),"",SQRT((Calc!$T$54-Calc!$T$6)^2+(Calc!$U$54-Calc!$U$6)^2+(Calc!$V$54-Calc!$V$6)^2)) | H16: =IF(OR(Calc!$E$55="",Calc!$E$7=""),"",SQRT((Calc!$T$55-Calc!$T$7)^2+(Calc!$U$55-Calc!$U$7)^2+(Calc!$V$55-Calc!$V$7)^2)) | L16: =IF(AND(Calc!$E$50<>"",Calc!$E$2<>""),Calc!$Z$2,"") | M16: =IF(AND(Calc!$E$50<>"",Calc!$E$2<>""),Calc!$AA$2,"") | N16: =IF(AND(Calc!$E$50<>"",Calc!$E$2<>""),Calc!$AB$2,"") | O16: =IF(AND(Calc!$E$50<>"",Calc!$E$2<>""),Calc!$Z$50,"") | P16: =IF(AND(Calc!$E$50<>"",Calc!$E$2<>""),Calc!$AA$50,"") | Q16: =IF(AND(Calc!$E$50<>"",Calc!$E$2<>""),Calc!$AB$50,"") | R16: =IF(AND(Calc!$E$50<>"",Calc!$E$2<>""),(SQRT(M16^2+N16^2)+SQRT(P16^2+Q16^2))/2,"") | S16: =IF(AND(Calc!$E$50<>"",Calc!$E$2<>""),0.5*(1-SQRT(R16^7/(R16^7+25^7))),"") | T16: =IF(AND(Calc!$E$50<>"",Calc!$E$2<>""),(1+S16)*M16,"") | U16: =IF(AND(Calc!$E$50<>"",Calc!$E$2<>""),(1+S16)*P16,"") | V16: =IF(AND(Calc!$E$50<>"",Calc!$E$2<>""),SQRT(T16^2+N16^2),"") | W16: =IF(AND(Calc!$E$50<>"",Calc!$E$2<>""),SQRT(U16^2+Q16^2),"") | X16: =IF(AND(Calc!$E$50<>"",Calc!$E$2<>""),IF(V16=0,0,MOD(DEGREES(ATAN2(T16,N16)),360)),"") | Y16: =IF(AND(Calc!$E$50<>"",Calc!$E$2<>""),IF(W16=0,0,MOD(DEGREES(ATAN2(U16,Q16)),360)),"") | Z16: =IF(AND(Calc!$E$50<>"",Calc!$E$2<>""),IF(V16*W16=0,0,IF((Y16-X16)>180,(Y16-X16)-360,IF((Y16-X16)<-180,(Y16-X16)+360,(Y16-X16)))),"") | AA16: =IF(AND(Calc!$E$50<>"",Calc!$E$2<>""),2*SQRT(V16*W16)*SIN(RADIANS(Z16/2)),"") | AB16: =IF(AND(Calc!$E$50<>"",Calc!$E$2<>""),(L16+O16)/2,"") | AC16: =IF(AND(Calc!$E$50<>"",Calc!$E$2<>""),(V16+W16)/2,"") | AD16: =IF(AND(Calc!$E$50<>"",Calc!$E$2<>""),X16+Y16,"") | AE16: =IF(AND(Calc!$E$50<>"",Calc!$E$2<>""),IF(V16*W16=0,AD16,IF(ABS(X16-Y16)>180,IF(AD16<360,(AD16+360)/2,(AD16-360)/2),AD16/2)),"") | AF16: =IF(AND(Calc!$E$50<>"",Calc!$E$2<>""),1-0.17*COS(RADIANS(AE16-30))+0.24*COS(RADIANS(2*AE16))+0.32*COS(RADIANS(3*AE16+6))-0.2*COS(RADIANS(4*AE16-63)),"") | AG16: =IF(AND(Calc!$E$50<>"",Calc!$E$2<>""),2*SQRT(AC16^7/(AC16^7+25^7)),"") | AH16: =IF(AND(Calc!$E$50<>"",Calc!$E$2<>""),1+0.015*(AB16-50)^2/SQRT(20+(AB16-50)^2),"") | AI16: =IF(AND(Calc!$E$50<>"",Calc!$E$2<>""),1+0.045*AC16,"") | AJ16: =IF(AND(Calc!$E$50<>"",Calc!$E$2<>""),1+0.015*AC16*AF16,"") | AK16: =IF(AND(Calc!$E$50<>"",Calc!$E$2<>""),-SIN(RADIANS(2*30*EXP(-(((AE16-275)/25)^2))))*AG16,"")
A17: =IF(Spectra!K4="","",Spectra!K4) | B17: =IF(AND(Calc!$E$56<>"",Calc!$E$2<>""),SQRT(((O17-L17)/AH17)^2+((W17-V17)/AI17)^2+(AA17/AJ17)^2+AK17*((W17-V17)/AI17)*(AA17/AJ17)),"") | C17: =IF(OR(Calc!$E$56="",Calc!$E$2=""),"",SQRT((Calc!$T$56-Calc!$T$2)^2+(Calc!$U$56-Calc!$U$2)^2+(Calc!$V$56-Calc!$V$2)^2)) | D17: =IF(OR(Calc!$E$57="",Calc!$E$3=""),"",SQRT((Calc!$T$57-Calc!$T$3)^2+(Calc!$U$57-Calc!$U$3)^2+(Calc!$V$57-Calc!$V$3)^2)) | E17: =IF(OR(Calc!$E$58="",Calc!$E$4=""),"",SQRT((Calc!$T$58-Calc!$T$4)^2+(Calc!$U$58-Calc!$U$4)^2+(Calc!$V$58-Calc!$V$4)^2)) | F17: =IF(OR(Calc!$E$59="",Calc!$E$5=""),"",SQRT((Calc!$T$59-Calc!$T$5)^2+(Calc!$U$59-Calc!$U$5)^2+(Calc!$V$59-Calc!$V$5)^2)) | G17: =IF(OR(Calc!$E$60="",Calc!$E$6=""),"",SQRT((Calc!$T$60-Calc!$T$6)^2+(Calc!$U$60-Calc!$U$6)^2+(Calc!$V$60-Calc!$V$6)^2)) | H17: =IF(OR(Calc!$E$61="",Calc!$E$7=""),"",SQRT((Calc!$T$61-Calc!$T$7)^2+(Calc!$U$61-Calc!$U$7)^2+(Calc!$V$61-Calc!$V$7)^2)) | L17: =IF(AND(Calc!$E$56<>"",Calc!$E$2<>""),Calc!$Z$2,"") | M17: =IF(AND(Calc!$E$56<>"",Calc!$E$2<>""),Calc!$AA$2,"") | N17: =IF(AND(Calc!$E$56<>"",Calc!$E$2<>""),Calc!$AB$2,"") | O17: =IF(AND(Calc!$E$56<>"",Calc!$E$2<>""),Calc!$Z$56,"") | P17: =IF(AND(Calc!$E$56<>"",Calc!$E$2<>""),Calc!$AA$56,"") | Q17: =IF(AND(Calc!$E$56<>"",Calc!$E$2<>""),Calc!$AB$56,"") | R17: =IF(AND(Calc!$E$56<>"",Calc!$E$2<>""),(SQRT(M17^2+N17^2)+SQRT(P17^2+Q17^2))/2,"") | S17: =IF(AND(Calc!$E$56<>"",Calc!$E$2<>""),0.5*(1-SQRT(R17^7/(R17^7+25^7))),"") | T17: =IF(AND(Calc!$E$56<>"",Calc!$E$2<>""),(1+S17)*M17,"") | U17: =IF(AND(Calc!$E$56<>"",Calc!$E$2<>""),(1+S17)*P17,"") | V17: =IF(AND(Calc!$E$56<>"",Calc!$E$2<>""),SQRT(T17^2+N17^2),"") | W17: =IF(AND(Calc!$E$56<>"",Calc!$E$2<>""),SQRT(U17^2+Q17^2),"") | X17: =IF(AND(Calc!$E$56<>"",Calc!$E$2<>""),IF(V17=0,0,MOD(DEGREES(ATAN2(T17,N17)),360)),"") | Y17: =IF(AND(Calc!$E$56<>"",Calc!$E$2<>""),IF(W17=0,0,MOD(DEGREES(ATAN2(U17,Q17)),360)),"") | Z17: =IF(AND(Calc!$E$56<>"",Calc!$E$2<>""),IF(V17*W17=0,0,IF((Y17-X17)>180,(Y17-X17)-360,IF((Y17-X17)<-180,(Y17-X17)+360,(Y17-X17)))),"") | AA17: =IF(AND(Calc!$E$56<>"",Calc!$E$2<>""),2*SQRT(V17*W17)*SIN(RADIANS(Z17/2)),"") | AB17: =IF(AND(Calc!$E$56<>"",Calc!$E$2<>""),(L17+O17)/2,"") | AC17: =IF(AND(Calc!$E$56<>"",Calc!$E$2<>""),(V17+W17)/2,"") | AD17: =IF(AND(Calc!$E$56<>"",Calc!$E$2<>""),X17+Y17,"") | AE17: =IF(AND(Calc!$E$56<>"",Calc!$E$2<>""),IF(V17*W17=0,AD17,IF(ABS(X17-Y17)>180,IF(AD17<360,(AD17+360)/2,(AD17-360)/2),AD17/2)),"") | AF17: =IF(AND(Calc!$E$56<>"",Calc!$E$2<>""),1-0.17*COS(RADIANS(AE17-30))+0.24*COS(RADIANS(2*AE17))+0.32*COS(RADIANS(3*AE17+6))-0.2*COS(RADIANS(4*AE17-63)),"") | AG17: =IF(AND(Calc!$E$56<>"",Calc!$E$2<>""),2*SQRT(AC17^7/(AC17^7+25^7)),"") | AH17: =IF(AND(Calc!$E$56<>"",Calc!$E$2<>""),1+0.015*(AB17-50)^2/SQRT(20+(AB17-50)^2),"") | AI17: =IF(AND(Calc!$E$56<>"",Calc!$E$2<>""),1+0.045*AC17,"") | AJ17: =IF(AND(Calc!$E$56<>"",Calc!$E$2<>""),1+0.015*AC17*AF17,"") | AK17: =IF(AND(Calc!$E$56<>"",Calc!$E$2<>""),-SIN(RADIANS(2*30*EXP(-(((AE17-275)/25)^2))))*AG17,"")
A18: =IF(Spectra!L4="","",Spectra!L4) | B18: =IF(AND(Calc!$E$62<>"",Calc!$E$2<>""),SQRT(((O18-L18)/AH18)^2+((W18-V18)/AI18)^2+(AA18/AJ18)^2+AK18*((W18-V18)/AI18)*(AA18/AJ18)),"") | C18: =IF(OR(Calc!$E$62="",Calc!$E$2=""),"",SQRT((Calc!$T$62-Calc!$T$2)^2+(Calc!$U$62-Calc!$U$2)^2+(Calc!$V$62-Calc!$V$2)^2)) | D18: =IF(OR(Calc!$E$63="",Calc!$E$3=""),"",SQRT((Calc!$T$63-Calc!$T$3)^2+(Calc!$U$63-Calc!$U$3)^2+(Calc!$V$63-Calc!$V$3)^2)) | E18: =IF(OR(Calc!$E$64="",Calc!$E$4=""),"",SQRT((Calc!$T$64-Calc!$T$4)^2+(Calc!$U$64-Calc!$U$4)^2+(Calc!$V$64-Calc!$V$4)^2)) | F18: =IF(OR(Calc!$E$65="",Calc!$E$5=""),"",SQRT((Calc!$T$65-Calc!$T$5)^2+(Calc!$U$65-Calc!$U$5)^2+(Calc!$V$65-Calc!$V$5)^2)) | G18: =IF(OR(Calc!$E$66="",Calc!$E$6=""),"",SQRT((Calc!$T$66-Calc!$T$6)^2+(Calc!$U$66-Calc!$U$6)^2+(Calc!$V$66-Calc!$V$6)^2)) | H18: =IF(OR(Calc!$E$67="",Calc!$E$7=""),"",SQRT((Calc!$T$67-Calc!$T$7)^2+(Calc!$U$67-Calc!$U$7)^2+(Calc!$V$67-Calc!$V$7)^2)) | L18: =IF(AND(Calc!$E$62<>"",Calc!$E$2<>""),Calc!$Z$2,"") | M18: =IF(AND(Calc!$E$62<>"",Calc!$E$2<>""),Calc!$AA$2,"") | N18: =IF(AND(Calc!$E$62<>"",Calc!$E$2<>""),Calc!$AB$2,"") | O18: =IF(AND(Calc!$E$62<>"",Calc!$E$2<>""),Calc!$Z$62,"") | P18: =IF(AND(Calc!$E$62<>"",Calc!$E$2<>""),Calc!$AA$62,"") | Q18: =IF(AND(Calc!$E$62<>"",Calc!$E$2<>""),Calc!$AB$62,"") | R18: =IF(AND(Calc!$E$62<>"",Calc!$E$2<>""),(SQRT(M18^2+N18^2)+SQRT(P18^2+Q18^2))/2,"") | S18: =IF(AND(Calc!$E$62<>"",Calc!$E$2<>""),0.5*(1-SQRT(R18^7/(R18^7+25^7))),"") | T18: =IF(AND(Calc!$E$62<>"",Calc!$E$2<>""),(1+S18)*M18,"") | U18: =IF(AND(Calc!$E$62<>"",Calc!$E$2<>""),(1+S18)*P18,"") | V18: =IF(AND(Calc!$E$62<>"",Calc!$E$2<>""),SQRT(T18^2+N18^2),"") | W18: =IF(AND(Calc!$E$62<>"",Calc!$E$2<>""),SQRT(U18^2+Q18^2),"") | X18: =IF(AND(Calc!$E$62<>"",Calc!$E$2<>""),IF(V18=0,0,MOD(DEGREES(ATAN2(T18,N18)),360)),"") | Y18: =IF(AND(Calc!$E$62<>"",Calc!$E$2<>""),IF(W18=0,0,MOD(DEGREES(ATAN2(U18,Q18)),360)),"") | Z18: =IF(AND(Calc!$E$62<>"",Calc!$E$2<>""),IF(V18*W18=0,0,IF((Y18-X18)>180,(Y18-X18)-360,IF((Y18-X18)<-180,(Y18-X18)+360,(Y18-X18)))),"") | AA18: =IF(AND(Calc!$E$62<>"",Calc!$E$2<>""),2*SQRT(V18*W18)*SIN(RADIANS(Z18/2)),"") | AB18: =IF(AND(Calc!$E$62<>"",Calc!$E$2<>""),(L18+O18)/2,"") | AC18: =IF(AND(Calc!$E$62<>"",Calc!$E$2<>""),(V18+W18)/2,"") | AD18: =IF(AND(Calc!$E$62<>"",Calc!$E$2<>""),X18+Y18,"") | AE18: =IF(AND(Calc!$E$62<>"",Calc!$E$2<>""),IF(V18*W18=0,AD18,IF(ABS(X18-Y18)>180,IF(AD18<360,(AD18+360)/2,(AD18-360)/2),AD18/2)),"") | AF18: =IF(AND(Calc!$E$62<>"",Calc!$E$2<>""),1-0.17*COS(RADIANS(AE18-30))+0.24*COS(RADIANS(2*AE18))+0.32*COS(RADIANS(3*AE18+6))-0.2*COS(RADIANS(4*AE18-63)),"") | AG18: =IF(AND(Calc!$E$62<>"",Calc!$E$2<>""),2*SQRT(AC18^7/(AC18^7+25^7)),"") | AH18: =IF(AND(Calc!$E$62<>"",Calc!$E$2<>""),1+0.015*(AB18-50)^2/SQRT(20+(AB18-50)^2),"") | AI18: =IF(AND(Calc!$E$62<>"",Calc!$E$2<>""),1+0.045*AC18,"") | AJ18: =IF(AND(Calc!$E$62<>"",Calc!$E$2<>""),1+0.015*AC18*AF18,"") | AK18: =IF(AND(Calc!$E$62<>"",Calc!$E$2<>""),-SIN(RADIANS(2*30*EXP(-(((AE18-275)/25)^2))))*AG18,"")
A21: For your own lights (a particular store LED, say), paste their spectra on the Custom lights sheet; they then appear in the list of conditions.
A22: WLab differences are material color differences; they correspond to perceived differences under a reference observing condition, like DeltaE00. WLab is not a color appearance space.

Sheet Spectra
A1: Paste spectral reflectance here: 380 to 730 nm every 10 nm, as fractions (0 to 1) or percent (0 to 100).
A2: Column B is the standard; columns C to L are the samples. Put names in row 4. If your instrument starts at 400 nm, repeat the 400 value at 380 and 390.
A4: nm | B4: Brand red standard (5R 5/6) | C4: Submission 1 (smooth) | D4: Submission 2 (jagged) | E4: Sample 3 | F4: Sample 4 | G4: Sample 5 | H4: Sample 6 | I4: Sample 7 | J4: Sample 8 | K4: Sample 9 | L4: Sample 10 | N4: Scale
A5: 380 | B5: 0.11796 | C5: 0.11792 | D5: 0.11796 | N5: =IF(MAX(B5:L40)>1.5,100,1)
A6: 390 | B6: 0.12925 | C6: 0.13531 | D6: 0.22305 | N6: (100 if the data look like percent)
A7: 400 | B7: 0.14565 | C7: 0.15707 | D7: 0.26253
A8: 410 | B8: 0.14825 | C8: 0.16294 | D8: 0.19991
A9: 420 | B9: 0.14569 | C9: 0.15824 | D9: 0.09235
A10: 430 | B10: 0.14305 | C10: 0.14861 | D10: 0.02345
A11: 440 | B11: 0.14183 | C11: 0.13804 | D11: 0.04394
A12: 450 | B12: 0.14016 | C12: 0.13154 | D12: 0.13535
A13: 460 | B13: 0.13801 | C13: 0.1304 | D13: 0.22714
A14: 470 | B14: 0.13623 | C14: 0.13626 | D14: 0.2495
A15: 480 | B15: 0.13284 | C15: 0.14183 | D15: 0.18239
A16: 490 | B16: 0.12803 | C16: 0.14286 | D16: 0.07437
A17: 500 | B17: 0.12475 | C17: 0.13779 | D17: 0.00648
A18: 510 | B18: 0.12302 | C18: 0.12961 | D18: 0.02787
... A40: 730 | B40: 0.3649 | C40: 0.33671 | D40: 0.3649

Sheet Weights
A1: Weights: X = sum over wavelength of weight x reflectance, for each condition (white Y = 100).
A2: Reflectance is used on 380-730 nm at 10 nm, interpolated to 5 nm and held constant beyond 730 nm.
B3: CIE 1931 2deg C | E3: CIE 1931 2deg D50 | H3: CIE 1931 2deg D65 | K3: CIE 1931 2deg A | N3: CIE 1931 2deg E | Q3: CIE 1931 2deg F2 | T3: CIE 1931 2deg F11 | W3: CIE 1964 10deg C | Z3: CIE 1964 10deg D50 | AC3: CIE 1964 10deg D65 | AF3: CIE 1964 10deg A | AI3: CIE 1964 10deg E | AL3: CIE 1964 10deg F2 | AO3: CIE 1964 10deg F11 | AR3: =IF(COUNT('Custom lights'!$B$8:$B$88)>0,'Custom lights'!$B$4,"") | AU3: =IF(COUNT('Custom lights'!$C$8:$C$88)>0,'Custom lights'!$C$4,"")
A4: nm | B4: X | C4: Y | D4: Z | E4: X | F4: Y | G4: Z | H4: X | I4: Y | J4: Z | K4: X | L4: Y | M4: Z | N4: X | O4: Y | P4: Z | Q4: X | R4: Y | S4: Z | T4: X | U4: Y | V4: Z | W4: X | X4: Y | Y4: Z | Z4: X | AA4: Y | AB4: Z | AC4: X | AD4: Y | AE4: Z | AF4: X | AG4: Y | AH4: Z | AI4: X | AJ4: Y | AK4: Z | AL4: X | AM4: Y | AN4: Z | AO4: X | AP4: Y | AQ4: Z | AR4: X | AS4: Y | AT4: Z | AU4: X | AV4: Y | AW4: Z
A5: 380 | B5: 0.0042160007 | C5: 0.00012043145 | D5: 0.019885062 | E5: 0.0030372239 | F5: 8.6751882e-05 | G5: 0.014325062 | H5: 0.0060020715 | I5: 0.00017142651 | J5: 0.028308468 | K5: 0.001185662 | L5: 3.3866013e-05 | M5: 0.0055921755 | N5: 0.011632408 | O5: 0.00033222083 | P5: 0.054863229 | Q5: 0.0011162845 | R5: 3.1888184e-05 | S5: 0.0052650676 | T5: 0.00066564234 | U5: 1.900401e-05 | V5: 0.0031392473 | W5: 0.00078708666 | X5: 8.5040251e-05 | Y5: 0.0034774982 | Z5: 0.00056568591 | AA5: 6.1093777e-05 | AB5: 0.0024991388 | AC5: 0.0010890872 | AD5: 0.00011758654 | AE5: 0.0048112407 | AF5: 0.00022738927 | AG5: 2.455822e-05 | AH5: 0.0010045831 | AI5: 0.0021044027 | AJ5: 0.00022715549 | AK5: 0.0092962312 | AL5: 0.00021916944 | AM5: 2.3684044e-05 | AN5: 0.00096835899 | AO5: 0.00011450797 | AP5: 1.2335806e-05 | AQ5: 0.0005056775 | AR5: =Custom1!$AV$5 | AS5: =Custom1!$AW$5 | AT5: =Custom1!$AX$5 | AU5: =Custom2!$AV$5 | AV5: =Custom2!$AW$5 | AW5: =Custom2!$AX$5
A6: 390 | B6: 0.021451061 | C6: 0.00060822406 | D6: 0.10142875 | E6: 0.014671075 | F6: 0.00041602348 | G6: 0.069373666 | H6: 0.026172318 | I6: 0.00074219109 | J6: 0.12375385 | K6: 0.0053081078 | L6: 0.00015051478 | M6: 0.025097744 | N6: 0.042982825 | O6: 0.0012189229 | P6: 0.20321621 | Q6: 0.0060393959 | R6: 0.00017123422 | S6: 0.028556879 | T6: 0.0013903388 | U6: 3.9443992e-05 | V6: 0.0065720408 | W6: 0.013829612 | X6: 0.001474376 | Y6: 0.061605745 | Z6: 0.0097649718 | AA6: 0.001040783 | AB6: 0.0435072 | AC6: 0.017002941 | AD6: 0.0018125409 | AE6: 0.075748067 | AF6: 0.0035375805 | AG6: 0.00037721231 | AH6: 0.015756956 | AI6: 0.027061505 | AJ6: 0.0028865891 | AK6: 0.12051241 | AL6: 0.0040757966 | AM6: 0.00043450081 | AN6: 0.018156497 | AO6: 0.00085196928 | AP6: 9.0966463e-05 | AQ6: 0.0037921464 | AR6: =Custom1!$AV$6 | AS6: =Custom1!$AW$6 | AT6: =Custom1!$AX$6 | AU6: =Custom2!$AV$6 | AV6: =Custom2!$AW$6 | AW6: =Custom2!$AX$6
A7: 400 | B7: 0.091551893 | C7: 0.0025374529 | D7: 0.43442226 | E7: 0.069925782 | F7: 0.0019378596 | G7: 0.3318 | H7: 0.11626304 | I7: 0.0032223815 | J7: 0.55166043 | K7: 0.02079739 | L7: 0.00057651632 | M7: 0.098682429 | N7: 0.13911162 | O7: 0.0038579729 | P7: 0.66001985 | Q7: 0.081744017 | R7: 0.0022593946 | S7: 0.38822062 | T7: 0.05699487 | U7: 0.0015737933 | V7: 0.27076645 | W7: 0.12630615 | X7: 0.013192011 | Y7: 0.57091434 | Z7: 0.09786591 | AA7: 0.010222225 | AB7: 0.44232823 | AC7: 0.16009444 | AD7: 0.016723567 | AE7: 0.72353107 | AF7: 0.02987212 | AG7: 0.0031204158 | AH7: 0.13500869 | AI7: 0.19042916 | AJ7: 0.019899678 | AK7: 0.86037498 | AL7: 0.13369393 | AM7: 0.013916407 | AN7: 0.60616622 | AO7: 0.097376125 | AP7: 0.010125541 | AQ7: 0.44191565 | AR7: =Custom1!$AV$7 | AS7: =Custom1!$AW$7 | AT7: =Custom1!$AX$7 | AU7: =Custom2!$AV$7 | AV7: =Custom2!$AW$7 | AW7: =Custom2!$AX$7
A8: 410 | B8: 0.36699227 | C8: 0.010242098 | D8: 1.7514236 | E8: 0.25367844 | F8: 0.0070778317 | G8: 1.2105314 | H8: 0.4059471 | I8: 0.011325379 | J8: 1.93709 | K8: 0.079014487 | L8: 0.0022049791 | M8: 0.37707562 | N8: 0.43946733 | O8: 0.012259417 | P8: 2.0969685 | Q8: 0.16890259 | R8: 0.0046974798 | S8: 0.80500419 | T8: 0.097558818 | U8: 0.0027089166 | V8: 0.4646839 | W8: 0.62493845 | X8: 0.064468049 | Y8: 2.8881457 | Z8: 0.43967257 | AA8: 0.045363119 | AB8: 2.0310777 | AC8: 0.6946521 | AD8: 0.071673759 | AE8: 3.2085685 | AF8: 0.14081256 | AG8: 0.014526761 | AH8: 0.65068197 | AI8: 0.75756355 | AJ8: 0.078169346 | AK8: 3.4986488 | AL8: 0.30023245 | AM8: 0.031039346 | AN8: 1.3800967 | AO8: 0.17323715 | AP8: 0.017928863 | AQ8: 0.79435248 | AR8: =Custom1!$AV$8 | AS8: =Custom1!$AW$8 | AT8: =Custom1!$AX$8 | AU8: =Custom2!$AV$8 | AV8: =Custom2!$AW$8 | AW8: =Custom2!$AX$8
A9: 420 | B9: 1.3158362 | C9: 0.041146194 | D9: 6.3361411 | E9: 0.7922093 | F9: 0.024671067 | G9: 3.8138408 | H9: 1.2214563 | I9: 0.038004853 | J9: 5.8800131 | K9: 0.27884456 | L9: 0.0087206913 | M9: 1.342728 | N9: 1.3128806 | O9: 0.040895916 | P9: 6.3205013 | Q9: 0.41126776 | R9: 0.012873975 | S9: 1.9804961 | T9: 0.25872968 | U9: 0.0081772223 | V9: 1.2466179 | W9: 1.7177658 | X9: 0.18326271 | Y9: 8.19923 | Z9: 1.0592879 | AA9: 0.11281033 | AB9: 5.0526742 | AC9: 1.6147612 | AD9: 0.17190002 | AE9: 7.7009768 | AF9: 0.38079653 | AG9: 0.040628351 | AH9: 1.8176346 | AI9: 1.745152 | AJ9: 0.18587105 | AK9: 8.3240571 | AL9: 0.55911557 | AM9: 0.059678069 | AN9: 2.6692722 | AO9: 0.34589032 | AP9: 0.037079358 | AQ9: 1.6541349 | AR9: =Custom1!$AV$9 | AS9: =Custom1!$AW$9 | AT9: =Custom1!$AX$9 | AU9: =Custom2!$AV$9 | AV9: =Custom2!$AW$9 | AW9: =Custom2!$AX$9
A10: 430 | B10: 2.9403963 | C10: 0.12592719 | D10: 14.38256 | E10: 1.5998216 | F10: 0.068691136 | G10: 7.8262983 | H10: 2.3663002 | I10: 0.10128612 | J10: 11.574045 | K10: 0.64077085 | L10: 0.027512324 | M10: 3.1346595 | N10: 2.5994408 | O10: 0.11075587 | P10: 12.711447 | Q10: 2.6219879 | R10: 0.12638163 | S10: 12.907206 | T10: 2.4611125 | U10: 0.11952662 | V10: 12.120561 | W10: 2.997732 | X10: 0.37571623 | Y10: 14.825485 | Z10: 1.6589423 | AA10: 0.20815906 | AB10: 8.2054752 | AC10: 2.4236587 | AD10: 0.30360417 | AE10: 11.98463 | AF10: 0.68305456 | AG10: 0.085728252 | AH10: 3.3788622 | AI10: 2.6826077 | AJ10: 0.33527078 | AK10: 13.260652 | AL10: 2.7321336 | AM10: 0.36536129 | AN10: 13.653347 | AO10: 2.5622866 | AP10: 0.34421059 | AQ10: 12.814698 | AR10: =Custom1!$AV$10 | AS10: =Custom1!$AW$10 | AT10: =Custom1!$AX$10 | AU10: =Custom2!$AV$10 | AV10: =Custom2!$AW$10 | AW10: =Custom2!$AX$10
A11: 440 | B11: 3.9044495 | C11: 0.26417864 | D11: 19.623134 | E11: 2.4286521 | F11: 0.16586419 | G11: 12.214117 | H11: 3.3858961 | I11: 0.23048777 | J11: 17.024307 | K11: 0.91484934 | L11: 0.062290481 | M11: 4.5999501 | N11: 3.2125286 | O11: 0.216739 | P11: 16.142376 | Q11: 3.7392361 | R11: 0.22524047 | S11: 18.647587 | T11: 3.7594098 | U11: 0.22822563 | V11: 18.757454 | W11: 3.896595 | X11: 0.64154197 | Y11: 20.005233 | Z11: 2.4650155 | AA11: 0.40831869 | AB11: 12.665225 | AC11: 3.3914976 | AD11: 0.56059401 | AE11: 17.420789 | AF11: 0.95547163 | AG11: 0.15795925 | AH11: 4.9079518 | AI11: 3.2399937 | AJ11: 0.53244389 | AK11: 16.630268 | AL11: 3.8754736 | AM11: 0.59254203 | AN11: 19.713536 | AO11: 3.9025309 | AP11: 0.59959982 | AQ11: 19.862917 | AR11: =Custom1!$AV$11 | AS11: =Custom1!$AW$11 | AT11: =Custom1!$AX$11 | AU11: =Custom2!$AV$11 | AV11: =Custom2!$AW$11 | AW11: =Custom2!$AX$11
A12: 450 | B12: 3.891676 | C12: 0.44697598 | D12: 20.548637 | E12: 2.7404672 | F12: 0.31669835 | G12: 14.480602 | H12: 3.6600527 | I12: 0.42192006 | J12: 19.334015 | K12: 1.0257415 | L12: 0.11894432 | M12: 5.4221905 | N12: 3.1330764 | O12: 0.35982791 | P12: 16.543006 | Q12: 1.5109049 | R12: 0.17473379 | S12: 7.9842872 | T12: 1.6259641 | U12: 0.18701961 | V12: 8.586808 | W12: 3.8743532 | X12: 0.9478256 | Y12: 20.852488 | Z12: 2.7727922 | AA12: 0.68184433 | AB12: 14.932959 | AC12: 3.6556064 | AD12: 0.89706401 | AE12: 19.682538 | AF12: 1.0678286 | AG12: 0.26334019 | AH12: 5.7526601 | AI12: 3.1525046 | AJ12: 0.77119716 | AK12: 16.967229 | AL12: 1.5689747 | AM12: 0.38605811 | AN12: 8.4502483 | AO12: 1.6911685 | AP12: 0.4142297 | AQ12: 9.1035891 | AR12: =Custom1!$AV$12 | AS12: =Custom1!$AW$12 | AT12: =Custom1!$AX$12 | AU12: =Custom2!$AV$12 | AV12: =Custom2!$AW$12 | AW12: =Custom2!$AX$12
A13: 460 | B13: 3.3330615 | C13: 0.70012652 | D13: 19.135701 | E13: 2.4713028 | F13: 0.52015271 | G13: 14.192853 | H13: 3.1973711 | I13: 0.67118418 | J13: 18.355049 | K13: 1.0054906 | L13: 0.21352114 | M13: 5.7826399 | N13: 2.6937962 | O13: 0.5659452 | P13: 15.466049 | Q13: 1.4083723 | R13: 0.29748759 | S13: 8.0928729 | T13: 1.3176009 | U13: 0.27339258 | V13: 7.5502595 | W13: 3.1523817 | X13: 1.35196 | Y13: 18.223308 | Z13: 2.3757168 | AA13: 1.020934 | AB13: 13.737684 | AC13: 3.0345004 | AD13: 1.3006069 | AE13: 17.540322 | AF13: 0.99396538 | AG13: 0.43091133 | AH13: 5.7551132 | AI13: 2.5749746 | AJ13: 1.1045307 | AK13: 14.885842 | AL13: 1.3892024 | AM13: 0.5990952 | AN13: 8.0372891 | AO13: 1.3034151 | AP13: 0.55228019 | AQ13: 7.5214939 | AR13: =Custom1!$AV$13 | AS13: =Custom1!$AW$13 | AT13: =Custom1!$AX$13 | AU13: =Custom2!$AV$13 | AV13: =Custom2!$AW$13 | AW13: =Custom2!$AX$13
A14: 470 | B14: 2.2768383 | C14: 1.0709951 | D14: 14.946242 | E14: 1.707979 | F14: 0.80522949 | G14: 11.21632 | H14: 2.1407521 | I14: 1.0052374 | J14: 14.048069 | K14: 0.77244617 | L14: 0.36850437 | M14: 5.0838163 | N14: 1.8340461 | O14: 0.86204287 | P14: 12.037811 | Q14: 1.005166 | R14: 0.47413105 | S14: 6.6017947 | T14: 0.74329638 | U14: 0.33907774 | V14: 4.8524226 | W14: 2.0468633 | X14: 1.9573581 | Y14: 13.742338 | Z14: 1.5606934 | AA14: 1.4958664 | AB14: 10.483454 | AC14: 1.9312784 | AD14: 1.8435907 | AE14: 12.960818 | AF14: 0.72579969 | AG14: 0.70403737 | AH14: 4.8887872 | AI14: 1.6665284 | AJ14: 1.592405 | AK14: 11.186808 | AL14: 0.94275151 | AM14: 0.90406256 | AN14: 6.3335908 | AO14: 0.6996716 | AP14: 0.6486746 | AQ14: 4.6649637 | AR14: =Custom1!$AV$14 | AS14: =Custom1!$AW$14 | AT14: =Custom1!$AX$14 | AU14: =Custom2!$AV$14 | AV14: =Custom2!$AW$14 | AW14: =Custom2!$AX$14
A15: 480 | B15: 1.1377973 | C15: 1.6256407 | D15: 9.5446141 | E15: 0.87696908 | F15: 1.2556399 | G15: 7.3612906 | H15: 1.0665622 | I15: 1.5199781 | J15: 8.9414415 | K15: 0.43221758 | L15: 0.62977601 | M15: 3.6450575 | N15: 0.91554914 | O15: 1.3100263 | P15: 7.6831916 | Q15: 0.51012779 | R15: 0.72994573 | S15: 4.2810445 | T15: 0.44247231 | U15: 0.77388109 | V15: 3.9269478 | W15: 0.88144996 | X15: 2.6966247 | Y15: 8.2830927 | Z15: 0.69035998 | AA15: 2.1171237 | AB15: 6.4935449 | AC15: 0.82941073 | AD15: 2.5304746 | AE15: 7.7868764 | AF15: 0.34906576 | AG15: 1.0912937 | AH15: 3.3062085 | AI15: 0.71668628 | AJ15: 2.1960857 | AK15: 6.7386104 | AL15: 0.41226272 | AM15: 1.2633312 | AN15: 3.8764285 | AO15: 0.34472512 | AP15: 1.3221418 | AQ15: 3.5279548 | AR15: =Custom1!$AV$15 | AS15: =Custom1!$AW$15 | AT15: =Custom1!$AX$15 | AU15: =Custom2!$AV$15 | AV15: =Custom2!$AW$15 | AW15: =Custom2!$AX$15
A16: 490 | B16: 0.38905407 | C16: 2.3776135 | D16: 5.3851079 | E16: 0.30185889 | F16: 1.8644651 | G16: 4.195767 | H16: 0.35679145 | I16: 2.1884088 | J16: 4.9448089 | K16: 0.16787464 | L16: 1.0606088 | M16: 2.3563865 | N16: 0.31975085 | O16: 1.9744679 | P16: 4.4448808 | Q16: 0.17739064 | R16: 1.0905193 | S16: 2.4615971 | T16: 0.32743989 | U16: 1.8718689 | V16: 4.4210848 | W16: 0.20327617 | X16: 3.5043054 | Y16: 4.3764479 | Z16: 0.15997099 | AA16: 2.7910088 | AB16: 3.465045 | AC16: 0.18704864 | AD16: 3.2352392 | AE16: 4.0318262 | AF16: 0.090778734 | AG16: 1.6310494 | AH16: 2.0006442 | AI16: 0.1683265 | AJ16: 2.9386848 | AK16: 3.6493258 | AL16: 0.096503166 | AM16: 1.676382 | AN16: 2.0869473 | AO16: 0.18056179 | AP16: 2.9015888 | AQ16: 3.76423 | AR16: =Custom1!$AV$16 | AS16: =Custom1!$AW$16 | AT16: =Custom1!$AX$16 | AU16: =Custom2!$AV$16 | AV16: =Custom2!$AW$16 | AW16: =Custom2!$AX$16
A17: 500 | B17: 0.072175139 | C17: 3.4333957 | D17: 2.9350136 | E17: 0.060635487 | F17: 2.9807904 | G17: 2.513704 | H17: 0.06945409 | I17: 3.384863 | J17: 2.864465 | K17: 0.036457317 | L17: 1.8305932 | M17: 1.5295254 | N17: 0.062934791 | O17: 3.0692993 | P17: 2.5960016 | Q17: 0.033810592 | R17: 1.6291804 | S17: 1.3847951 | T17: 0.031367203 | U17: 1.078733 | V17: 1.0639923 | W17: 0.066131575 | X17: 4.3915864 | Y17: 2.1571608 | Z17: 0.059133816 | AA17: 3.8675183 | AB17: 1.8748041 | AC17: 0.066075047 | AD17: 4.33716 | AE17: 2.1096642 | AF17: 0.037800696 | AG17: 2.4405125 | AH17: 1.1725748 | AI17: 0.060449075 | AJ17: 3.9608481 | AK17: 1.9256978 | AL17: 0.032974713 | AM17: 2.1723362 | AN17: 1.0612563 | AO17: 0.019084381 | AP17: 1.476797 | AQ17: 0.83195429 | AR17: =Custom1!$AV$17 | AS17: =Custom1!$AW$17 | AT17: =Custom1!$AX$17 | AU17: =Custom2!$AV$17 | AV17: =Custom2!$AW$17 | AW17: =Custom2!$AX$17
A18: 510 | B18: 0.11822478 | C18: 4.8507843 | D18: 1.5524879 | E18: 0.11533062 | F18: 4.6467 | G18: 1.4706614 | H18: 0.12678098 | I18: 5.1413885 | J18: 1.6331771 | K18: 0.078665813 | L18: 3.1097641 | M18: 0.9731308 | N18: 0.11721312 | O18: 4.7294677 | P18: 1.4982692 | Q18: 0.060298991 | R18: 2.4392895 | S18: 0.77431343 | T18: 0.011088917 | U18: 0.52877403 | V18: 0.18485574 | W18: 0.3483211 | X18: 5.2930795 | Y18: 1.023307 | Z18: 0.34281949 | AA18: 5.1467366 | AB18: 0.98506132 | AC18: 0.37304081 | AD18: 5.6235678 | AE18: 1.0797961 | AF18: 0.23867776 | AG18: 3.5391568 | AH18: 0.67056486 | AI18: 0.34658784 | AJ18: 5.2085082 | AK18: 0.99773762 | AL18: 0.18424104 | AM18: 2.7742235 | AN18: 0.53243511 | AO18: 0.036316325 | AP18: 0.61050329 | AQ18: 0.12787402 | AR18: =Custom1!$AV$18 | AS18: =Custom1!$AW$18 | AT18: =Custom1!$AX$18 | AU18: =Custom2!$AV$18 | AV18: =Custom2!$AW$18 | AW18: =Custom2!$AX$18
A19: 520 | B19: 0.60450032 | C19: 6.4446104 | D19: 0.74534894 | E19: 0.61935974 | F19: 6.5643223 | G19: 0.7549137 | H19: 0.66235466 | I19: 7.0434386 | J19: 0.8127706 | K19: 0.45172294 | L19: 4.7541596 | M19: 0.54265866 | N19: 0.62055108 | O19: 6.6009004 | P19: 0.76141739 | Q19: 0.32946839 | R19: 3.4787645 | S19: 0.39861348 | T19: 0.040227477 | U19: 0.44243248 | V19: 0.052875286 | W19: 0.99184327 | X19: 6.2789058 | Y19: 0.5119709 | Z19: 1.0307842 | AA19: 6.4987442 | AB19: 0.5272633 | AC19: 1.0894032 | AD19: 6.8844739 | AE19: 0.56021279 | AF19: 0.77164342 | AG19: 4.8407181 | AH19: 0.39020912 | AI19: 1.0282193 | AJ19: 6.4985842 | AK19: 0.52870654 | AL19: 0.56198499 | AM19: 3.533825 | AN19: 0.28579128 | AO19: 0.069785094 | AP19: 0.45164204 | AQ19: 0.037875018 | AR19: =Custom1!$AV$19 | AS19: =Custom1!$AW$19 | AT19: =Custom1!$AX$19 | AU19: =Custom2!$AV$19 | AV19: =Custom2!$AW$19 | AW19: =Custom2!$AX$19
A20: 530 | B20: 1.5405101 | C20: 7.9165869 | D20: 0.39415807 | E20: 1.6089326 | F20: 8.2772606 | G20: 0.41260795 | H20: 1.6851309 | I20: 8.6810866 | J20: 0.43357824 | K20: 1.2310148 | L20: 6.3032052 | M20: 0.31219717 | N20: 1.5589813 | O20: 8.0295669 | P20: 0.40102798 | Q20: 0.9364656 | R20: 4.7654756 | S20: 0.23401677 | T20: 0.27109707 | U20: 1.2251766 | V20: 0.050067985 | W20: 1.9895516 | X20: 7.3107413 | Y20: 0.25944529 | Z20: 2.1130743 | AA20: 7.7710774 | AB20: 0.27613301 | AC20: 2.1851675 | AD20: 8.0448571 | AE20: 0.28645575 | AF20: 1.6618122 | AG20: 6.0889554 | AH20: 0.21488208 | AI20: 2.0361446 | AJ20: 7.4951924 | AK20: 0.2668777 | AL20: 1.2588237 | AM20: 4.5900512 | AN20: 0.16050211 | AO20: 0.35444237 | AP20: 1.1762718 | AQ20: 0.033702369 | AR20: =Custom1!$AV$20 | AS20: =Custom1!$AW$20 | AT20: =Custom1!$AX$20 | AU20: =Custom2!$AV$20 | AV20: =Custom2!$AW$20 | AW20: =Custom2!$AX$20
A21: 540 | B21: 2.8001602 | C21: 9.1139109 | D21: 0.20006787 | E21: 2.8067136 | F21: 9.1519748 | G21: 0.20175556 | H21: 2.8878843 | I21: 9.4251738 | J21: 0.20818756 | K21: 2.3334769 | L21: 7.5798231 | M21: 0.16566886 | N21: 2.728539 | O21: 8.8977863 | P21: 0.19615066 | Q21: 2.863005 | R21: 8.8125874 | S21: 0.17155986 | T21: 8.5886164 | U21: 25.855278 | V21: 0.46607224 | W21: 3.2831321 | X21: 8.317595 | Y21: 0.12071927 | Z21: 3.3466265 | AA21: 8.4915605 | AB21: 0.12382992 | AC21: 3.399212 | AD21: 8.6315737 | AE21: 0.12615324 | AF21: 2.8614998 | AG21: 7.2372189 | AH21: 0.10451958 | AI21: 3.234482 | AJ21: 8.2075692 | AK21: 0.1196938 | AL21: 3.4682878 | AM21: 8.3800904 | AN21: 0.10553177 | AO21: 10.382259 | AP21: 24.613461 | AQ21: 0.28462478 | AR21: =Custom1!$AV$21 | AS21: =Custom1!$AW$21 | AT21: =Custom1!$AX$21 | AU21: =Custom2!$AV$21 | AV21: =Custom2!$AW$21 | AW21: =Custom2!$AX$21
A22: 550 | B22: 4.2899166 | C22: 9.7894739 | D22: 0.090203191 | E22: 4.2128804 | F22: 9.6217947 | G22: 0.088836221 | H22: 4.2567287 | I22: 9.7289962 | J22: 0.089996057 | K22: 3.7557353 | L22: 8.5494731 | M22: 0.078284974 | N22: 4.0677165 | O22: 9.2886137 | P22: 0.085745728 | Q22: 5.2666661 | R22: 12.309256 | S22: 0.12096961 | T22: 9.9580283 | U22: 24.555928 | V22: 0.27148091 | W22: 4.7564324 | X22: 8.8597886 | Y22: 0.037823983 | Z22: 4.7492079 | AA22: 8.852923 | AB22: 0.037942382 | AC22: 4.736718 | AD22: 8.8353044 | AE22: 0.038002772 | AF22: 4.3554557 | AG22: 8.0953105 | AH22: 0.034146992 | AI22: 4.5587299 | AJ22: 8.496541 | AK22: 0.036398452 | AL22: 6.1125489 | AM22: 11.628878 | AN22: 0.05580931 | AO22: 11.653755 | AP22: 23.239075 | AQ22: 0.1366233 | AR22: =Custom1!$AV$22 | AS22: =Custom1!$AW$22 | AT22: =Custom1!$AX$22 | AU22: =Custom2!$AV$22 | AV22: =Custom2!$AW$22 | AW22: =Custom2!$AX$22
A23: 560 | B23: 5.8688108 | C23: 9.7939208 | D23: 0.040275742 | E23: 5.6588528 | F23: 9.4463347 | G23: 0.03887779 | H23: 5.6243791 | I23: 9.3943172 | J23: 0.038718397 | K23: 5.5274307 | L23: 9.1942835 | M23: 0.037522374 | N23: 5.5669215 | O23: 9.2848703 | P23: 0.038135208 | Q23: 6.5903419 | R23: 10.916122 | S23: 0.044091356 | T23: 1.4590487 | U23: 2.5730979 | V23: 0.012072413 | W23: 6.3045248 | X23: 8.8927553 | Y23: 0.0024532931 | Z23: 6.1802758 | AA23: 8.7198001 | AB23: 0.0024199886 | AC23: 6.0631359 | AD23: 8.5590248 | AE23: 0.0023946459 | AF23: 6.2106046 | AG23: 8.7348813 | AH23: 0.0023116565 | AI23: 6.0439068 | AJ23: 8.520838 | AK23: 0.0023379871 | AL23: 7.3824113 | AM23: 10.343868 | AN23: 0.0025701886 | AO23: 1.6458838 | AP23: 2.4386605 | AQ23: 0.0013264338 | AR23: =Custom1!$AV$23 | AS23: =Custom1!$AW$23 | AT23: =Custom1!$AX$23 | AU23: =Custom2!$AV$23 | AV23: =Custom2!$AW$23 | AW23: =Custom2!$AX$23
A24: 570 | B24: 7.3009669 | C24: 9.1185945 | D24: 0.021044474 | E24: 7.1134303 | F24: 8.8738789 | G24: 0.020453013 | H24: 6.9639673 | I24: 8.692425 | J24: 0.020049473 | K24: 7.5765972 | L24: 9.4274982 | M24: 0.021652229 | N24: 7.1242651 | O24: 8.8857374 | P24: 0.020471354 | Q24: 9.9683499 | R24: 12.343154 | S24: 0.028196694 | T24: 1.2989237 | U24: 1.5628293 | V24: 0.0034794584 | W24: 7.6114016 | X24: 8.2872301 | Y24: 0 | Z24: 7.5380478 | AA24: 8.1988237 | AB24: 0 | AC24: 7.2843134 | AD24: 7.926887 | AE24: 0 | AF24: 8.2601629 | AG24: 8.9637969 | AH24: 0 | AI24: 7.5053544 | AJ24: 8.1618659 | AK24: 0 | AL24: 10.831599 | AM24: 11.703831 | AN24: 0 | AO24: 1.4072626 | AP24: 1.4827596 | AQ24: 0 | AR24: =Custom1!$AV$24 | AS24: =Custom1!$AW$24 | AT24: =Custom1!$AX$24 | AU24: =Custom2!$AV$24 | AV24: =Custom2!$AW$24 | AW24: =Custom2!$AX$24
A25: 580 | B25: 8.3825553 | C25: 7.9776567 | D25: 0.014948314 | E25: 8.5271628 | F25: 8.1080969 | G25: 0.015187693 | H25: 8.2030492 | I25: 7.8047169 | J25: 0.014623967 | K25: 9.6996902 | L25: 9.197267 | M25: 0.017201788 | N25: 8.5481355 | O25: 8.1223314 | P25: 0.015207292 | Q25: 13.442796 | R25: 12.815147 | S25: 0.024050855 | T25: 6.6331574 | U25: 6.1009207 | V25: 0.011245661 | W25: 8.4300773 | X25: 7.2438935 | Y25: 0 | Z25: 8.7171956 | AA25: 7.4849008 | AB25: 0 | AC25: 8.2774252 | AD25: 7.1110307 | AE25: 0 | AF25: 10.201962 | AG25: 8.7389899 | AH25: 0 | AI25: 8.6871587 | AJ25: 7.4546988 | AK25: 0 | AL25: 14.107428 | AM25: 12.139298 | AN25: 0 | AO25: 6.9439052 | AP25: 5.795011 | AQ25: 0 | AR25: =Custom1!$AV$25 | AS25: =Custom1!$AW$25 | AT25: =Custom1!$AX$25 | AU25: =Custom2!$AV$25 | AV25: =Custom2!$AW$25 | AW25: =Custom2!$AX$25
A26: 590 | B26: 8.9482098 | C26: 6.6308843 | D26: 0.010093608 | E26: 9.2134812 | F26: 6.8199076 | G26: 0.010377483 | H26: 8.6756239 | I26: 6.4266656 | J26: 0.0097845885 | K26: 11.53697 | L26: 8.5226254 | M26: 0.012940941 | N26: 9.5639826 | O26: 7.0777074 | P26: 0.010762083 | Q26: 12.961874 | R26: 9.6160126 | S26: 0.014647802 | T26: 8.6851556 | U26: 6.5037312 | V26: 0.0099732635 | W26: 8.8202346 | X26: 6.1586234 | Y26: 0 | Z26: 9.2315616 | AA26: 6.4401867 | AB26: 0 | AC26: 8.5803384 | AD26: 5.9895178 | AE26: 0 | AF26: 11.894492 | AG26: 8.2844726 | AH26: 0 | AI26: 9.5269011 | AJ26: 6.6449109 | AK26: 0 | AL26: 13.333586 | AM26: 9.3184282 | AN26: 0 | AO26: 8.9539308 | AP26: 6.304545 | AQ26: 0 | AR26: =Custom1!$AV$26 | AS26: =Custom1!$AW$26 | AT26: =Custom1!$AX$26 | AU26: =Custom2!$AV$26 | AV26: =Custom2!$AW$26 | AW26: =Custom2!$AX$26
A27: 600 | B27: 8.91884 | C27: 5.328765 | D27: 0.0067634328 | E27: 9.7956079 | F27: 5.8445337 | G27: 0.0074025738 | H27: 8.9786296 | I27: 5.3602847 | J27: 0.006795446 | K27: 12.636852 | L27: 7.5349885 | M27: 0.009534089 | N27: 9.8887168 | O27: 5.9044064 | P27: 0.0074866666 | Q27: 11.913922 | R27: 7.1396825 | S27: 0.0091040799 | T27: 6.1515181 | U27: 3.6758301 | V27: 0.0046613609 | W27: 8.5515947 | X27: 5.0342499 | Y27: 0 | Z27: 9.5465222 | AA27: 5.6138218 | AB27: 0 | AC27: 8.6374129 | AD27: 5.0816165 | AE27: 0 | AF27: 12.673021 | AG27: 7.4486504 | AH27: 0 | AI27: 9.5820613 | AJ27: 5.6379842 | AK27: 0 | AL27: 11.925652 | AM27: 7.0371811 | AN27: 0 | AO27: 6.1617314 | AP27: 3.6279898 | AQ27: 0 | AR27: =Custom1!$AV$27 | AS27: =Custom1!$AW$27 | AT27: =Custom1!$AX$27 | AU27: =Custom2!$AV$27 | AV27: =Custom2!$AW$27 | AW27: =Custom2!$AX$27
A28: 610 | B28: 8.2864091 | C28: 4.1840559 | D28: 0.0031599755 | E28: 9.4047065 | F28: 4.7474418 | G28: 0.003579972 | H28: 8.439968 | I28: 4.261948 | J28: 0.0032194839 | K28: 12.593556 | L28: 6.3519838 | M28: 0.0047715419 | N28: 9.3330657 | O28: 4.7119208 | P28: 0.0035561666 | Q28: 9.4206327 | R28: 4.7735054 | S28: 0.0036669704 | T28: 27.481149 | U28: 13.642115 | V28: 0.009157918 | W28: 7.7199691 | X28: 3.9756948 | Y28: 0 | Z28: 8.9071567 | AA28: 4.5860837 | AB28: 0 | AC28: 7.8901293 | AD28: 4.0636011 | AE28: 0 | AF28: 12.272823 | AG28: 6.3148142 | AH28: 0 | AI28: 8.7879172 | AJ28: 4.5251902 | AK28: 0 | AL28: 9.1645052 | AM28: 4.733084 | AN28: 0 | AO28: 26.672796 | AP28: 13.548113 | AQ28: 0 | AR28: =Custom1!$AV$28 | AS28: =Custom1!$AW$28 | AT28: =Custom1!$AX$28 | AU28: =Custom2!$AV$28 | AV28: =Custom2!$AW$28 | AW28: =Custom2!$AX$28
A29: 620 | B29: 7.0320998 | C29: 3.1537128 | D29: 0.0014898628 | E29: 7.9862498 | F29: 3.5822432 | G29: 0.0016942987 | H29: 7.03342 | I29: 3.155538 | J29: 0.0014940134 | K29: 11.293966 | L29: 5.0619037 | M29: 0.0023841527 | N29: 7.9515418 | O29: 3.5659929 | P29: 0.0016845 | Q29: 6.4135082 | R29: 2.8846858 | S29: 0.0013817302 | T29: 12.35667 | U29: 5.643801 | V29: 0.0028247506 | W29: 6.4096501 | X29: 2.9955504 | Y29: 0 | Z29: 7.4004792 | AA29: 3.4590878 | AB29: 0 | AC29: 6.4329904 | AD29: 3.0074004 | AE29: 0 | AF29: 10.769797 | AG29: 5.03074 | AH29: 0 | AI29: 7.3252587 | AJ29: 3.4234089 | AK29: 0 | AL29: 6.1017133 | AM29: 2.8583632 | AN29: 0 | AO29: 11.800561 | AP29: 5.5981932 | AQ29: 0 | AR29: =Custom1!$AV$29 | AS29: =Custom1!$AW$29 | AT29: =Custom1!$AX$29 | AU29: =Custom2!$AV$29 | AV29: =Custom2!$AW$29 | AW29: =Custom2!$AX$29
A30: 630 | B30: 5.3264873 | C30: 2.2065813 | D30: 0.00047529858 | E30: 5.9249977 | F30: 2.454585 | G30: 0.00052920199 | H30: 5.1218132 | I30: 2.122226 | J30: 0.00045856281 | K30: 8.9926513 | L30: 3.7238499 | M30: 0.00079798819 | N30: 6.0316797 | O30: 2.498675 | P30: 0.00053810416 | Q30: 3.758086 | R30: 1.5602757 | S30: 0.00034568867 | T30: 4.850749 | U30: 2.0200989 | V30: 0.00046021121 | W30: 4.8401104 | X30: 2.1248208 | Y30: 0 | Z30: 5.4732839 | AA30: 2.4028181 | AB30: 0 | AC30: 4.6700869 | AD30: 2.0505077 | AE30: 0 | AF30: 8.5486642 | AG30: 3.7516638 | AH30: 0 | AI30: 5.539538 | AJ30: 2.4318366 | AK30: 0 | AL30: 3.5651244 | AM30: 1.5678808 | AN30: 0 | AO30: 4.6150435 | AP30: 2.0348675 | AQ30: 0 | AR30: =Custom1!$AV$30 | AS30: =Custom1!$AW$30 | AT30: =Custom1!$AX$30 | AU30: =Custom2!$AV$30 | AV30: =Custom2!$AW$30 | AW30: =Custom2!$AX$30
A31: 640 | B31: 3.7102248 | C31: 1.4547877 | D31: 0.00016501773 | E31: 4.1990567 | F31: 1.6464243 | G31: 0.00018678939 | H31: 3.5429962 | I31: 1.389345 | J31: 0.00015783197 | K31: 6.5682175 | L31: 2.5747869 | M31: 0.00029118207 | N31: 4.2077406 | O31: 1.6498742 | P31: 0.00018716666 | Q31: 1.9769359 | R31: 0.77643629 | S31: 8.9862664e-05 | T31: 0.93358471 | U31: 0.36825742 | V31: 4.4308541e-05 | W31: 3.2566846 | X31: 1.3612722 | Y31: 0 | Z31: 3.7469412 | AA31: 1.5661682 | AB31: 0 | AC31: 3.1207485 | AD31: 1.3045757 | AE31: 0 | AF31: 6.0307582 | AG31: 2.5202048 | AH31: 0 | AI31: 3.7329233 | AJ31: 1.560346 | AK31: 0 | AL31: 1.8132176 | AM31: 0.7591544 | AN31: 0 | AO31: 0.86097362 | AP31: 0.36198389 | AQ31: 0 | AR31: =Custom1!$AV$31 | AS31: =Custom1!$AW$31 | AT31: =Custom1!$AX$31 | AU31: =Custom2!$AV$31 | AV31: =Custom2!$AW$31 | AW31: =Custom2!$AX$31
A32: 650 | B32: 2.3726545 | C32: 0.89773049 | D32: 2.066097e-05 | E32: 2.6317206 | F32: 0.99579068 | G32: 2.315697e-05 | H32: 2.1867928 | I32: 0.82748513 | J32: 1.9367103e-05 | K32: 4.3722745 | L32: 1.6541031 | M32: 3.7424276e-05 | N32: 2.6823323 | O32: 1.0149112 | P32: 2.3395833e-05 | Q32: 0.93770622 | R32: 0.35514415 | S32: 9.2714092e-06 | T32: 0.60314579 | U32: 0.22796684 | V32: 3.9954522e-06 | W32: 2.0342419 | X32: 0.81894888 | Y32: 0 | Z32: 2.2939183 | AA32: 0.92353431 | AB32: 0 | AC32: 1.8814129 | AD32: 0.75750111 | AE32: 0 | AF32: 3.9216892 | AG32: 1.5785932 | AH32: 0 | AI32: 2.3243749 | AJ32: 0.9357606 | AK32: 0 | AL32: 0.83948248 | AM32: 0.3383005 | AN32: 0 | AO32: 0.54006146 | AP32: 0.21714881 | AQ32: 0 | AR32: =Custom1!$AV$32 | AS32: =Custom1!$AW$32 | AT32: =Custom1!$AX$32 | AU32: =Custom2!$AV$32 | AV32: =Custom2!$AW$32 | AW32: =Custom2!$AX$32
A33: 660 | B33: 1.3818553 | C33: 0.51210248 | D33: 0 | E33: 1.5660917 | F33: 0.58033243 | G33: 0 | H33: 1.2733702 | I33: 0.47188103 | J33: 0 | K33: 2.6605203 | L33: 0.98587503 | M33: 0 | N33: 1.5668189 | O33: 0.58063779 | P33: 0 | Q33: 0.4056431 | R33: 0.15040664 | S33: 0 | T33: 0.29633945 | U33: 0.10988812 | V33: 0 | W33: 1.1624804 | X33: 0.45973766 | Y33: 0 | Z33: 1.3393216 | AA33: 0.52964157 | AB33: 0 | AC33: 1.0748684 | AD33: 0.4250758 | AE33: 0 | AF33: 2.341533 | AG33: 0.9259653 | AH33: 0 | AI33: 1.3321726 | AJ33: 0.52684001 | AK33: 0 | AL33: 0.35622087 | AM33: 0.1409344 | AN33: 0 | AO33: 0.2605894 | AP33: 0.10310536 | AQ33: 0 | AR33: =Custom1!$AV$33 | AS33: =Custom1!$AW$33 | AT33: =Custom1!$AX$33 | AU33: =Custom2!$AV$33 | AV33: =Custom2!$AW$33 | AW33: =Custom2!$AX$33
