Workbook

Sheet Read me
A1: Wpt normalization and material adjustment transforms (MATs)
A3: Inputs Pick an observer and a light for the source and for the destination, or paste your own (380-780 nm, 5 nm).
A4: Source, Destination Each Wpt normalization in four steps, as in the Technical annex (A.3). Results at rows 59-65.
A5: Results Both normalizations, the MAT from source to destination and back, an XYZ converter, and the
A6: source observer's functions converted by the MAT (meaningful when both conditions share one light).
A7: Base The 40 base reflectances and their reference p, t (Technical annex A.4).
A9: This workbook uses the reference coordinates of the Wpt toolbox. The 2015 Wpt paper's matrices differ slightly
A10: (Technical annex A.4); MATs are the same with either.

Sheet Results
A1: Results
A2: =Inputs!C4&" / "&Inputs!C5&" to "&Inputs!H4&" / "&Inputs!H5
A3: Source: XYZ to Wpt | E3: Source: Wpt to XYZ | I3: Source observer functions converted by the MAT (C'(nm) = MAT x C(nm))
A4: =Source!$B$59 | B4: =Source!$C$59 | C4: =Source!$D$59 | E4: =Source!$B$63 | F4: =Source!$C$63 | G4: =Source!$D$63 | I4: nm | J4: x' | K4: y' | L4: z'
A5: =Source!$B$60 | B5: =Source!$C$60 | C5: =Source!$D$60 | E5: =Source!$B$64 | F5: =Source!$C$64 | G5: =Source!$D$64 | I5: 380 | J5: =$A$14*INDEX(CHOOSE(MATCH(Inputs!$C$4,{"CIE 1931 2deg","CIE 1964 10deg","CIE 2015 2deg","Pasted below"},0),Tables!$B$5:$B$85,Tables!$E$5:$E$85,Tables!$H$5:$H$85,Inputs!$C$9:$C$89),1)+$B$14*INDEX(CHOOSE(MATCH(Inputs!$C$4,{"CIE 1931 2deg","CIE 1964 10deg","CIE 2015 2deg","Pasted below"},0),Tables!$C$5:$C$85,Tables!$F$5:$F$85,Tables!$I$5:$I$85,Inputs!$D$9:$D$89),1)+$C$14*INDEX(CHOOSE(MATCH(Inputs!$C$4,{"CIE 1931 2deg","CIE 1964 10deg","CIE 2015 2deg","Pasted below"},0),Tables!$D$5:$D$85,Tables!$G$5:$G$85,Tables!$J$5:$J$85,Inputs!$E$9:$E$89),1) | K5: =$A$15*INDEX(CHOOSE(MATCH(Inputs!$C$4,{"CIE 1931 2deg","CIE 1964 10deg","CIE 2015 2deg","Pasted below"},0),Tables!$B$5:$B$85,Tables!$E$5:$E$85,Tables!$H$5:$H$85,Inputs!$C$9:$C$89),1)+$B$15*INDEX(CHOOSE(MATCH(Inputs!$C$4,{"CIE 1931 2deg","CIE 1964 10deg","CIE 2015 2deg","Pasted below"},0),Tables!$C$5:$C$85,Tables!$F$5:$F$85,Tables!$I$5:$I$85,Inputs!$D$9:$D$89),1)+$C$15*INDEX(CHOOSE(MATCH(Inputs!$C$4,{"CIE 1931 2deg","CIE 1964 10deg","CIE 2015 2deg","Pasted below"},0),Tables!$D$5:$D$85,Tables!$G$5:$G$85,Tables!$J$5:$J$85,Inputs!$E$9:$E$89),1) | L5: =$A$16*INDEX(CHOOSE(MATCH(Inputs!$C$4,{"CIE 1931 2deg","CIE 1964 10deg","CIE 2015 2deg","Pasted below"},0),Tables!$B$5:$B$85,Tables!$E$5:$E$85,Tables!$H$5:$H$85,Inputs!$C$9:$C$89),1)+$B$16*INDEX(CHOOSE(MATCH(Inputs!$C$4,{"CIE 1931 2deg","CIE 1964 10deg","CIE 2015 2deg","Pasted below"},0),Tables!$C$5:$C$85,Tables!$F$5:$F$85,Tables!$I$5:$I$85,Inputs!$D$9:$D$89),1)+$C$16*INDEX(CHOOSE(MATCH(Inputs!$C$4,{"CIE 1931 2deg","CIE 1964 10deg","CIE 2015 2deg","Pasted below"},0),Tables!$D$5:$D$85,Tables!$G$5:$G$85,Tables!$J$5:$J$85,Inputs!$E$9:$E$89),1)
A6: =Source!$B$61 | B6: =Source!$C$61 | C6: =Source!$D$61 | E6: =Source!$B$65 | F6: =Source!$C$65 | G6: =Source!$D$65 | I6: 385 | J6: =$A$14*INDEX(CHOOSE(MATCH(Inputs!$C$4,{"CIE 1931 2deg","CIE 1964 10deg","CIE 2015 2deg","Pasted below"},0),Tables!$B$5:$B$85,Tables!$E$5:$E$85,Tables!$H$5:$H$85,Inputs!$C$9:$C$89),2)+$B$14*INDEX(CHOOSE(MATCH(Inputs!$C$4,{"CIE 1931 2deg","CIE 1964 10deg","CIE 2015 2deg","Pasted below"},0),Tables!$C$5:$C$85,Tables!$F$5:$F$85,Tables!$I$5:$I$85,Inputs!$D$9:$D$89),2)+$C$14*INDEX(CHOOSE(MATCH(Inputs!$C$4,{"CIE 1931 2deg","CIE 1964 10deg","CIE 2015 2deg","Pasted below"},0),Tables!$D$5:$D$85,Tables!$G$5:$G$85,Tables!$J$5:$J$85,Inputs!$E$9:$E$89),2) | K6: =$A$15*INDEX(CHOOSE(MATCH(Inputs!$C$4,{"CIE 1931 2deg","CIE 1964 10deg","CIE 2015 2deg","Pasted below"},0),Tables!$B$5:$B$85,Tables!$E$5:$E$85,Tables!$H$5:$H$85,Inputs!$C$9:$C$89),2)+$B$15*INDEX(CHOOSE(MATCH(Inputs!$C$4,{"CIE 1931 2deg","CIE 1964 10deg","CIE 2015 2deg","Pasted below"},0),Tables!$C$5:$C$85,Tables!$F$5:$F$85,Tables!$I$5:$I$85,Inputs!$D$9:$D$89),2)+$C$15*INDEX(CHOOSE(MATCH(Inputs!$C$4,{"CIE 1931 2deg","CIE 1964 10deg","CIE 2015 2deg","Pasted below"},0),Tables!$D$5:$D$85,Tables!$G$5:$G$85,Tables!$J$5:$J$85,Inputs!$E$9:$E$89),2) | L6: =$A$16*INDEX(CHOOSE(MATCH(Inputs!$C$4,{"CIE 1931 2deg","CIE 1964 10deg","CIE 2015 2deg","Pasted below"},0),Tables!$B$5:$B$85,Tables!$E$5:$E$85,Tables!$H$5:$H$85,Inputs!$C$9:$C$89),2)+$B$16*INDEX(CHOOSE(MATCH(Inputs!$C$4,{"CIE 1931 2deg","CIE 1964 10deg","CIE 2015 2deg","Pasted below"},0),Tables!$C$5:$C$85,Tables!$F$5:$F$85,Tables!$I$5:$I$85,Inputs!$D$9:$D$89),2)+$C$16*INDEX(CHOOSE(MATCH(Inputs!$C$4,{"CIE 1931 2deg","CIE 1964 10deg","CIE 2015 2deg","Pasted below"},0),Tables!$D$5:$D$85,Tables!$G$5:$G$85,Tables!$J$5:$J$85,Inputs!$E$9:$E$89),2)
I7: 390 | J7: =$A$14*INDEX(CHOOSE(MATCH(Inputs!$C$4,{"CIE 1931 2deg","CIE 1964 10deg","CIE 2015 2deg","Pasted below"},0),Tables!$B$5:$B$85,Tables!$E$5:$E$85,Tables!$H$5:$H$85,Inputs!$C$9:$C$89),3)+$B$14*INDEX(CHOOSE(MATCH(Inputs!$C$4,{"CIE 1931 2deg","CIE 1964 10deg","CIE 2015 2deg","Pasted below"},0),Tables!$C$5:$C$85,Tables!$F$5:$F$85,Tables!$I$5:$I$85,Inputs!$D$9:$D$89),3)+$C$14*INDEX(CHOOSE(MATCH(Inputs!$C$4,{"CIE 1931 2deg","CIE 1964 10deg","CIE 2015 2deg","Pasted below"},0),Tables!$D$5:$D$85,Tables!$G$5:$G$85,Tables!$J$5:$J$85,Inputs!$E$9:$E$89),3) | K7: =$A$15*INDEX(CHOOSE(MATCH(Inputs!$C$4,{"CIE 1931 2deg","CIE 1964 10deg","CIE 2015 2deg","Pasted below"},0),Tables!$B$5:$B$85,Tables!$E$5:$E$85,Tables!$H$5:$H$85,Inputs!$C$9:$C$89),3)+$B$15*INDEX(CHOOSE(MATCH(Inputs!$C$4,{"CIE 1931 2deg","CIE 1964 10deg","CIE 2015 2deg","Pasted below"},0),Tables!$C$5:$C$85,Tables!$F$5:$F$85,Tables!$I$5:$I$85,Inputs!$D$9:$D$89),3)+$C$15*INDEX(CHOOSE(MATCH(Inputs!$C$4,{"CIE 1931 2deg","CIE 1964 10deg","CIE 2015 2deg","Pasted below"},0),Tables!$D$5:$D$85,Tables!$G$5:$G$85,Tables!$J$5:$J$85,Inputs!$E$9:$E$89),3) | L7: =$A$16*INDEX(CHOOSE(MATCH(Inputs!$C$4,{"CIE 1931 2deg","CIE 1964 10deg","CIE 2015 2deg","Pasted below"},0),Tables!$B$5:$B$85,Tables!$E$5:$E$85,Tables!$H$5:$H$85,Inputs!$C$9:$C$89),3)+$B$16*INDEX(CHOOSE(MATCH(Inputs!$C$4,{"CIE 1931 2deg","CIE 1964 10deg","CIE 2015 2deg","Pasted below"},0),Tables!$C$5:$C$85,Tables!$F$5:$F$85,Tables!$I$5:$I$85,Inputs!$D$9:$D$89),3)+$C$16*INDEX(CHOOSE(MATCH(Inputs!$C$4,{"CIE 1931 2deg","CIE 1964 10deg","CIE 2015 2deg","Pasted below"},0),Tables!$D$5:$D$85,Tables!$G$5:$G$85,Tables!$J$5:$J$85,Inputs!$E$9:$E$89),3)
A8: Destination: XYZ to Wpt | E8: Destination: Wpt to XYZ | I8: 395 | J8: =$A$14*INDEX(CHOOSE(MATCH(Inputs!$C$4,{"CIE 1931 2deg","CIE 1964 10deg","CIE 2015 2deg","Pasted below"},0),Tables!$B$5:$B$85,Tables!$E$5:$E$85,Tables!$H$5:$H$85,Inputs!$C$9:$C$89),4)+$B$14*INDEX(CHOOSE(MATCH(Inputs!$C$4,{"CIE 1931 2deg","CIE 1964 10deg","CIE 2015 2deg","Pasted below"},0),Tables!$C$5:$C$85,Tables!$F$5:$F$85,Tables!$I$5:$I$85,Inputs!$D$9:$D$89),4)+$C$14*INDEX(CHOOSE(MATCH(Inputs!$C$4,{"CIE 1931 2deg","CIE 1964 10deg","CIE 2015 2deg","Pasted below"},0),Tables!$D$5:$D$85,Tables!$G$5:$G$85,Tables!$J$5:$J$85,Inputs!$E$9:$E$89),4) | K8: =$A$15*INDEX(CHOOSE(MATCH(Inputs!$C$4,{"CIE 1931 2deg","CIE 1964 10deg","CIE 2015 2deg","Pasted below"},0),Tables!$B$5:$B$85,Tables!$E$5:$E$85,Tables!$H$5:$H$85,Inputs!$C$9:$C$89),4)+$B$15*INDEX(CHOOSE(MATCH(Inputs!$C$4,{"CIE 1931 2deg","CIE 1964 10deg","CIE 2015 2deg","Pasted below"},0),Tables!$C$5:$C$85,Tables!$F$5:$F$85,Tables!$I$5:$I$85,Inputs!$D$9:$D$89),4)+$C$15*INDEX(CHOOSE(MATCH(Inputs!$C$4,{"CIE 1931 2deg","CIE 1964 10deg","CIE 2015 2deg","Pasted below"},0),Tables!$D$5:$D$85,Tables!$G$5:$G$85,Tables!$J$5:$J$85,Inputs!$E$9:$E$89),4) | L8: =$A$16*INDEX(CHOOSE(MATCH(Inputs!$C$4,{"CIE 1931 2deg","CIE 1964 10deg","CIE 2015 2deg","Pasted below"},0),Tables!$B$5:$B$85,Tables!$E$5:$E$85,Tables!$H$5:$H$85,Inputs!$C$9:$C$89),4)+$B$16*INDEX(CHOOSE(MATCH(Inputs!$C$4,{"CIE 1931 2deg","CIE 1964 10deg","CIE 2015 2deg","Pasted below"},0),Tables!$C$5:$C$85,Tables!$F$5:$F$85,Tables!$I$5:$I$85,Inputs!$D$9:$D$89),4)+$C$16*INDEX(CHOOSE(MATCH(Inputs!$C$4,{"CIE 1931 2deg","CIE 1964 10deg","CIE 2015 2deg","Pasted below"},0),Tables!$D$5:$D$85,Tables!$G$5:$G$85,Tables!$J$5:$J$85,Inputs!$E$9:$E$89),4)
A9: =Destination!$B$59 | B9: =Destination!$C$59 | C9: =Destination!$D$59 | E9: =Destination!$B$63 | F9: =Destination!$C$63 | G9: =Destination!$D$63 | I9: 400 | J9: =$A$14*INDEX(CHOOSE(MATCH(Inputs!$C$4,{"CIE 1931 2deg","CIE 1964 10deg","CIE 2015 2deg","Pasted below"},0),Tables!$B$5:$B$85,Tables!$E$5:$E$85,Tables!$H$5:$H$85,Inputs!$C$9:$C$89),5)+$B$14*INDEX(CHOOSE(MATCH(Inputs!$C$4,{"CIE 1931 2deg","CIE 1964 10deg","CIE 2015 2deg","Pasted below"},0),Tables!$C$5:$C$85,Tables!$F$5:$F$85,Tables!$I$5:$I$85,Inputs!$D$9:$D$89),5)+$C$14*INDEX(CHOOSE(MATCH(Inputs!$C$4,{"CIE 1931 2deg","CIE 1964 10deg","CIE 2015 2deg","Pasted below"},0),Tables!$D$5:$D$85,Tables!$G$5:$G$85,Tables!$J$5:$J$85,Inputs!$E$9:$E$89),5) | K9: =$A$15*INDEX(CHOOSE(MATCH(Inputs!$C$4,{"CIE 1931 2deg","CIE 1964 10deg","CIE 2015 2deg","Pasted below"},0),Tables!$B$5:$B$85,Tables!$E$5:$E$85,Tables!$H$5:$H$85,Inputs!$C$9:$C$89),5)+$B$15*INDEX(CHOOSE(MATCH(Inputs!$C$4,{"CIE 1931 2deg","CIE 1964 10deg","CIE 2015 2deg","Pasted below"},0),Tables!$C$5:$C$85,Tables!$F$5:$F$85,Tables!$I$5:$I$85,Inputs!$D$9:$D$89),5)+$C$15*INDEX(CHOOSE(MATCH(Inputs!$C$4,{"CIE 1931 2deg","CIE 1964 10deg","CIE 2015 2deg","Pasted below"},0),Tables!$D$5:$D$85,Tables!$G$5:$G$85,Tables!$J$5:$J$85,Inputs!$E$9:$E$89),5) | L9: =$A$16*INDEX(CHOOSE(MATCH(Inputs!$C$4,{"CIE 1931 2deg","CIE 1964 10deg","CIE 2015 2deg","Pasted below"},0),Tables!$B$5:$B$85,Tables!$E$5:$E$85,Tables!$H$5:$H$85,Inputs!$C$9:$C$89),5)+$B$16*INDEX(CHOOSE(MATCH(Inputs!$C$4,{"CIE 1931 2deg","CIE 1964 10deg","CIE 2015 2deg","Pasted below"},0),Tables!$C$5:$C$85,Tables!$F$5:$F$85,Tables!$I$5:$I$85,Inputs!$D$9:$D$89),5)+$C$16*INDEX(CHOOSE(MATCH(Inputs!$C$4,{"CIE 1931 2deg","CIE 1964 10deg","CIE 2015 2deg","Pasted below"},0),Tables!$D$5:$D$85,Tables!$G$5:$G$85,Tables!$J$5:$J$85,Inputs!$E$9:$E$89),5)
A10: =Destination!$B$60 | B10: =Destination!$C$60 | C10: =Destination!$D$60 | E10: =Destination!$B$64 | F10: =Destination!$C$64 | G10: =Destination!$D$64 | I10: 405 | J10: =$A$14*INDEX(CHOOSE(MATCH(Inputs!$C$4,{"CIE 1931 2deg","CIE 1964 10deg","CIE 2015 2deg","Pasted below"},0),Tables!$B$5:$B$85,Tables!$E$5:$E$85,Tables!$H$5:$H$85,Inputs!$C$9:$C$89),6)+$B$14*INDEX(CHOOSE(MATCH(Inputs!$C$4,{"CIE 1931 2deg","CIE 1964 10deg","CIE 2015 2deg","Pasted below"},0),Tables!$C$5:$C$85,Tables!$F$5:$F$85,Tables!$I$5:$I$85,Inputs!$D$9:$D$89),6)+$C$14*INDEX(CHOOSE(MATCH(Inputs!$C$4,{"CIE 1931 2deg","CIE 1964 10deg","CIE 2015 2deg","Pasted below"},0),Tables!$D$5:$D$85,Tables!$G$5:$G$85,Tables!$J$5:$J$85,Inputs!$E$9:$E$89),6) | K10: =$A$15*INDEX(CHOOSE(MATCH(Inputs!$C$4,{"CIE 1931 2deg","CIE 1964 10deg","CIE 2015 2deg","Pasted below"},0),Tables!$B$5:$B$85,Tables!$E$5:$E$85,Tables!$H$5:$H$85,Inputs!$C$9:$C$89),6)+$B$15*INDEX(CHOOSE(MATCH(Inputs!$C$4,{"CIE 1931 2deg","CIE 1964 10deg","CIE 2015 2deg","Pasted below"},0),Tables!$C$5:$C$85,Tables!$F$5:$F$85,Tables!$I$5:$I$85,Inputs!$D$9:$D$89),6)+$C$15*INDEX(CHOOSE(MATCH(Inputs!$C$4,{"CIE 1931 2deg","CIE 1964 10deg","CIE 2015 2deg","Pasted below"},0),Tables!$D$5:$D$85,Tables!$G$5:$G$85,Tables!$J$5:$J$85,Inputs!$E$9:$E$89),6) | L10: =$A$16*INDEX(CHOOSE(MATCH(Inputs!$C$4,{"CIE 1931 2deg","CIE 1964 10deg","CIE 2015 2deg","Pasted below"},0),Tables!$B$5:$B$85,Tables!$E$5:$E$85,Tables!$H$5:$H$85,Inputs!$C$9:$C$89),6)+$B$16*INDEX(CHOOSE(MATCH(Inputs!$C$4,{"CIE 1931 2deg","CIE 1964 10deg","CIE 2015 2deg","Pasted below"},0),Tables!$C$5:$C$85,Tables!$F$5:$F$85,Tables!$I$5:$I$85,Inputs!$D$9:$D$89),6)+$C$16*INDEX(CHOOSE(MATCH(Inputs!$C$4,{"CIE 1931 2deg","CIE 1964 10deg","CIE 2015 2deg","Pasted below"},0),Tables!$D$5:$D$85,Tables!$G$5:$G$85,Tables!$J$5:$J$85,Inputs!$E$9:$E$89),6)
A11: =Destination!$B$61 | B11: =Destination!$C$61 | C11: =Destination!$D$61 | E11: =Destination!$B$65 | F11: =Destination!$C$65 | G11: =Destination!$D$65 | I11: 410 | J11: =$A$14*INDEX(CHOOSE(MATCH(Inputs!$C$4,{"CIE 1931 2deg","CIE 1964 10deg","CIE 2015 2deg","Pasted below"},0),Tables!$B$5:$B$85,Tables!$E$5:$E$85,Tables!$H$5:$H$85,Inputs!$C$9:$C$89),7)+$B$14*INDEX(CHOOSE(MATCH(Inputs!$C$4,{"CIE 1931 2deg","CIE 1964 10deg","CIE 2015 2deg","Pasted below"},0),Tables!$C$5:$C$85,Tables!$F$5:$F$85,Tables!$I$5:$I$85,Inputs!$D$9:$D$89),7)+$C$14*INDEX(CHOOSE(MATCH(Inputs!$C$4,{"CIE 1931 2deg","CIE 1964 10deg","CIE 2015 2deg","Pasted below"},0),Tables!$D$5:$D$85,Tables!$G$5:$G$85,Tables!$J$5:$J$85,Inputs!$E$9:$E$89),7) | K11: =$A$15*INDEX(CHOOSE(MATCH(Inputs!$C$4,{"CIE 1931 2deg","CIE 1964 10deg","CIE 2015 2deg","Pasted below"},0),Tables!$B$5:$B$85,Tables!$E$5:$E$85,Tables!$H$5:$H$85,Inputs!$C$9:$C$89),7)+$B$15*INDEX(CHOOSE(MATCH(Inputs!$C$4,{"CIE 1931 2deg","CIE 1964 10deg","CIE 2015 2deg","Pasted below"},0),Tables!$C$5:$C$85,Tables!$F$5:$F$85,Tables!$I$5:$I$85,Inputs!$D$9:$D$89),7)+$C$15*INDEX(CHOOSE(MATCH(Inputs!$C$4,{"CIE 1931 2deg","CIE 1964 10deg","CIE 2015 2deg","Pasted below"},0),Tables!$D$5:$D$85,Tables!$G$5:$G$85,Tables!$J$5:$J$85,Inputs!$E$9:$E$89),7) | L11: =$A$16*INDEX(CHOOSE(MATCH(Inputs!$C$4,{"CIE 1931 2deg","CIE 1964 10deg","CIE 2015 2deg","Pasted below"},0),Tables!$B$5:$B$85,Tables!$E$5:$E$85,Tables!$H$5:$H$85,Inputs!$C$9:$C$89),7)+$B$16*INDEX(CHOOSE(MATCH(Inputs!$C$4,{"CIE 1931 2deg","CIE 1964 10deg","CIE 2015 2deg","Pasted below"},0),Tables!$C$5:$C$85,Tables!$F$5:$F$85,Tables!$I$5:$I$85,Inputs!$D$9:$D$89),7)+$C$16*INDEX(CHOOSE(MATCH(Inputs!$C$4,{"CIE 1931 2deg","CIE 1964 10deg","CIE 2015 2deg","Pasted below"},0),Tables!$D$5:$D$85,Tables!$G$5:$G$85,Tables!$J$5:$J$85,Inputs!$E$9:$E$89),7)
I12: 415 | J12: =$A$14*INDEX(CHOOSE(MATCH(Inputs!$C$4,{"CIE 1931 2deg","CIE 1964 10deg","CIE 2015 2deg","Pasted below"},0),Tables!$B$5:$B$85,Tables!$E$5:$E$85,Tables!$H$5:$H$85,Inputs!$C$9:$C$89),8)+$B$14*INDEX(CHOOSE(MATCH(Inputs!$C$4,{"CIE 1931 2deg","CIE 1964 10deg","CIE 2015 2deg","Pasted below"},0),Tables!$C$5:$C$85,Tables!$F$5:$F$85,Tables!$I$5:$I$85,Inputs!$D$9:$D$89),8)+$C$14*INDEX(CHOOSE(MATCH(Inputs!$C$4,{"CIE 1931 2deg","CIE 1964 10deg","CIE 2015 2deg","Pasted below"},0),Tables!$D$5:$D$85,Tables!$G$5:$G$85,Tables!$J$5:$J$85,Inputs!$E$9:$E$89),8) | K12: =$A$15*INDEX(CHOOSE(MATCH(Inputs!$C$4,{"CIE 1931 2deg","CIE 1964 10deg","CIE 2015 2deg","Pasted below"},0),Tables!$B$5:$B$85,Tables!$E$5:$E$85,Tables!$H$5:$H$85,Inputs!$C$9:$C$89),8)+$B$15*INDEX(CHOOSE(MATCH(Inputs!$C$4,{"CIE 1931 2deg","CIE 1964 10deg","CIE 2015 2deg","Pasted below"},0),Tables!$C$5:$C$85,Tables!$F$5:$F$85,Tables!$I$5:$I$85,Inputs!$D$9:$D$89),8)+$C$15*INDEX(CHOOSE(MATCH(Inputs!$C$4,{"CIE 1931 2deg","CIE 1964 10deg","CIE 2015 2deg","Pasted below"},0),Tables!$D$5:$D$85,Tables!$G$5:$G$85,Tables!$J$5:$J$85,Inputs!$E$9:$E$89),8) | L12: =$A$16*INDEX(CHOOSE(MATCH(Inputs!$C$4,{"CIE 1931 2deg","CIE 1964 10deg","CIE 2015 2deg","Pasted below"},0),Tables!$B$5:$B$85,Tables!$E$5:$E$85,Tables!$H$5:$H$85,Inputs!$C$9:$C$89),8)+$B$16*INDEX(CHOOSE(MATCH(Inputs!$C$4,{"CIE 1931 2deg","CIE 1964 10deg","CIE 2015 2deg","Pasted below"},0),Tables!$C$5:$C$85,Tables!$F$5:$F$85,Tables!$I$5:$I$85,Inputs!$D$9:$D$89),8)+$C$16*INDEX(CHOOSE(MATCH(Inputs!$C$4,{"CIE 1931 2deg","CIE 1964 10deg","CIE 2015 2deg","Pasted below"},0),Tables!$D$5:$D$85,Tables!$G$5:$G$85,Tables!$J$5:$J$85,Inputs!$E$9:$E$89),8)
A13: MAT, source to destination | E13: MAT, destination to source | I13: 420 | J13: =$A$14*INDEX(CHOOSE(MATCH(Inputs!$C$4,{"CIE 1931 2deg","CIE 1964 10deg","CIE 2015 2deg","Pasted below"},0),Tables!$B$5:$B$85,Tables!$E$5:$E$85,Tables!$H$5:$H$85,Inputs!$C$9:$C$89),9)+$B$14*INDEX(CHOOSE(MATCH(Inputs!$C$4,{"CIE 1931 2deg","CIE 1964 10deg","CIE 2015 2deg","Pasted below"},0),Tables!$C$5:$C$85,Tables!$F$5:$F$85,Tables!$I$5:$I$85,Inputs!$D$9:$D$89),9)+$C$14*INDEX(CHOOSE(MATCH(Inputs!$C$4,{"CIE 1931 2deg","CIE 1964 10deg","CIE 2015 2deg","Pasted below"},0),Tables!$D$5:$D$85,Tables!$G$5:$G$85,Tables!$J$5:$J$85,Inputs!$E$9:$E$89),9) | K13: =$A$15*INDEX(CHOOSE(MATCH(Inputs!$C$4,{"CIE 1931 2deg","CIE 1964 10deg","CIE 2015 2deg","Pasted below"},0),Tables!$B$5:$B$85,Tables!$E$5:$E$85,Tables!$H$5:$H$85,Inputs!$C$9:$C$89),9)+$B$15*INDEX(CHOOSE(MATCH(Inputs!$C$4,{"CIE 1931 2deg","CIE 1964 10deg","CIE 2015 2deg","Pasted below"},0),Tables!$C$5:$C$85,Tables!$F$5:$F$85,Tables!$I$5:$I$85,Inputs!$D$9:$D$89),9)+$C$15*INDEX(CHOOSE(MATCH(Inputs!$C$4,{"CIE 1931 2deg","CIE 1964 10deg","CIE 2015 2deg","Pasted below"},0),Tables!$D$5:$D$85,Tables!$G$5:$G$85,Tables!$J$5:$J$85,Inputs!$E$9:$E$89),9) | L13: =$A$16*INDEX(CHOOSE(MATCH(Inputs!$C$4,{"CIE 1931 2deg","CIE 1964 10deg","CIE 2015 2deg","Pasted below"},0),Tables!$B$5:$B$85,Tables!$E$5:$E$85,Tables!$H$5:$H$85,Inputs!$C$9:$C$89),9)+$B$16*INDEX(CHOOSE(MATCH(Inputs!$C$4,{"CIE 1931 2deg","CIE 1964 10deg","CIE 2015 2deg","Pasted below"},0),Tables!$C$5:$C$85,Tables!$F$5:$F$85,Tables!$I$5:$I$85,Inputs!$D$9:$D$89),9)+$C$16*INDEX(CHOOSE(MATCH(Inputs!$C$4,{"CIE 1931 2deg","CIE 1964 10deg","CIE 2015 2deg","Pasted below"},0),Tables!$D$5:$D$85,Tables!$G$5:$G$85,Tables!$J$5:$J$85,Inputs!$E$9:$E$89),9)
A14: =Destination!$B$63*Source!$B$59+Destination!$C$63*Source!$B$60+Destination!$D$63*Source!$B$61 | B14: =Destination!$B$63*Source!$C$59+Destination!$C$63*Source!$C$60+Destination!$D$63*Source!$C$61 | C14: =Destination!$B$63*Source!$D$59+Destination!$C$63*Source!$D$60+Destination!$D$63*Source!$D$61 | E14: =Source!$B$63*Destination!$B$59+Source!$C$63*Destination!$B$60+Source!$D$63*Destination!$B$61 | F14: =Source!$B$63*Destination!$C$59+Source!$C$63*Destination!$C$60+Source!$D$63*Destination!$C$61 | G14: =Source!$B$63*Destination!$D$59+Source!$C$63*Destination!$D$60+Source!$D$63*Destination!$D$61 | I14: 425 | J14: =$A$14*INDEX(CHOOSE(MATCH(Inputs!$C$4,{"CIE 1931 2deg","CIE 1964 10deg","CIE 2015 2deg","Pasted below"},0),Tables!$B$5:$B$85,Tables!$E$5:$E$85,Tables!$H$5:$H$85,Inputs!$C$9:$C$89),10)+$B$14*INDEX(CHOOSE(MATCH(Inputs!$C$4,{"CIE 1931 2deg","CIE 1964 10deg","CIE 2015 2deg","Pasted below"},0),Tables!$C$5:$C$85,Tables!$F$5:$F$85,Tables!$I$5:$I$85,Inputs!$D$9:$D$89),10)+$C$14*INDEX(CHOOSE(MATCH(Inputs!$C$4,{"CIE 1931 2deg","CIE 1964 10deg","CIE 2015 2deg","Pasted below"},0),Tables!$D$5:$D$85,Tables!$G$5:$G$85,Tables!$J$5:$J$85,Inputs!$E$9:$E$89),10) | K14: =$A$15*INDEX(CHOOSE(MATCH(Inputs!$C$4,{"CIE 1931 2deg","CIE 1964 10deg","CIE 2015 2deg","Pasted below"},0),Tables!$B$5:$B$85,Tables!$E$5:$E$85,Tables!$H$5:$H$85,Inputs!$C$9:$C$89),10)+$B$15*INDEX(CHOOSE(MATCH(Inputs!$C$4,{"CIE 1931 2deg","CIE 1964 10deg","CIE 2015 2deg","Pasted below"},0),Tables!$C$5:$C$85,Tables!$F$5:$F$85,Tables!$I$5:$I$85,Inputs!$D$9:$D$89),10)+$C$15*INDEX(CHOOSE(MATCH(Inputs!$C$4,{"CIE 1931 2deg","CIE 1964 10deg","CIE 2015 2deg","Pasted below"},0),Tables!$D$5:$D$85,Tables!$G$5:$G$85,Tables!$J$5:$J$85,Inputs!$E$9:$E$89),10) | L14: =$A$16*INDEX(CHOOSE(MATCH(Inputs!$C$4,{"CIE 1931 2deg","CIE 1964 10deg","CIE 2015 2deg","Pasted below"},0),Tables!$B$5:$B$85,Tables!$E$5:$E$85,Tables!$H$5:$H$85,Inputs!$C$9:$C$89),10)+$B$16*INDEX(CHOOSE(MATCH(Inputs!$C$4,{"CIE 1931 2deg","CIE 1964 10deg","CIE 2015 2deg","Pasted below"},0),Tables!$C$5:$C$85,Tables!$F$5:$F$85,Tables!$I$5:$I$85,Inputs!$D$9:$D$89),10)+$C$16*INDEX(CHOOSE(MATCH(Inputs!$C$4,{"CIE 1931 2deg","CIE 1964 10deg","CIE 2015 2deg","Pasted below"},0),Tables!$D$5:$D$85,Tables!$G$5:$G$85,Tables!$J$5:$J$85,Inputs!$E$9:$E$89),10)
A15: =Destination!$B$64*Source!$B$59+Destination!$C$64*Source!$B$60+Destination!$D$64*Source!$B$61 | B15: =Destination!$B$64*Source!$C$59+Destination!$C$64*Source!$C$60+Destination!$D$64*Source!$C$61 | C15: =Destination!$B$64*Source!$D$59+Destination!$C$64*Source!$D$60+Destination!$D$64*Source!$D$61 | E15: =Source!$B$64*Destination!$B$59+Source!$C$64*Destination!$B$60+Source!$D$64*Destination!$B$61 | F15: =Source!$B$64*Destination!$C$59+Source!$C$64*Destination!$C$60+Source!$D$64*Destination!$C$61 | G15: =Source!$B$64*Destination!$D$59+Source!$C$64*Destination!$D$60+Source!$D$64*Destination!$D$61 | I15: 430 | J15: =$A$14*INDEX(CHOOSE(MATCH(Inputs!$C$4,{"CIE 1931 2deg","CIE 1964 10deg","CIE 2015 2deg","Pasted below"},0),Tables!$B$5:$B$85,Tables!$E$5:$E$85,Tables!$H$5:$H$85,Inputs!$C$9:$C$89),11)+$B$14*INDEX(CHOOSE(MATCH(Inputs!$C$4,{"CIE 1931 2deg","CIE 1964 10deg","CIE 2015 2deg","Pasted below"},0),Tables!$C$5:$C$85,Tables!$F$5:$F$85,Tables!$I$5:$I$85,Inputs!$D$9:$D$89),11)+$C$14*INDEX(CHOOSE(MATCH(Inputs!$C$4,{"CIE 1931 2deg","CIE 1964 10deg","CIE 2015 2deg","Pasted below"},0),Tables!$D$5:$D$85,Tables!$G$5:$G$85,Tables!$J$5:$J$85,Inputs!$E$9:$E$89),11) | K15: =$A$15*INDEX(CHOOSE(MATCH(Inputs!$C$4,{"CIE 1931 2deg","CIE 1964 10deg","CIE 2015 2deg","Pasted below"},0),Tables!$B$5:$B$85,Tables!$E$5:$E$85,Tables!$H$5:$H$85,Inputs!$C$9:$C$89),11)+$B$15*INDEX(CHOOSE(MATCH(Inputs!$C$4,{"CIE 1931 2deg","CIE 1964 10deg","CIE 2015 2deg","Pasted below"},0),Tables!$C$5:$C$85,Tables!$F$5:$F$85,Tables!$I$5:$I$85,Inputs!$D$9:$D$89),11)+$C$15*INDEX(CHOOSE(MATCH(Inputs!$C$4,{"CIE 1931 2deg","CIE 1964 10deg","CIE 2015 2deg","Pasted below"},0),Tables!$D$5:$D$85,Tables!$G$5:$G$85,Tables!$J$5:$J$85,Inputs!$E$9:$E$89),11) | L15: =$A$16*INDEX(CHOOSE(MATCH(Inputs!$C$4,{"CIE 1931 2deg","CIE 1964 10deg","CIE 2015 2deg","Pasted below"},0),Tables!$B$5:$B$85,Tables!$E$5:$E$85,Tables!$H$5:$H$85,Inputs!$C$9:$C$89),11)+$B$16*INDEX(CHOOSE(MATCH(Inputs!$C$4,{"CIE 1931 2deg","CIE 1964 10deg","CIE 2015 2deg","Pasted below"},0),Tables!$C$5:$C$85,Tables!$F$5:$F$85,Tables!$I$5:$I$85,Inputs!$D$9:$D$89),11)+$C$16*INDEX(CHOOSE(MATCH(Inputs!$C$4,{"CIE 1931 2deg","CIE 1964 10deg","CIE 2015 2deg","Pasted below"},0),Tables!$D$5:$D$85,Tables!$G$5:$G$85,Tables!$J$5:$J$85,Inputs!$E$9:$E$89),11)
A16: =Destination!$B$65*Source!$B$59+Destination!$C$65*Source!$B$60+Destination!$D$65*Source!$B$61 | B16: =Destination!$B$65*Source!$C$59+Destination!$C$65*Source!$C$60+Destination!$D$65*Source!$C$61 | C16: =Destination!$B$65*Source!$D$59+Destination!$C$65*Source!$D$60+Destination!$D$65*Source!$D$61 | E16: =Source!$B$65*Destination!$B$59+Source!$C$65*Destination!$B$60+Source!$D$65*Destination!$B$61 | F16: =Source!$B$65*Destination!$C$59+Source!$C$65*Destination!$C$60+Source!$D$65*Destination!$C$61 | G16: =Source!$B$65*Destination!$D$59+Source!$C$65*Destination!$D$60+Source!$D$65*Destination!$D$61 | I16: 435 | J16: =$A$14*INDEX(CHOOSE(MATCH(Inputs!$C$4,{"CIE 1931 2deg","CIE 1964 10deg","CIE 2015 2deg","Pasted below"},0),Tables!$B$5:$B$85,Tables!$E$5:$E$85,Tables!$H$5:$H$85,Inputs!$C$9:$C$89),12)+$B$14*INDEX(CHOOSE(MATCH(Inputs!$C$4,{"CIE 1931 2deg","CIE 1964 10deg","CIE 2015 2deg","Pasted below"},0),Tables!$C$5:$C$85,Tables!$F$5:$F$85,Tables!$I$5:$I$85,Inputs!$D$9:$D$89),12)+$C$14*INDEX(CHOOSE(MATCH(Inputs!$C$4,{"CIE 1931 2deg","CIE 1964 10deg","CIE 2015 2deg","Pasted below"},0),Tables!$D$5:$D$85,Tables!$G$5:$G$85,Tables!$J$5:$J$85,Inputs!$E$9:$E$89),12) | K16: =$A$15*INDEX(CHOOSE(MATCH(Inputs!$C$4,{"CIE 1931 2deg","CIE 1964 10deg","CIE 2015 2deg","Pasted below"},0),Tables!$B$5:$B$85,Tables!$E$5:$E$85,Tables!$H$5:$H$85,Inputs!$C$9:$C$89),12)+$B$15*INDEX(CHOOSE(MATCH(Inputs!$C$4,{"CIE 1931 2deg","CIE 1964 10deg","CIE 2015 2deg","Pasted below"},0),Tables!$C$5:$C$85,Tables!$F$5:$F$85,Tables!$I$5:$I$85,Inputs!$D$9:$D$89),12)+$C$15*INDEX(CHOOSE(MATCH(Inputs!$C$4,{"CIE 1931 2deg","CIE 1964 10deg","CIE 2015 2deg","Pasted below"},0),Tables!$D$5:$D$85,Tables!$G$5:$G$85,Tables!$J$5:$J$85,Inputs!$E$9:$E$89),12) | L16: =$A$16*INDEX(CHOOSE(MATCH(Inputs!$C$4,{"CIE 1931 2deg","CIE 1964 10deg","CIE 2015 2deg","Pasted below"},0),Tables!$B$5:$B$85,Tables!$E$5:$E$85,Tables!$H$5:$H$85,Inputs!$C$9:$C$89),12)+$B$16*INDEX(CHOOSE(MATCH(Inputs!$C$4,{"CIE 1931 2deg","CIE 1964 10deg","CIE 2015 2deg","Pasted below"},0),Tables!$C$5:$C$85,Tables!$F$5:$F$85,Tables!$I$5:$I$85,Inputs!$D$9:$D$89),12)+$C$16*INDEX(CHOOSE(MATCH(Inputs!$C$4,{"CIE 1931 2deg","CIE 1964 10deg","CIE 2015 2deg","Pasted below"},0),Tables!$D$5:$D$85,Tables!$G$5:$G$85,Tables!$J$5:$J$85,Inputs!$E$9:$E$89),12)
I17: 440 | J17: =$A$14*INDEX(CHOOSE(MATCH(Inputs!$C$4,{"CIE 1931 2deg","CIE 1964 10deg","CIE 2015 2deg","Pasted below"},0),Tables!$B$5:$B$85,Tables!$E$5:$E$85,Tables!$H$5:$H$85,Inputs!$C$9:$C$89),13)+$B$14*INDEX(CHOOSE(MATCH(Inputs!$C$4,{"CIE 1931 2deg","CIE 1964 10deg","CIE 2015 2deg","Pasted below"},0),Tables!$C$5:$C$85,Tables!$F$5:$F$85,Tables!$I$5:$I$85,Inputs!$D$9:$D$89),13)+$C$14*INDEX(CHOOSE(MATCH(Inputs!$C$4,{"CIE 1931 2deg","CIE 1964 10deg","CIE 2015 2deg","Pasted below"},0),Tables!$D$5:$D$85,Tables!$G$5:$G$85,Tables!$J$5:$J$85,Inputs!$E$9:$E$89),13) | K17: =$A$15*INDEX(CHOOSE(MATCH(Inputs!$C$4,{"CIE 1931 2deg","CIE 1964 10deg","CIE 2015 2deg","Pasted below"},0),Tables!$B$5:$B$85,Tables!$E$5:$E$85,Tables!$H$5:$H$85,Inputs!$C$9:$C$89),13)+$B$15*INDEX(CHOOSE(MATCH(Inputs!$C$4,{"CIE 1931 2deg","CIE 1964 10deg","CIE 2015 2deg","Pasted below"},0),Tables!$C$5:$C$85,Tables!$F$5:$F$85,Tables!$I$5:$I$85,Inputs!$D$9:$D$89),13)+$C$15*INDEX(CHOOSE(MATCH(Inputs!$C$4,{"CIE 1931 2deg","CIE 1964 10deg","CIE 2015 2deg","Pasted below"},0),Tables!$D$5:$D$85,Tables!$G$5:$G$85,Tables!$J$5:$J$85,Inputs!$E$9:$E$89),13) | L17: =$A$16*INDEX(CHOOSE(MATCH(Inputs!$C$4,{"CIE 1931 2deg","CIE 1964 10deg","CIE 2015 2deg","Pasted below"},0),Tables!$B$5:$B$85,Tables!$E$5:$E$85,Tables!$H$5:$H$85,Inputs!$C$9:$C$89),13)+$B$16*INDEX(CHOOSE(MATCH(Inputs!$C$4,{"CIE 1931 2deg","CIE 1964 10deg","CIE 2015 2deg","Pasted below"},0),Tables!$C$5:$C$85,Tables!$F$5:$F$85,Tables!$I$5:$I$85,Inputs!$D$9:$D$89),13)+$C$16*INDEX(CHOOSE(MATCH(Inputs!$C$4,{"CIE 1931 2deg","CIE 1964 10deg","CIE 2015 2deg","Pasted below"},0),Tables!$D$5:$D$85,Tables!$G$5:$G$85,Tables!$J$5:$J$85,Inputs!$E$9:$E$89),13)
A18: XYZ converter: source XYZ in, destination XYZ out | I18: 445 | J18: =$A$14*INDEX(CHOOSE(MATCH(Inputs!$C$4,{"CIE 1931 2deg","CIE 1964 10deg","CIE 2015 2deg","Pasted below"},0),Tables!$B$5:$B$85,Tables!$E$5:$E$85,Tables!$H$5:$H$85,Inputs!$C$9:$C$89),14)+$B$14*INDEX(CHOOSE(MATCH(Inputs!$C$4,{"CIE 1931 2deg","CIE 1964 10deg","CIE 2015 2deg","Pasted below"},0),Tables!$C$5:$C$85,Tables!$F$5:$F$85,Tables!$I$5:$I$85,Inputs!$D$9:$D$89),14)+$C$14*INDEX(CHOOSE(MATCH(Inputs!$C$4,{"CIE 1931 2deg","CIE 1964 10deg","CIE 2015 2deg","Pasted below"},0),Tables!$D$5:$D$85,Tables!$G$5:$G$85,Tables!$J$5:$J$85,Inputs!$E$9:$E$89),14) | K18: =$A$15*INDEX(CHOOSE(MATCH(Inputs!$C$4,{"CIE 1931 2deg","CIE 1964 10deg","CIE 2015 2deg","Pasted below"},0),Tables!$B$5:$B$85,Tables!$E$5:$E$85,Tables!$H$5:$H$85,Inputs!$C$9:$C$89),14)+$B$15*INDEX(CHOOSE(MATCH(Inputs!$C$4,{"CIE 1931 2deg","CIE 1964 10deg","CIE 2015 2deg","Pasted below"},0),Tables!$C$5:$C$85,Tables!$F$5:$F$85,Tables!$I$5:$I$85,Inputs!$D$9:$D$89),14)+$C$15*INDEX(CHOOSE(MATCH(Inputs!$C$4,{"CIE 1931 2deg","CIE 1964 10deg","CIE 2015 2deg","Pasted below"},0),Tables!$D$5:$D$85,Tables!$G$5:$G$85,Tables!$J$5:$J$85,Inputs!$E$9:$E$89),14) | L18: =$A$16*INDEX(CHOOSE(MATCH(Inputs!$C$4,{"CIE 1931 2deg","CIE 1964 10deg","CIE 2015 2deg","Pasted below"},0),Tables!$B$5:$B$85,Tables!$E$5:$E$85,Tables!$H$5:$H$85,Inputs!$C$9:$C$89),14)+$B$16*INDEX(CHOOSE(MATCH(Inputs!$C$4,{"CIE 1931 2deg","CIE 1964 10deg","CIE 2015 2deg","Pasted below"},0),Tables!$C$5:$C$85,Tables!$F$5:$F$85,Tables!$I$5:$I$85,Inputs!$D$9:$D$89),14)+$C$16*INDEX(CHOOSE(MATCH(Inputs!$C$4,{"CIE 1931 2deg","CIE 1964 10deg","CIE 2015 2deg","Pasted below"},0),Tables!$D$5:$D$85,Tables!$G$5:$G$85,Tables!$J$5:$J$85,Inputs!$E$9:$E$89),14)
A19: X | B19: Y | C19: Z | E19: X dest | F19: Y dest | G19: Z dest | I19: 450 | J19: =$A$14*INDEX(CHOOSE(MATCH(Inputs!$C$4,{"CIE 1931 2deg","CIE 1964 10deg","CIE 2015 2deg","Pasted below"},0),Tables!$B$5:$B$85,Tables!$E$5:$E$85,Tables!$H$5:$H$85,Inputs!$C$9:$C$89),15)+$B$14*INDEX(CHOOSE(MATCH(Inputs!$C$4,{"CIE 1931 2deg","CIE 1964 10deg","CIE 2015 2deg","Pasted below"},0),Tables!$C$5:$C$85,Tables!$F$5:$F$85,Tables!$I$5:$I$85,Inputs!$D$9:$D$89),15)+$C$14*INDEX(CHOOSE(MATCH(Inputs!$C$4,{"CIE 1931 2deg","CIE 1964 10deg","CIE 2015 2deg","Pasted below"},0),Tables!$D$5:$D$85,Tables!$G$5:$G$85,Tables!$J$5:$J$85,Inputs!$E$9:$E$89),15) | K19: =$A$15*INDEX(CHOOSE(MATCH(Inputs!$C$4,{"CIE 1931 2deg","CIE 1964 10deg","CIE 2015 2deg","Pasted below"},0),Tables!$B$5:$B$85,Tables!$E$5:$E$85,Tables!$H$5:$H$85,Inputs!$C$9:$C$89),15)+$B$15*INDEX(CHOOSE(MATCH(Inputs!$C$4,{"CIE 1931 2deg","CIE 1964 10deg","CIE 2015 2deg","Pasted below"},0),Tables!$C$5:$C$85,Tables!$F$5:$F$85,Tables!$I$5:$I$85,Inputs!$D$9:$D$89),15)+$C$15*INDEX(CHOOSE(MATCH(Inputs!$C$4,{"CIE 1931 2deg","CIE 1964 10deg","CIE 2015 2deg","Pasted below"},0),Tables!$D$5:$D$85,Tables!$G$5:$G$85,Tables!$J$5:$J$85,Inputs!$E$9:$E$89),15) | L19: =$A$16*INDEX(CHOOSE(MATCH(Inputs!$C$4,{"CIE 1931 2deg","CIE 1964 10deg","CIE 2015 2deg","Pasted below"},0),Tables!$B$5:$B$85,Tables!$E$5:$E$85,Tables!$H$5:$H$85,Inputs!$C$9:$C$89),15)+$B$16*INDEX(CHOOSE(MATCH(Inputs!$C$4,{"CIE 1931 2deg","CIE 1964 10deg","CIE 2015 2deg","Pasted below"},0),Tables!$C$5:$C$85,Tables!$F$5:$F$85,Tables!$I$5:$I$85,Inputs!$D$9:$D$89),15)+$C$16*INDEX(CHOOSE(MATCH(Inputs!$C$4,{"CIE 1931 2deg","CIE 1964 10deg","CIE 2015 2deg","Pasted below"},0),Tables!$D$5:$D$85,Tables!$G$5:$G$85,Tables!$J$5:$J$85,Inputs!$E$9:$E$89),15)
E20: =IF($A20="","",$A$14*A20+$B$14*B20+$C$14*C20) | F20: =IF($A20="","",$A$15*A20+$B$15*B20+$C$15*C20) | G20: =IF($A20="","",$A$16*A20+$B$16*B20+$C$16*C20) | I20: 455 | J20: =$A$14*INDEX(CHOOSE(MATCH(Inputs!$C$4,{"CIE 1931 2deg","CIE 1964 10deg","CIE 2015 2deg","Pasted below"},0),Tables!$B$5:$B$85,Tables!$E$5:$E$85,Tables!$H$5:$H$85,Inputs!$C$9:$C$89),16)+$B$14*INDEX(CHOOSE(MATCH(Inputs!$C$4,{"CIE 1931 2deg","CIE 1964 10deg","CIE 2015 2deg","Pasted below"},0),Tables!$C$5:$C$85,Tables!$F$5:$F$85,Tables!$I$5:$I$85,Inputs!$D$9:$D$89),16)+$C$14*INDEX(CHOOSE(MATCH(Inputs!$C$4,{"CIE 1931 2deg","CIE 1964 10deg","CIE 2015 2deg","Pasted below"},0),Tables!$D$5:$D$85,Tables!$G$5:$G$85,Tables!$J$5:$J$85,Inputs!$E$9:$E$89),16) | K20: =$A$15*INDEX(CHOOSE(MATCH(Inputs!$C$4,{"CIE 1931 2deg","CIE 1964 10deg","CIE 2015 2deg","Pasted below"},0),Tables!$B$5:$B$85,Tables!$E$5:$E$85,Tables!$H$5:$H$85,Inputs!$C$9:$C$89),16)+$B$15*INDEX(CHOOSE(MATCH(Inputs!$C$4,{"CIE 1931 2deg","CIE 1964 10deg","CIE 2015 2deg","Pasted below"},0),Tables!$C$5:$C$85,Tables!$F$5:$F$85,Tables!$I$5:$I$85,Inputs!$D$9:$D$89),16)+$C$15*INDEX(CHOOSE(MATCH(Inputs!$C$4,{"CIE 1931 2deg","CIE 1964 10deg","CIE 2015 2deg","Pasted below"},0),Tables!$D$5:$D$85,Tables!$G$5:$G$85,Tables!$J$5:$J$85,Inputs!$E$9:$E$89),16) | L20: =$A$16*INDEX(CHOOSE(MATCH(Inputs!$C$4,{"CIE 1931 2deg","CIE 1964 10deg","CIE 2015 2deg","Pasted below"},0),Tables!$B$5:$B$85,Tables!$E$5:$E$85,Tables!$H$5:$H$85,Inputs!$C$9:$C$89),16)+$B$16*INDEX(CHOOSE(MATCH(Inputs!$C$4,{"CIE 1931 2deg","CIE 1964 10deg","CIE 2015 2deg","Pasted below"},0),Tables!$C$5:$C$85,Tables!$F$5:$F$85,Tables!$I$5:$I$85,Inputs!$D$9:$D$89),16)+$C$16*INDEX(CHOOSE(MATCH(Inputs!$C$4,{"CIE 1931 2deg","CIE 1964 10deg","CIE 2015 2deg","Pasted below"},0),Tables!$D$5:$D$85,Tables!$G$5:$G$85,Tables!$J$5:$J$85,Inputs!$E$9:$E$89),16)
E21: =IF($A21="","",$A$14*A21+$B$14*B21+$C$14*C21) | F21: =IF($A21="","",$A$15*A21+$B$15*B21+$C$15*C21) | G21: =IF($A21="","",$A$16*A21+$B$16*B21+$C$16*C21) | I21: 460 | J21: =$A$14*INDEX(CHOOSE(MATCH(Inputs!$C$4,{"CIE 1931 2deg","CIE 1964 10deg","CIE 2015 2deg","Pasted below"},0),Tables!$B$5:$B$85,Tables!$E$5:$E$85,Tables!$H$5:$H$85,Inputs!$C$9:$C$89),17)+$B$14*INDEX(CHOOSE(MATCH(Inputs!$C$4,{"CIE 1931 2deg","CIE 1964 10deg","CIE 2015 2deg","Pasted below"},0),Tables!$C$5:$C$85,Tables!$F$5:$F$85,Tables!$I$5:$I$85,Inputs!$D$9:$D$89),17)+$C$14*INDEX(CHOOSE(MATCH(Inputs!$C$4,{"CIE 1931 2deg","CIE 1964 10deg","CIE 2015 2deg","Pasted below"},0),Tables!$D$5:$D$85,Tables!$G$5:$G$85,Tables!$J$5:$J$85,Inputs!$E$9:$E$89),17) | K21: =$A$15*INDEX(CHOOSE(MATCH(Inputs!$C$4,{"CIE 1931 2deg","CIE 1964 10deg","CIE 2015 2deg","Pasted below"},0),Tables!$B$5:$B$85,Tables!$E$5:$E$85,Tables!$H$5:$H$85,Inputs!$C$9:$C$89),17)+$B$15*INDEX(CHOOSE(MATCH(Inputs!$C$4,{"CIE 1931 2deg","CIE 1964 10deg","CIE 2015 2deg","Pasted below"},0),Tables!$C$5:$C$85,Tables!$F$5:$F$85,Tables!$I$5:$I$85,Inputs!$D$9:$D$89),17)+$C$15*INDEX(CHOOSE(MATCH(Inputs!$C$4,{"CIE 1931 2deg","CIE 1964 10deg","CIE 2015 2deg","Pasted below"},0),Tables!$D$5:$D$85,Tables!$G$5:$G$85,Tables!$J$5:$J$85,Inputs!$E$9:$E$89),17) | L21: =$A$16*INDEX(CHOOSE(MATCH(Inputs!$C$4,{"CIE 1931 2deg","CIE 1964 10deg","CIE 2015 2deg","Pasted below"},0),Tables!$B$5:$B$85,Tables!$E$5:$E$85,Tables!$H$5:$H$85,Inputs!$C$9:$C$89),17)+$B$16*INDEX(CHOOSE(MATCH(Inputs!$C$4,{"CIE 1931 2deg","CIE 1964 10deg","CIE 2015 2deg","Pasted below"},0),Tables!$C$5:$C$85,Tables!$F$5:$F$85,Tables!$I$5:$I$85,Inputs!$D$9:$D$89),17)+$C$16*INDEX(CHOOSE(MATCH(Inputs!$C$4,{"CIE 1931 2deg","CIE 1964 10deg","CIE 2015 2deg","Pasted below"},0),Tables!$D$5:$D$85,Tables!$G$5:$G$85,Tables!$J$5:$J$85,Inputs!$E$9:$E$89),17)
E22: =IF($A22="","",$A$14*A22+$B$14*B22+$C$14*C22) | F22: =IF($A22="","",$A$15*A22+$B$15*B22+$C$15*C22) | G22: =IF($A22="","",$A$16*A22+$B$16*B22+$C$16*C22) | I22: 465 | J22: =$A$14*INDEX(CHOOSE(MATCH(Inputs!$C$4,{"CIE 1931 2deg","CIE 1964 10deg","CIE 2015 2deg","Pasted below"},0),Tables!$B$5:$B$85,Tables!$E$5:$E$85,Tables!$H$5:$H$85,Inputs!$C$9:$C$89),18)+$B$14*INDEX(CHOOSE(MATCH(Inputs!$C$4,{"CIE 1931 2deg","CIE 1964 10deg","CIE 2015 2deg","Pasted below"},0),Tables!$C$5:$C$85,Tables!$F$5:$F$85,Tables!$I$5:$I$85,Inputs!$D$9:$D$89),18)+$C$14*INDEX(CHOOSE(MATCH(Inputs!$C$4,{"CIE 1931 2deg","CIE 1964 10deg","CIE 2015 2deg","Pasted below"},0),Tables!$D$5:$D$85,Tables!$G$5:$G$85,Tables!$J$5:$J$85,Inputs!$E$9:$E$89),18) | K22: =$A$15*INDEX(CHOOSE(MATCH(Inputs!$C$4,{"CIE 1931 2deg","CIE 1964 10deg","CIE 2015 2deg","Pasted below"},0),Tables!$B$5:$B$85,Tables!$E$5:$E$85,Tables!$H$5:$H$85,Inputs!$C$9:$C$89),18)+$B$15*INDEX(CHOOSE(MATCH(Inputs!$C$4,{"CIE 1931 2deg","CIE 1964 10deg","CIE 2015 2deg","Pasted below"},0),Tables!$C$5:$C$85,Tables!$F$5:$F$85,Tables!$I$5:$I$85,Inputs!$D$9:$D$89),18)+$C$15*INDEX(CHOOSE(MATCH(Inputs!$C$4,{"CIE 1931 2deg","CIE 1964 10deg","CIE 2015 2deg","Pasted below"},0),Tables!$D$5:$D$85,Tables!$G$5:$G$85,Tables!$J$5:$J$85,Inputs!$E$9:$E$89),18) | L22: =$A$16*INDEX(CHOOSE(MATCH(Inputs!$C$4,{"CIE 1931 2deg","CIE 1964 10deg","CIE 2015 2deg","Pasted below"},0),Tables!$B$5:$B$85,Tables!$E$5:$E$85,Tables!$H$5:$H$85,Inputs!$C$9:$C$89),18)+$B$16*INDEX(CHOOSE(MATCH(Inputs!$C$4,{"CIE 1931 2deg","CIE 1964 10deg","CIE 2015 2deg","Pasted below"},0),Tables!$C$5:$C$85,Tables!$F$5:$F$85,Tables!$I$5:$I$85,Inputs!$D$9:$D$89),18)+$C$16*INDEX(CHOOSE(MATCH(Inputs!$C$4,{"CIE 1931 2deg","CIE 1964 10deg","CIE 2015 2deg","Pasted below"},0),Tables!$D$5:$D$85,Tables!$G$5:$G$85,Tables!$J$5:$J$85,Inputs!$E$9:$E$89),18)
E23: =IF($A23="","",$A$14*A23+$B$14*B23+$C$14*C23) | F23: =IF($A23="","",$A$15*A23+$B$15*B23+$C$15*C23) | G23: =IF($A23="","",$A$16*A23+$B$16*B23+$C$16*C23) | I23: 470 | J23: =$A$14*INDEX(CHOOSE(MATCH(Inputs!$C$4,{"CIE 1931 2deg","CIE 1964 10deg","CIE 2015 2deg","Pasted below"},0),Tables!$B$5:$B$85,Tables!$E$5:$E$85,Tables!$H$5:$H$85,Inputs!$C$9:$C$89),19)+$B$14*INDEX(CHOOSE(MATCH(Inputs!$C$4,{"CIE 1931 2deg","CIE 1964 10deg","CIE 2015 2deg","Pasted below"},0),Tables!$C$5:$C$85,Tables!$F$5:$F$85,Tables!$I$5:$I$85,Inputs!$D$9:$D$89),19)+$C$14*INDEX(CHOOSE(MATCH(Inputs!$C$4,{"CIE 1931 2deg","CIE 1964 10deg","CIE 2015 2deg","Pasted below"},0),Tables!$D$5:$D$85,Tables!$G$5:$G$85,Tables!$J$5:$J$85,Inputs!$E$9:$E$89),19) | K23: =$A$15*INDEX(CHOOSE(MATCH(Inputs!$C$4,{"CIE 1931 2deg","CIE 1964 10deg","CIE 2015 2deg","Pasted below"},0),Tables!$B$5:$B$85,Tables!$E$5:$E$85,Tables!$H$5:$H$85,Inputs!$C$9:$C$89),19)+$B$15*INDEX(CHOOSE(MATCH(Inputs!$C$4,{"CIE 1931 2deg","CIE 1964 10deg","CIE 2015 2deg","Pasted below"},0),Tables!$C$5:$C$85,Tables!$F$5:$F$85,Tables!$I$5:$I$85,Inputs!$D$9:$D$89),19)+$C$15*INDEX(CHOOSE(MATCH(Inputs!$C$4,{"CIE 1931 2deg","CIE 1964 10deg","CIE 2015 2deg","Pasted below"},0),Tables!$D$5:$D$85,Tables!$G$5:$G$85,Tables!$J$5:$J$85,Inputs!$E$9:$E$89),19) | L23: =$A$16*INDEX(CHOOSE(MATCH(Inputs!$C$4,{"CIE 1931 2deg","CIE 1964 10deg","CIE 2015 2deg","Pasted below"},0),Tables!$B$5:$B$85,Tables!$E$5:$E$85,Tables!$H$5:$H$85,Inputs!$C$9:$C$89),19)+$B$16*INDEX(CHOOSE(MATCH(Inputs!$C$4,{"CIE 1931 2deg","CIE 1964 10deg","CIE 2015 2deg","Pasted below"},0),Tables!$C$5:$C$85,Tables!$F$5:$F$85,Tables!$I$5:$I$85,Inputs!$D$9:$D$89),19)+$C$16*INDEX(CHOOSE(MATCH(Inputs!$C$4,{"CIE 1931 2deg","CIE 1964 10deg","CIE 2015 2deg","Pasted below"},0),Tables!$D$5:$D$85,Tables!$G$5:$G$85,Tables!$J$5:$J$85,Inputs!$E$9:$E$89),19)
E24: =IF($A24="","",$A$14*A24+$B$14*B24+$C$14*C24) | F24: =IF($A24="","",$A$15*A24+$B$15*B24+$C$15*C24) | G24: =IF($A24="","",$A$16*A24+$B$16*B24+$C$16*C24) | I24: 475 | J24: =$A$14*INDEX(CHOOSE(MATCH(Inputs!$C$4,{"CIE 1931 2deg","CIE 1964 10deg","CIE 2015 2deg","Pasted below"},0),Tables!$B$5:$B$85,Tables!$E$5:$E$85,Tables!$H$5:$H$85,Inputs!$C$9:$C$89),20)+$B$14*INDEX(CHOOSE(MATCH(Inputs!$C$4,{"CIE 1931 2deg","CIE 1964 10deg","CIE 2015 2deg","Pasted below"},0),Tables!$C$5:$C$85,Tables!$F$5:$F$85,Tables!$I$5:$I$85,Inputs!$D$9:$D$89),20)+$C$14*INDEX(CHOOSE(MATCH(Inputs!$C$4,{"CIE 1931 2deg","CIE 1964 10deg","CIE 2015 2deg","Pasted below"},0),Tables!$D$5:$D$85,Tables!$G$5:$G$85,Tables!$J$5:$J$85,Inputs!$E$9:$E$89),20) | K24: =$A$15*INDEX(CHOOSE(MATCH(Inputs!$C$4,{"CIE 1931 2deg","CIE 1964 10deg","CIE 2015 2deg","Pasted below"},0),Tables!$B$5:$B$85,Tables!$E$5:$E$85,Tables!$H$5:$H$85,Inputs!$C$9:$C$89),20)+$B$15*INDEX(CHOOSE(MATCH(Inputs!$C$4,{"CIE 1931 2deg","CIE 1964 10deg","CIE 2015 2deg","Pasted below"},0),Tables!$C$5:$C$85,Tables!$F$5:$F$85,Tables!$I$5:$I$85,Inputs!$D$9:$D$89),20)+$C$15*INDEX(CHOOSE(MATCH(Inputs!$C$4,{"CIE 1931 2deg","CIE 1964 10deg","CIE 2015 2deg","Pasted below"},0),Tables!$D$5:$D$85,Tables!$G$5:$G$85,Tables!$J$5:$J$85,Inputs!$E$9:$E$89),20) | L24: =$A$16*INDEX(CHOOSE(MATCH(Inputs!$C$4,{"CIE 1931 2deg","CIE 1964 10deg","CIE 2015 2deg","Pasted below"},0),Tables!$B$5:$B$85,Tables!$E$5:$E$85,Tables!$H$5:$H$85,Inputs!$C$9:$C$89),20)+$B$16*INDEX(CHOOSE(MATCH(Inputs!$C$4,{"CIE 1931 2deg","CIE 1964 10deg","CIE 2015 2deg","Pasted below"},0),Tables!$C$5:$C$85,Tables!$F$5:$F$85,Tables!$I$5:$I$85,Inputs!$D$9:$D$89),20)+$C$16*INDEX(CHOOSE(MATCH(Inputs!$C$4,{"CIE 1931 2deg","CIE 1964 10deg","CIE 2015 2deg","Pasted below"},0),Tables!$D$5:$D$85,Tables!$G$5:$G$85,Tables!$J$5:$J$85,Inputs!$E$9:$E$89),20)
E25: =IF($A25="","",$A$14*A25+$B$14*B25+$C$14*C25) | F25: =IF($A25="","",$A$15*A25+$B$15*B25+$C$15*C25) | G25: =IF($A25="","",$A$16*A25+$B$16*B25+$C$16*C25) | I25: 480 | J25: =$A$14*INDEX(CHOOSE(MATCH(Inputs!$C$4,{"CIE 1931 2deg","CIE 1964 10deg","CIE 2015 2deg","Pasted below"},0),Tables!$B$5:$B$85,Tables!$E$5:$E$85,Tables!$H$5:$H$85,Inputs!$C$9:$C$89),21)+$B$14*INDEX(CHOOSE(MATCH(Inputs!$C$4,{"CIE 1931 2deg","CIE 1964 10deg","CIE 2015 2deg","Pasted below"},0),Tables!$C$5:$C$85,Tables!$F$5:$F$85,Tables!$I$5:$I$85,Inputs!$D$9:$D$89),21)+$C$14*INDEX(CHOOSE(MATCH(Inputs!$C$4,{"CIE 1931 2deg","CIE 1964 10deg","CIE 2015 2deg","Pasted below"},0),Tables!$D$5:$D$85,Tables!$G$5:$G$85,Tables!$J$5:$J$85,Inputs!$E$9:$E$89),21) | K25: =$A$15*INDEX(CHOOSE(MATCH(Inputs!$C$4,{"CIE 1931 2deg","CIE 1964 10deg","CIE 2015 2deg","Pasted below"},0),Tables!$B$5:$B$85,Tables!$E$5:$E$85,Tables!$H$5:$H$85,Inputs!$C$9:$C$89),21)+$B$15*INDEX(CHOOSE(MATCH(Inputs!$C$4,{"CIE 1931 2deg","CIE 1964 10deg","CIE 2015 2deg","Pasted below"},0),Tables!$C$5:$C$85,Tables!$F$5:$F$85,Tables!$I$5:$I$85,Inputs!$D$9:$D$89),21)+$C$15*INDEX(CHOOSE(MATCH(Inputs!$C$4,{"CIE 1931 2deg","CIE 1964 10deg","CIE 2015 2deg","Pasted below"},0),Tables!$D$5:$D$85,Tables!$G$5:$G$85,Tables!$J$5:$J$85,Inputs!$E$9:$E$89),21) | L25: =$A$16*INDEX(CHOOSE(MATCH(Inputs!$C$4,{"CIE 1931 2deg","CIE 1964 10deg","CIE 2015 2deg","Pasted below"},0),Tables!$B$5:$B$85,Tables!$E$5:$E$85,Tables!$H$5:$H$85,Inputs!$C$9:$C$89),21)+$B$16*INDEX(CHOOSE(MATCH(Inputs!$C$4,{"CIE 1931 2deg","CIE 1964 10deg","CIE 2015 2deg","Pasted below"},0),Tables!$C$5:$C$85,Tables!$F$5:$F$85,Tables!$I$5:$I$85,Inputs!$D$9:$D$89),21)+$C$16*INDEX(CHOOSE(MATCH(Inputs!$C$4,{"CIE 1931 2deg","CIE 1964 10deg","CIE 2015 2deg","Pasted below"},0),Tables!$D$5:$D$85,Tables!$G$5:$G$85,Tables!$J$5:$J$85,Inputs!$E$9:$E$89),21)
E26: =IF($A26="","",$A$14*A26+$B$14*B26+$C$14*C26) | F26: =IF($A26="","",$A$15*A26+$B$15*B26+$C$15*C26) | G26: =IF($A26="","",$A$16*A26+$B$16*B26+$C$16*C26) | I26: 485 | J26: =$A$14*INDEX(CHOOSE(MATCH(Inputs!$C$4,{"CIE 1931 2deg","CIE 1964 10deg","CIE 2015 2deg","Pasted below"},0),Tables!$B$5:$B$85,Tables!$E$5:$E$85,Tables!$H$5:$H$85,Inputs!$C$9:$C$89),22)+$B$14*INDEX(CHOOSE(MATCH(Inputs!$C$4,{"CIE 1931 2deg","CIE 1964 10deg","CIE 2015 2deg","Pasted below"},0),Tables!$C$5:$C$85,Tables!$F$5:$F$85,Tables!$I$5:$I$85,Inputs!$D$9:$D$89),22)+$C$14*INDEX(CHOOSE(MATCH(Inputs!$C$4,{"CIE 1931 2deg","CIE 1964 10deg","CIE 2015 2deg","Pasted below"},0),Tables!$D$5:$D$85,Tables!$G$5:$G$85,Tables!$J$5:$J$85,Inputs!$E$9:$E$89),22) | K26: =$A$15*INDEX(CHOOSE(MATCH(Inputs!$C$4,{"CIE 1931 2deg","CIE 1964 10deg","CIE 2015 2deg","Pasted below"},0),Tables!$B$5:$B$85,Tables!$E$5:$E$85,Tables!$H$5:$H$85,Inputs!$C$9:$C$89),22)+$B$15*INDEX(CHOOSE(MATCH(Inputs!$C$4,{"CIE 1931 2deg","CIE 1964 10deg","CIE 2015 2deg","Pasted below"},0),Tables!$C$5:$C$85,Tables!$F$5:$F$85,Tables!$I$5:$I$85,Inputs!$D$9:$D$89),22)+$C$15*INDEX(CHOOSE(MATCH(Inputs!$C$4,{"CIE 1931 2deg","CIE 1964 10deg","CIE 2015 2deg","Pasted below"},0),Tables!$D$5:$D$85,Tables!$G$5:$G$85,Tables!$J$5:$J$85,Inputs!$E$9:$E$89),22) | L26: =$A$16*INDEX(CHOOSE(MATCH(Inputs!$C$4,{"CIE 1931 2deg","CIE 1964 10deg","CIE 2015 2deg","Pasted below"},0),Tables!$B$5:$B$85,Tables!$E$5:$E$85,Tables!$H$5:$H$85,Inputs!$C$9:$C$89),22)+$B$16*INDEX(CHOOSE(MATCH(Inputs!$C$4,{"CIE 1931 2deg","CIE 1964 10deg","CIE 2015 2deg","Pasted below"},0),Tables!$C$5:$C$85,Tables!$F$5:$F$85,Tables!$I$5:$I$85,Inputs!$D$9:$D$89),22)+$C$16*INDEX(CHOOSE(MATCH(Inputs!$C$4,{"CIE 1931 2deg","CIE 1964 10deg","CIE 2015 2deg","Pasted below"},0),Tables!$D$5:$D$85,Tables!$G$5:$G$85,Tables!$J$5:$J$85,Inputs!$E$9:$E$89),22)
E27: =IF($A27="","",$A$14*A27+$B$14*B27+$C$14*C27) | F27: =IF($A27="","",$A$15*A27+$B$15*B27+$C$15*C27) | G27: =IF($A27="","",$A$16*A27+$B$16*B27+$C$16*C27) | I27: 490 | J27: =$A$14*INDEX(CHOOSE(MATCH(Inputs!$C$4,{"CIE 1931 2deg","CIE 1964 10deg","CIE 2015 2deg","Pasted below"},0),Tables!$B$5:$B$85,Tables!$E$5:$E$85,Tables!$H$5:$H$85,Inputs!$C$9:$C$89),23)+$B$14*INDEX(CHOOSE(MATCH(Inputs!$C$4,{"CIE 1931 2deg","CIE 1964 10deg","CIE 2015 2deg","Pasted below"},0),Tables!$C$5:$C$85,Tables!$F$5:$F$85,Tables!$I$5:$I$85,Inputs!$D$9:$D$89),23)+$C$14*INDEX(CHOOSE(MATCH(Inputs!$C$4,{"CIE 1931 2deg","CIE 1964 10deg","CIE 2015 2deg","Pasted below"},0),Tables!$D$5:$D$85,Tables!$G$5:$G$85,Tables!$J$5:$J$85,Inputs!$E$9:$E$89),23) | K27: =$A$15*INDEX(CHOOSE(MATCH(Inputs!$C$4,{"CIE 1931 2deg","CIE 1964 10deg","CIE 2015 2deg","Pasted below"},0),Tables!$B$5:$B$85,Tables!$E$5:$E$85,Tables!$H$5:$H$85,Inputs!$C$9:$C$89),23)+$B$15*INDEX(CHOOSE(MATCH(Inputs!$C$4,{"CIE 1931 2deg","CIE 1964 10deg","CIE 2015 2deg","Pasted below"},0),Tables!$C$5:$C$85,Tables!$F$5:$F$85,Tables!$I$5:$I$85,Inputs!$D$9:$D$89),23)+$C$15*INDEX(CHOOSE(MATCH(Inputs!$C$4,{"CIE 1931 2deg","CIE 1964 10deg","CIE 2015 2deg","Pasted below"},0),Tables!$D$5:$D$85,Tables!$G$5:$G$85,Tables!$J$5:$J$85,Inputs!$E$9:$E$89),23) | L27: =$A$16*INDEX(CHOOSE(MATCH(Inputs!$C$4,{"CIE 1931 2deg","CIE 1964 10deg","CIE 2015 2deg","Pasted below"},0),Tables!$B$5:$B$85,Tables!$E$5:$E$85,Tables!$H$5:$H$85,Inputs!$C$9:$C$89),23)+$B$16*INDEX(CHOOSE(MATCH(Inputs!$C$4,{"CIE 1931 2deg","CIE 1964 10deg","CIE 2015 2deg","Pasted below"},0),Tables!$C$5:$C$85,Tables!$F$5:$F$85,Tables!$I$5:$I$85,Inputs!$D$9:$D$89),23)+$C$16*INDEX(CHOOSE(MATCH(Inputs!$C$4,{"CIE 1931 2deg","CIE 1964 10deg","CIE 2015 2deg","Pasted below"},0),Tables!$D$5:$D$85,Tables!$G$5:$G$85,Tables!$J$5:$J$85,Inputs!$E$9:$E$89),23)
E28: =IF($A28="","",$A$14*A28+$B$14*B28+$C$14*C28) | F28: =IF($A28="","",$A$15*A28+$B$15*B28+$C$15*C28) | G28: =IF($A28="","",$A$16*A28+$B$16*B28+$C$16*C28) | I28: 495 | J28: =$A$14*INDEX(CHOOSE(MATCH(Inputs!$C$4,{"CIE 1931 2deg","CIE 1964 10deg","CIE 2015 2deg","Pasted below"},0),Tables!$B$5:$B$85,Tables!$E$5:$E$85,Tables!$H$5:$H$85,Inputs!$C$9:$C$89),24)+$B$14*INDEX(CHOOSE(MATCH(Inputs!$C$4,{"CIE 1931 2deg","CIE 1964 10deg","CIE 2015 2deg","Pasted below"},0),Tables!$C$5:$C$85,Tables!$F$5:$F$85,Tables!$I$5:$I$85,Inputs!$D$9:$D$89),24)+$C$14*INDEX(CHOOSE(MATCH(Inputs!$C$4,{"CIE 1931 2deg","CIE 1964 10deg","CIE 2015 2deg","Pasted below"},0),Tables!$D$5:$D$85,Tables!$G$5:$G$85,Tables!$J$5:$J$85,Inputs!$E$9:$E$89),24) | K28: =$A$15*INDEX(CHOOSE(MATCH(Inputs!$C$4,{"CIE 1931 2deg","CIE 1964 10deg","CIE 2015 2deg","Pasted below"},0),Tables!$B$5:$B$85,Tables!$E$5:$E$85,Tables!$H$5:$H$85,Inputs!$C$9:$C$89),24)+$B$15*INDEX(CHOOSE(MATCH(Inputs!$C$4,{"CIE 1931 2deg","CIE 1964 10deg","CIE 2015 2deg","Pasted below"},0),Tables!$C$5:$C$85,Tables!$F$5:$F$85,Tables!$I$5:$I$85,Inputs!$D$9:$D$89),24)+$C$15*INDEX(CHOOSE(MATCH(Inputs!$C$4,{"CIE 1931 2deg","CIE 1964 10deg","CIE 2015 2deg","Pasted below"},0),Tables!$D$5:$D$85,Tables!$G$5:$G$85,Tables!$J$5:$J$85,Inputs!$E$9:$E$89),24) | L28: =$A$16*INDEX(CHOOSE(MATCH(Inputs!$C$4,{"CIE 1931 2deg","CIE 1964 10deg","CIE 2015 2deg","Pasted below"},0),Tables!$B$5:$B$85,Tables!$E$5:$E$85,Tables!$H$5:$H$85,Inputs!$C$9:$C$89),24)+$B$16*INDEX(CHOOSE(MATCH(Inputs!$C$4,{"CIE 1931 2deg","CIE 1964 10deg","CIE 2015 2deg","Pasted below"},0),Tables!$C$5:$C$85,Tables!$F$5:$F$85,Tables!$I$5:$I$85,Inputs!$D$9:$D$89),24)+$C$16*INDEX(CHOOSE(MATCH(Inputs!$C$4,{"CIE 1931 2deg","CIE 1964 10deg","CIE 2015 2deg","Pasted below"},0),Tables!$D$5:$D$85,Tables!$G$5:$G$85,Tables!$J$5:$J$85,Inputs!$E$9:$E$89),24)
E29: =IF($A29="","",$A$14*A29+$B$14*B29+$C$14*C29) | F29: =IF($A29="","",$A$15*A29+$B$15*B29+$C$15*C29) | G29: =IF($A29="","",$A$16*A29+$B$16*B29+$C$16*C29) | I29: 500 | J29: =$A$14*INDEX(CHOOSE(MATCH(Inputs!$C$4,{"CIE 1931 2deg","CIE 1964 10deg","CIE 2015 2deg","Pasted below"},0),Tables!$B$5:$B$85,Tables!$E$5:$E$85,Tables!$H$5:$H$85,Inputs!$C$9:$C$89),25)+$B$14*INDEX(CHOOSE(MATCH(Inputs!$C$4,{"CIE 1931 2deg","CIE 1964 10deg","CIE 2015 2deg","Pasted below"},0),Tables!$C$5:$C$85,Tables!$F$5:$F$85,Tables!$I$5:$I$85,Inputs!$D$9:$D$89),25)+$C$14*INDEX(CHOOSE(MATCH(Inputs!$C$4,{"CIE 1931 2deg","CIE 1964 10deg","CIE 2015 2deg","Pasted below"},0),Tables!$D$5:$D$85,Tables!$G$5:$G$85,Tables!$J$5:$J$85,Inputs!$E$9:$E$89),25) | K29: =$A$15*INDEX(CHOOSE(MATCH(Inputs!$C$4,{"CIE 1931 2deg","CIE 1964 10deg","CIE 2015 2deg","Pasted below"},0),Tables!$B$5:$B$85,Tables!$E$5:$E$85,Tables!$H$5:$H$85,Inputs!$C$9:$C$89),25)+$B$15*INDEX(CHOOSE(MATCH(Inputs!$C$4,{"CIE 1931 2deg","CIE 1964 10deg","CIE 2015 2deg","Pasted below"},0),Tables!$C$5:$C$85,Tables!$F$5:$F$85,Tables!$I$5:$I$85,Inputs!$D$9:$D$89),25)+$C$15*INDEX(CHOOSE(MATCH(Inputs!$C$4,{"CIE 1931 2deg","CIE 1964 10deg","CIE 2015 2deg","Pasted below"},0),Tables!$D$5:$D$85,Tables!$G$5:$G$85,Tables!$J$5:$J$85,Inputs!$E$9:$E$89),25) | L29: =$A$16*INDEX(CHOOSE(MATCH(Inputs!$C$4,{"CIE 1931 2deg","CIE 1964 10deg","CIE 2015 2deg","Pasted below"},0),Tables!$B$5:$B$85,Tables!$E$5:$E$85,Tables!$H$5:$H$85,Inputs!$C$9:$C$89),25)+$B$16*INDEX(CHOOSE(MATCH(Inputs!$C$4,{"CIE 1931 2deg","CIE 1964 10deg","CIE 2015 2deg","Pasted below"},0),Tables!$C$5:$C$85,Tables!$F$5:$F$85,Tables!$I$5:$I$85,Inputs!$D$9:$D$89),25)+$C$16*INDEX(CHOOSE(MATCH(Inputs!$C$4,{"CIE 1931 2deg","CIE 1964 10deg","CIE 2015 2deg","Pasted below"},0),Tables!$D$5:$D$85,Tables!$G$5:$G$85,Tables!$J$5:$J$85,Inputs!$E$9:$E$89),25)
I30: 505 | J30: =$A$14*INDEX(CHOOSE(MATCH(Inputs!$C$4,{"CIE 1931 2deg","CIE 1964 10deg","CIE 2015 2deg","Pasted below"},0),Tables!$B$5:$B$85,Tables!$E$5:$E$85,Tables!$H$5:$H$85,Inputs!$C$9:$C$89),26)+$B$14*INDEX(CHOOSE(MATCH(Inputs!$C$4,{"CIE 1931 2deg","CIE 1964 10deg","CIE 2015 2deg","Pasted below"},0),Tables!$C$5:$C$85,Tables!$F$5:$F$85,Tables!$I$5:$I$85,Inputs!$D$9:$D$89),26)+$C$14*INDEX(CHOOSE(MATCH(Inputs!$C$4,{"CIE 1931 2deg","CIE 1964 10deg","CIE 2015 2deg","Pasted below"},0),Tables!$D$5:$D$85,Tables!$G$5:$G$85,Tables!$J$5:$J$85,Inputs!$E$9:$E$89),26) | K30: =$A$15*INDEX(CHOOSE(MATCH(Inputs!$C$4,{"CIE 1931 2deg","CIE 1964 10deg","CIE 2015 2deg","Pasted below"},0),Tables!$B$5:$B$85,Tables!$E$5:$E$85,Tables!$H$5:$H$85,Inputs!$C$9:$C$89),26)+$B$15*INDEX(CHOOSE(MATCH(Inputs!$C$4,{"CIE 1931 2deg","CIE 1964 10deg","CIE 2015 2deg","Pasted below"},0),Tables!$C$5:$C$85,Tables!$F$5:$F$85,Tables!$I$5:$I$85,Inputs!$D$9:$D$89),26)+$C$15*INDEX(CHOOSE(MATCH(Inputs!$C$4,{"CIE 1931 2deg","CIE 1964 10deg","CIE 2015 2deg","Pasted below"},0),Tables!$D$5:$D$85,Tables!$G$5:$G$85,Tables!$J$5:$J$85,Inputs!$E$9:$E$89),26) | L30: =$A$16*INDEX(CHOOSE(MATCH(Inputs!$C$4,{"CIE 1931 2deg","CIE 1964 10deg","CIE 2015 2deg","Pasted below"},0),Tables!$B$5:$B$85,Tables!$E$5:$E$85,Tables!$H$5:$H$85,Inputs!$C$9:$C$89),26)+$B$16*INDEX(CHOOSE(MATCH(Inputs!$C$4,{"CIE 1931 2deg","CIE 1964 10deg","CIE 2015 2deg","Pasted below"},0),Tables!$C$5:$C$85,Tables!$F$5:$F$85,Tables!$I$5:$I$85,Inputs!$D$9:$D$89),26)+$C$16*INDEX(CHOOSE(MATCH(Inputs!$C$4,{"CIE 1931 2deg","CIE 1964 10deg","CIE 2015 2deg","Pasted below"},0),Tables!$D$5:$D$85,Tables!$G$5:$G$85,Tables!$J$5:$J$85,Inputs!$E$9:$E$89),26)
I31: 510 | J31: =$A$14*INDEX(CHOOSE(MATCH(Inputs!$C$4,{"CIE 1931 2deg","CIE 1964 10deg","CIE 2015 2deg","Pasted below"},0),Tables!$B$5:$B$85,Tables!$E$5:$E$85,Tables!$H$5:$H$85,Inputs!$C$9:$C$89),27)+$B$14*INDEX(CHOOSE(MATCH(Inputs!$C$4,{"CIE 1931 2deg","CIE 1964 10deg","CIE 2015 2deg","Pasted below"},0),Tables!$C$5:$C$85,Tables!$F$5:$F$85,Tables!$I$5:$I$85,Inputs!$D$9:$D$89),27)+$C$14*INDEX(CHOOSE(MATCH(Inputs!$C$4,{"CIE 1931 2deg","CIE 1964 10deg","CIE 2015 2deg","Pasted below"},0),Tables!$D$5:$D$85,Tables!$G$5:$G$85,Tables!$J$5:$J$85,Inputs!$E$9:$E$89),27) | K31: =$A$15*INDEX(CHOOSE(MATCH(Inputs!$C$4,{"CIE 1931 2deg","CIE 1964 10deg","CIE 2015 2deg","Pasted below"},0),Tables!$B$5:$B$85,Tables!$E$5:$E$85,Tables!$H$5:$H$85,Inputs!$C$9:$C$89),27)+$B$15*INDEX(CHOOSE(MATCH(Inputs!$C$4,{"CIE 1931 2deg","CIE 1964 10deg","CIE 2015 2deg","Pasted below"},0),Tables!$C$5:$C$85,Tables!$F$5:$F$85,Tables!$I$5:$I$85,Inputs!$D$9:$D$89),27)+$C$15*INDEX(CHOOSE(MATCH(Inputs!$C$4,{"CIE 1931 2deg","CIE 1964 10deg","CIE 2015 2deg","Pasted below"},0),Tables!$D$5:$D$85,Tables!$G$5:$G$85,Tables!$J$5:$J$85,Inputs!$E$9:$E$89),27) | L31: =$A$16*INDEX(CHOOSE(MATCH(Inputs!$C$4,{"CIE 1931 2deg","CIE 1964 10deg","CIE 2015 2deg","Pasted below"},0),Tables!$B$5:$B$85,Tables!$E$5:$E$85,Tables!$H$5:$H$85,Inputs!$C$9:$C$89),27)+$B$16*INDEX(CHOOSE(MATCH(Inputs!$C$4,{"CIE 1931 2deg","CIE 1964 10deg","CIE 2015 2deg","Pasted below"},0),Tables!$C$5:$C$85,Tables!$F$5:$F$85,Tables!$I$5:$I$85,Inputs!$D$9:$D$89),27)+$C$16*INDEX(CHOOSE(MATCH(Inputs!$C$4,{"CIE 1931 2deg","CIE 1964 10deg","CIE 2015 2deg","Pasted below"},0),Tables!$D$5:$D$85,Tables!$G$5:$G$85,Tables!$J$5:$J$85,Inputs!$E$9:$E$89),27)
I32: 515 | J32: =$A$14*INDEX(CHOOSE(MATCH(Inputs!$C$4,{"CIE 1931 2deg","CIE 1964 10deg","CIE 2015 2deg","Pasted below"},0),Tables!$B$5:$B$85,Tables!$E$5:$E$85,Tables!$H$5:$H$85,Inputs!$C$9:$C$89),28)+$B$14*INDEX(CHOOSE(MATCH(Inputs!$C$4,{"CIE 1931 2deg","CIE 1964 10deg","CIE 2015 2deg","Pasted below"},0),Tables!$C$5:$C$85,Tables!$F$5:$F$85,Tables!$I$5:$I$85,Inputs!$D$9:$D$89),28)+$C$14*INDEX(CHOOSE(MATCH(Inputs!$C$4,{"CIE 1931 2deg","CIE 1964 10deg","CIE 2015 2deg","Pasted below"},0),Tables!$D$5:$D$85,Tables!$G$5:$G$85,Tables!$J$5:$J$85,Inputs!$E$9:$E$89),28) | K32: =$A$15*INDEX(CHOOSE(MATCH(Inputs!$C$4,{"CIE 1931 2deg","CIE 1964 10deg","CIE 2015 2deg","Pasted below"},0),Tables!$B$5:$B$85,Tables!$E$5:$E$85,Tables!$H$5:$H$85,Inputs!$C$9:$C$89),28)+$B$15*INDEX(CHOOSE(MATCH(Inputs!$C$4,{"CIE 1931 2deg","CIE 1964 10deg","CIE 2015 2deg","Pasted below"},0),Tables!$C$5:$C$85,Tables!$F$5:$F$85,Tables!$I$5:$I$85,Inputs!$D$9:$D$89),28)+$C$15*INDEX(CHOOSE(MATCH(Inputs!$C$4,{"CIE 1931 2deg","CIE 1964 10deg","CIE 2015 2deg","Pasted below"},0),Tables!$D$5:$D$85,Tables!$G$5:$G$85,Tables!$J$5:$J$85,Inputs!$E$9:$E$89),28) | L32: =$A$16*INDEX(CHOOSE(MATCH(Inputs!$C$4,{"CIE 1931 2deg","CIE 1964 10deg","CIE 2015 2deg","Pasted below"},0),Tables!$B$5:$B$85,Tables!$E$5:$E$85,Tables!$H$5:$H$85,Inputs!$C$9:$C$89),28)+$B$16*INDEX(CHOOSE(MATCH(Inputs!$C$4,{"CIE 1931 2deg","CIE 1964 10deg","CIE 2015 2deg","Pasted below"},0),Tables!$C$5:$C$85,Tables!$F$5:$F$85,Tables!$I$5:$I$85,Inputs!$D$9:$D$89),28)+$C$16*INDEX(CHOOSE(MATCH(Inputs!$C$4,{"CIE 1931 2deg","CIE 1964 10deg","CIE 2015 2deg","Pasted below"},0),Tables!$D$5:$D$85,Tables!$G$5:$G$85,Tables!$J$5:$J$85,Inputs!$E$9:$E$89),28)
I33: 520 | J33: =$A$14*INDEX(CHOOSE(MATCH(Inputs!$C$4,{"CIE 1931 2deg","CIE 1964 10deg","CIE 2015 2deg","Pasted below"},0),Tables!$B$5:$B$85,Tables!$E$5:$E$85,Tables!$H$5:$H$85,Inputs!$C$9:$C$89),29)+$B$14*INDEX(CHOOSE(MATCH(Inputs!$C$4,{"CIE 1931 2deg","CIE 1964 10deg","CIE 2015 2deg","Pasted below"},0),Tables!$C$5:$C$85,Tables!$F$5:$F$85,Tables!$I$5:$I$85,Inputs!$D$9:$D$89),29)+$C$14*INDEX(CHOOSE(MATCH(Inputs!$C$4,{"CIE 1931 2deg","CIE 1964 10deg","CIE 2015 2deg","Pasted below"},0),Tables!$D$5:$D$85,Tables!$G$5:$G$85,Tables!$J$5:$J$85,Inputs!$E$9:$E$89),29) | K33: =$A$15*INDEX(CHOOSE(MATCH(Inputs!$C$4,{"CIE 1931 2deg","CIE 1964 10deg","CIE 2015 2deg","Pasted below"},0),Tables!$B$5:$B$85,Tables!$E$5:$E$85,Tables!$H$5:$H$85,Inputs!$C$9:$C$89),29)+$B$15*INDEX(CHOOSE(MATCH(Inputs!$C$4,{"CIE 1931 2deg","CIE 1964 10deg","CIE 2015 2deg","Pasted below"},0),Tables!$C$5:$C$85,Tables!$F$5:$F$85,Tables!$I$5:$I$85,Inputs!$D$9:$D$89),29)+$C$15*INDEX(CHOOSE(MATCH(Inputs!$C$4,{"CIE 1931 2deg","CIE 1964 10deg","CIE 2015 2deg","Pasted below"},0),Tables!$D$5:$D$85,Tables!$G$5:$G$85,Tables!$J$5:$J$85,Inputs!$E$9:$E$89),29) | L33: =$A$16*INDEX(CHOOSE(MATCH(Inputs!$C$4,{"CIE 1931 2deg","CIE 1964 10deg","CIE 2015 2deg","Pasted below"},0),Tables!$B$5:$B$85,Tables!$E$5:$E$85,Tables!$H$5:$H$85,Inputs!$C$9:$C$89),29)+$B$16*INDEX(CHOOSE(MATCH(Inputs!$C$4,{"CIE 1931 2deg","CIE 1964 10deg","CIE 2015 2deg","Pasted below"},0),Tables!$C$5:$C$85,Tables!$F$5:$F$85,Tables!$I$5:$I$85,Inputs!$D$9:$D$89),29)+$C$16*INDEX(CHOOSE(MATCH(Inputs!$C$4,{"CIE 1931 2deg","CIE 1964 10deg","CIE 2015 2deg","Pasted below"},0),Tables!$D$5:$D$85,Tables!$G$5:$G$85,Tables!$J$5:$J$85,Inputs!$E$9:$E$89),29)
I34: 525 | J34: =$A$14*INDEX(CHOOSE(MATCH(Inputs!$C$4,{"CIE 1931 2deg","CIE 1964 10deg","CIE 2015 2deg","Pasted below"},0),Tables!$B$5:$B$85,Tables!$E$5:$E$85,Tables!$H$5:$H$85,Inputs!$C$9:$C$89),30)+$B$14*INDEX(CHOOSE(MATCH(Inputs!$C$4,{"CIE 1931 2deg","CIE 1964 10deg","CIE 2015 2deg","Pasted below"},0),Tables!$C$5:$C$85,Tables!$F$5:$F$85,Tables!$I$5:$I$85,Inputs!$D$9:$D$89),30)+$C$14*INDEX(CHOOSE(MATCH(Inputs!$C$4,{"CIE 1931 2deg","CIE 1964 10deg","CIE 2015 2deg","Pasted below"},0),Tables!$D$5:$D$85,Tables!$G$5:$G$85,Tables!$J$5:$J$85,Inputs!$E$9:$E$89),30) | K34: =$A$15*INDEX(CHOOSE(MATCH(Inputs!$C$4,{"CIE 1931 2deg","CIE 1964 10deg","CIE 2015 2deg","Pasted below"},0),Tables!$B$5:$B$85,Tables!$E$5:$E$85,Tables!$H$5:$H$85,Inputs!$C$9:$C$89),30)+$B$15*INDEX(CHOOSE(MATCH(Inputs!$C$4,{"CIE 1931 2deg","CIE 1964 10deg","CIE 2015 2deg","Pasted below"},0),Tables!$C$5:$C$85,Tables!$F$5:$F$85,Tables!$I$5:$I$85,Inputs!$D$9:$D$89),30)+$C$15*INDEX(CHOOSE(MATCH(Inputs!$C$4,{"CIE 1931 2deg","CIE 1964 10deg","CIE 2015 2deg","Pasted below"},0),Tables!$D$5:$D$85,Tables!$G$5:$G$85,Tables!$J$5:$J$85,Inputs!$E$9:$E$89),30) | L34: =$A$16*INDEX(CHOOSE(MATCH(Inputs!$C$4,{"CIE 1931 2deg","CIE 1964 10deg","CIE 2015 2deg","Pasted below"},0),Tables!$B$5:$B$85,Tables!$E$5:$E$85,Tables!$H$5:$H$85,Inputs!$C$9:$C$89),30)+$B$16*INDEX(CHOOSE(MATCH(Inputs!$C$4,{"CIE 1931 2deg","CIE 1964 10deg","CIE 2015 2deg","Pasted below"},0),Tables!$C$5:$C$85,Tables!$F$5:$F$85,Tables!$I$5:$I$85,Inputs!$D$9:$D$89),30)+$C$16*INDEX(CHOOSE(MATCH(Inputs!$C$4,{"CIE 1931 2deg","CIE 1964 10deg","CIE 2015 2deg","Pasted below"},0),Tables!$D$5:$D$85,Tables!$G$5:$G$85,Tables!$J$5:$J$85,Inputs!$E$9:$E$89),30)
I35: 530 | J35: =$A$14*INDEX(CHOOSE(MATCH(Inputs!$C$4,{"CIE 1931 2deg","CIE 1964 10deg","CIE 2015 2deg","Pasted below"},0),Tables!$B$5:$B$85,Tables!$E$5:$E$85,Tables!$H$5:$H$85,Inputs!$C$9:$C$89),31)+$B$14*INDEX(CHOOSE(MATCH(Inputs!$C$4,{"CIE 1931 2deg","CIE 1964 10deg","CIE 2015 2deg","Pasted below"},0),Tables!$C$5:$C$85,Tables!$F$5:$F$85,Tables!$I$5:$I$85,Inputs!$D$9:$D$89),31)+$C$14*INDEX(CHOOSE(MATCH(Inputs!$C$4,{"CIE 1931 2deg","CIE 1964 10deg","CIE 2015 2deg","Pasted below"},0),Tables!$D$5:$D$85,Tables!$G$5:$G$85,Tables!$J$5:$J$85,Inputs!$E$9:$E$89),31) | K35: =$A$15*INDEX(CHOOSE(MATCH(Inputs!$C$4,{"CIE 1931 2deg","CIE 1964 10deg","CIE 2015 2deg","Pasted below"},0),Tables!$B$5:$B$85,Tables!$E$5:$E$85,Tables!$H$5:$H$85,Inputs!$C$9:$C$89),31)+$B$15*INDEX(CHOOSE(MATCH(Inputs!$C$4,{"CIE 1931 2deg","CIE 1964 10deg","CIE 2015 2deg","Pasted below"},0),Tables!$C$5:$C$85,Tables!$F$5:$F$85,Tables!$I$5:$I$85,Inputs!$D$9:$D$89),31)+$C$15*INDEX(CHOOSE(MATCH(Inputs!$C$4,{"CIE 1931 2deg","CIE 1964 10deg","CIE 2015 2deg","Pasted below"},0),Tables!$D$5:$D$85,Tables!$G$5:$G$85,Tables!$J$5:$J$85,Inputs!$E$9:$E$89),31) | L35: =$A$16*INDEX(CHOOSE(MATCH(Inputs!$C$4,{"CIE 1931 2deg","CIE 1964 10deg","CIE 2015 2deg","Pasted below"},0),Tables!$B$5:$B$85,Tables!$E$5:$E$85,Tables!$H$5:$H$85,Inputs!$C$9:$C$89),31)+$B$16*INDEX(CHOOSE(MATCH(Inputs!$C$4,{"CIE 1931 2deg","CIE 1964 10deg","CIE 2015 2deg","Pasted below"},0),Tables!$C$5:$C$85,Tables!$F$5:$F$85,Tables!$I$5:$I$85,Inputs!$D$9:$D$89),31)+$C$16*INDEX(CHOOSE(MATCH(Inputs!$C$4,{"CIE 1931 2deg","CIE 1964 10deg","CIE 2015 2deg","Pasted below"},0),Tables!$D$5:$D$85,Tables!$G$5:$G$85,Tables!$J$5:$J$85,Inputs!$E$9:$E$89),31)
I36: 535 | J36: =$A$14*INDEX(CHOOSE(MATCH(Inputs!$C$4,{"CIE 1931 2deg","CIE 1964 10deg","CIE 2015 2deg","Pasted below"},0),Tables!$B$5:$B$85,Tables!$E$5:$E$85,Tables!$H$5:$H$85,Inputs!$C$9:$C$89),32)+$B$14*INDEX(CHOOSE(MATCH(Inputs!$C$4,{"CIE 1931 2deg","CIE 1964 10deg","CIE 2015 2deg","Pasted below"},0),Tables!$C$5:$C$85,Tables!$F$5:$F$85,Tables!$I$5:$I$85,Inputs!$D$9:$D$89),32)+$C$14*INDEX(CHOOSE(MATCH(Inputs!$C$4,{"CIE 1931 2deg","CIE 1964 10deg","CIE 2015 2deg","Pasted below"},0),Tables!$D$5:$D$85,Tables!$G$5:$G$85,Tables!$J$5:$J$85,Inputs!$E$9:$E$89),32) | K36: =$A$15*INDEX(CHOOSE(MATCH(Inputs!$C$4,{"CIE 1931 2deg","CIE 1964 10deg","CIE 2015 2deg","Pasted below"},0),Tables!$B$5:$B$85,Tables!$E$5:$E$85,Tables!$H$5:$H$85,Inputs!$C$9:$C$89),32)+$B$15*INDEX(CHOOSE(MATCH(Inputs!$C$4,{"CIE 1931 2deg","CIE 1964 10deg","CIE 2015 2deg","Pasted below"},0),Tables!$C$5:$C$85,Tables!$F$5:$F$85,Tables!$I$5:$I$85,Inputs!$D$9:$D$89),32)+$C$15*INDEX(CHOOSE(MATCH(Inputs!$C$4,{"CIE 1931 2deg","CIE 1964 10deg","CIE 2015 2deg","Pasted below"},0),Tables!$D$5:$D$85,Tables!$G$5:$G$85,Tables!$J$5:$J$85,Inputs!$E$9:$E$89),32) | L36: =$A$16*INDEX(CHOOSE(MATCH(Inputs!$C$4,{"CIE 1931 2deg","CIE 1964 10deg","CIE 2015 2deg","Pasted below"},0),Tables!$B$5:$B$85,Tables!$E$5:$E$85,Tables!$H$5:$H$85,Inputs!$C$9:$C$89),32)+$B$16*INDEX(CHOOSE(MATCH(Inputs!$C$4,{"CIE 1931 2deg","CIE 1964 10deg","CIE 2015 2deg","Pasted below"},0),Tables!$C$5:$C$85,Tables!$F$5:$F$85,Tables!$I$5:$I$85,Inputs!$D$9:$D$89),32)+$C$16*INDEX(CHOOSE(MATCH(Inputs!$C$4,{"CIE 1931 2deg","CIE 1964 10deg","CIE 2015 2deg","Pasted below"},0),Tables!$D$5:$D$85,Tables!$G$5:$G$85,Tables!$J$5:$J$85,Inputs!$E$9:$E$89),32)
